Workbook

Sheet 質問設定
A1: 質問・選択肢の設定
A2: このシートの設問文や選択肢を変えると、個人シート（01〜45）と Sheet1 の見出し・回答文言に反映されます。
A3: 学年段階 | B3: 中学年
A4: 項目数 | B4: 10
A5: 【選択肢】点数1〜4に対応する文言（子どもが選ぶ数字 → Sheet1に出るテキスト）
A6: 1 | B6: そう思わない
A7: 2 | B7: あまりそう思わない
A8: 3 | B8: そう思う
A9: 4 | B9: とてもそう思う
A10: 【設問一覧】C列（設問文）を直すと個人シートが、D列（Sheet1見出し）を直すと集計用の列名が変わります。
A11: No | B11: 観点 | C11: 設問文（個人シート） | D11: Sheet1の列見出し
A12: ① | B12: 目標 | C12: みんなで決めたもくひょうやめあてに力をあわせてとりくんでいる学級です。 | D12: ①目標：みんなで決めたもくひょうやめあてに力をあわせてとりくんでいる学級です。
A13: ② | B13: 役割 | C13: かかりやとうばんの活動にすすんでとりくむ学級です。 | D13: ②役割：かかりやとうばんの活動にすすんでとりくむ学級です。
A14: ③ | B14: 聞く姿勢 | C14: 発言している人の話をさいごまでしっかりと聞いている学級です。 | D14: ③聞く姿勢：発言している人の話をさいごまでしっかりと聞いている学級です。
A15: ④ | B15: つながり | C15: 友だちの話に賛成・反対・つけたしと、つなげるように発言している学級です。 | D15: ④つながり：友だちの話に賛成・反対・つけたしと、つなげるように発言している学級です。
A16: ⑤ | B16: 支え合い | C16: 勉強・運動・そうじ・給食などで、教えあいや助けあいをしている学級です。 | D16: ⑤支え合い：勉強・運動・そうじ・給食などで、教えあいや助けあいをしている学級です。
A17: ⑥ | B17: 仲直り | C17: すなおに「ごめんね」と言って、なかなおりができる学級です。 | D17: ⑥仲直り：すなおに「ごめんね」と言って、なかなおりができる学級です。
A18: ⑦ | B18: 尊重 | C18: 友だちの心をきずつけることを言ったり、からかったりしない学級です。 | D18: ⑦尊重：友だちの心をきずつけることを言ったり、からかったりしない学級です。
A19: ⑧ | B19: 仲間 | C19: だれとでも遊んだり、グループになったりすることができる学級です。 | D19: ⑧仲間：だれとでも遊んだり、グループになったりすることができる学級です。
A20: ⑨ | B20: 学習 | C20: じゅぎょう中にむだなおしゃべりをしない学級です。 | D20: ⑨学習：じゅぎょう中にむだなおしゃべりをしない学級です。
A21: ⑩ | B21: 生活 | C21: ろうかを走らない、あいさつをするなど、学校のきまりをまもっている学級です。 | D21: ⑩生活：ろうかを走らない、あいさつをするなど、学校のきまりをまもっている学級です。

Sheet Sheet1
A1: ID | B1: 開始時刻 | C1: 完了時刻 | D1: メール | E1: 名前 | F1: =IF('質問設定'!D12="","",'質問設定'!D12) | G1: =IF('質問設定'!D13="","",'質問設定'!D13) | H1: =IF('質問設定'!D14="","",'質問設定'!D14) | I1: =IF('質問設定'!D15="","",'質問設定'!D15) | J1: =IF('質問設定'!D16="","",'質問設定'!D16) | K1: =IF('質問設定'!D17="","",'質問設定'!D17) | L1: =IF('質問設定'!D18="","",'質問設定'!D18) | M1: =IF('質問設定'!D19="","",'質問設定'!D19) | N1: =IF('質問設定'!D20="","",'質問設定'!D20) | O1: =IF('質問設定'!D21="","",'質問設定'!D21)
A2: 01 | F2: =IF('01'!B4="","",IFERROR(CHOOSE('01'!B4,'質問設定'!$B$6,'質問設定'!$B$7,'質問設定'!$B$8,'質問設定'!$B$9),"")) | G2: =IF('01'!B5="","",IFERROR(CHOOSE('01'!B5,'質問設定'!$B$6,'質問設定'!$B$7,'質問設定'!$B$8,'質問設定'!$B$9),"")) | H2: =IF('01'!B6="","",IFERROR(CHOOSE('01'!B6,'質問設定'!$B$6,'質問設定'!$B$7,'質問設定'!$B$8,'質問設定'!$B$9),"")) | I2: =IF('01'!B7="","",IFERROR(CHOOSE('01'!B7,'質問設定'!$B$6,'質問設定'!$B$7,'質問設定'!$B$8,'質問設定'!$B$9),"")) | J2: =IF('01'!B8="","",IFERROR(CHOOSE('01'!B8,'質問設定'!$B$6,'質問設定'!$B$7,'質問設定'!$B$8,'質問設定'!$B$9),"")) | K2: =IF('01'!B9="","",IFERROR(CHOOSE('01'!B9,'質問設定'!$B$6,'質問設定'!$B$7,'質問設定'!$B$8,'質問設定'!$B$9),"")) | L2: =IF('01'!B10="","",IFERROR(CHOOSE('01'!B10,'質問設定'!$B$6,'質問設定'!$B$7,'質問設定'!$B$8,'質問設定'!$B$9),"")) | M2: =IF('01'!B11="","",IFERROR(CHOOSE('01'!B11,'質問設定'!$B$6,'質問設定'!$B$7,'質問設定'!$B$8,'質問設定'!$B$9),"")) | N2: =IF('01'!B12="","",IFERROR(CHOOSE('01'!B12,'質問設定'!$B$6,'質問設定'!$B$7,'質問設定'!$B$8,'質問設定'!$B$9),"")) | O2: =IF('01'!B13="","",IFERROR(CHOOSE('01'!B13,'質問設定'!$B$6,'質問設定'!$B$7,'質問設定'!$B$8,'質問設定'!$B$9),""))
A3: 02 | F3: =IF('02'!B4="","",IFERROR(CHOOSE('02'!B4,'質問設定'!$B$6,'質問設定'!$B$7,'質問設定'!$B$8,'質問設定'!$B$9),"")) | G3: =IF('02'!B5="","",IFERROR(CHOOSE('02'!B5,'質問設定'!$B$6,'質問設定'!$B$7,'質問設定'!$B$8,'質問設定'!$B$9),"")) | H3: =IF('02'!B6="","",IFERROR(CHOOSE('02'!B6,'質問設定'!$B$6,'質問設定'!$B$7,'質問設定'!$B$8,'質問設定'!$B$9),"")) | I3: =IF('02'!B7="","",IFERROR(CHOOSE('02'!B7,'質問設定'!$B$6,'質問設定'!$B$7,'質問設定'!$B$8,'質問設定'!$B$9),"")) | J3: =IF('02'!B8="","",IFERROR(CHOOSE('02'!B8,'質問設定'!$B$6,'質問設定'!$B$7,'質問設定'!$B$8,'質問設定'!$B$9),"")) | K3: =IF('02'!B9="","",IFERROR(CHOOSE('02'!B9,'質問設定'!$B$6,'質問設定'!$B$7,'質問設定'!$B$8,'質問設定'!$B$9),"")) | L3: =IF('02'!B10="","",IFERROR(CHOOSE('02'!B10,'質問設定'!$B$6,'質問設定'!$B$7,'質問設定'!$B$8,'質問設定'!$B$9),"")) | M3: =IF('02'!B11="","",IFERROR(CHOOSE('02'!B11,'質問設定'!$B$6,'質問設定'!$B$7,'質問設定'!$B$8,'質問設定'!$B$9),"")) | N3: =IF('02'!B12="","",IFERROR(CHOOSE('02'!B12,'質問設定'!$B$6,'質問設定'!$B$7,'質問設定'!$B$8,'質問設定'!$B$9),"")) | O3: =IF('02'!B13="","",IFERROR(CHOOSE('02'!B13,'質問設定'!$B$6,'質問設定'!$B$7,'質問設定'!$B$8,'質問設定'!$B$9),""))
A4: 03 | F4: =IF('03'!B4="","",IFERROR(CHOOSE('03'!B4,'質問設定'!$B$6,'質問設定'!$B$7,'質問設定'!$B$8,'質問設定'!$B$9),"")) | G4: =IF('03'!B5="","",IFERROR(CHOOSE('03'!B5,'質問設定'!$B$6,'質問設定'!$B$7,'質問設定'!$B$8,'質問設定'!$B$9),"")) | H4: =IF('03'!B6="","",IFERROR(CHOOSE('03'!B6,'質問設定'!$B$6,'質問設定'!$B$7,'質問設定'!$B$8,'質問設定'!$B$9),"")) | I4: =IF('03'!B7="","",IFERROR(CHOOSE('03'!B7,'質問設定'!$B$6,'質問設定'!$B$7,'質問設定'!$B$8,'質問設定'!$B$9),"")) | J4: =IF('03'!B8="","",IFERROR(CHOOSE('03'!B8,'質問設定'!$B$6,'質問設定'!$B$7,'質問設定'!$B$8,'質問設定'!$B$9),"")) | K4: =IF('03'!B9="","",IFERROR(CHOOSE('03'!B9,'質問設定'!$B$6,'質問設定'!$B$7,'質問設定'!$B$8,'質問設定'!$B$9),"")) | L4: =IF('03'!B10="","",IFERROR(CHOOSE('03'!B10,'質問設定'!$B$6,'質問設定'!$B$7,'質問設定'!$B$8,'質問設定'!$B$9),"")) | M4: =IF('03'!B11="","",IFERROR(CHOOSE('03'!B11,'質問設定'!$B$6,'質問設定'!$B$7,'質問設定'!$B$8,'質問設定'!$B$9),"")) | N4: =IF('03'!B12="","",IFERROR(CHOOSE('03'!B12,'質問設定'!$B$6,'質問設定'!$B$7,'質問設定'!$B$8,'質問設定'!$B$9),"")) | O4: =IF('03'!B13="","",IFERROR(CHOOSE('03'!B13,'質問設定'!$B$6,'質問設定'!$B$7,'質問設定'!$B$8,'質問設定'!$B$9),""))
A5: 04 | F5: =IF('04'!B4="","",IFERROR(CHOOSE('04'!B4,'質問設定'!$B$6,'質問設定'!$B$7,'質問設定'!$B$8,'質問設定'!$B$9),"")) | G5: =IF('04'!B5="","",IFERROR(CHOOSE('04'!B5,'質問設定'!$B$6,'質問設定'!$B$7,'質問設定'!$B$8,'質問設定'!$B$9),"")) | H5: =IF('04'!B6="","",IFERROR(CHOOSE('04'!B6,'質問設定'!$B$6,'質問設定'!$B$7,'質問設定'!$B$8,'質問設定'!$B$9),"")) | I5: =IF('04'!B7="","",IFERROR(CHOOSE('04'!B7,'質問設定'!$B$6,'質問設定'!$B$7,'質問設定'!$B$8,'質問設定'!$B$9),"")) | J5: =IF('04'!B8="","",IFERROR(CHOOSE('04'!B8,'質問設定'!$B$6,'質問設定'!$B$7,'質問設定'!$B$8,'質問設定'!$B$9),"")) | K5: =IF('04'!B9="","",IFERROR(CHOOSE('04'!B9,'質問設定'!$B$6,'質問設定'!$B$7,'質問設定'!$B$8,'質問設定'!$B$9),"")) | L5: =IF('04'!B10="","",IFERROR(CHOOSE('04'!B10,'質問設定'!$B$6,'質問設定'!$B$7,'質問設定'!$B$8,'質問設定'!$B$9),"")) | M5: =IF('04'!B11="","",IFERROR(CHOOSE('04'!B11,'質問設定'!$B$6,'質問設定'!$B$7,'質問設定'!$B$8,'質問設定'!$B$9),"")) | N5: =IF('04'!B12="","",IFERROR(CHOOSE('04'!B12,'質問設定'!$B$6,'質問設定'!$B$7,'質問設定'!$B$8,'質問設定'!$B$9),"")) | O5: =IF('04'!B13="","",IFERROR(CHOOSE('04'!B13,'質問設定'!$B$6,'質問設定'!$B$7,'質問設定'!$B$8,'質問設定'!$B$9),""))
A6: 05 | F6: =IF('05'!B4="","",IFERROR(CHOOSE('05'!B4,'質問設定'!$B$6,'質問設定'!$B$7,'質問設定'!$B$8,'質問設定'!$B$9),"")) | G6: =IF('05'!B5="","",IFERROR(CHOOSE('05'!B5,'質問設定'!$B$6,'質問設定'!$B$7,'質問設定'!$B$8,'質問設定'!$B$9),"")) | H6: =IF('05'!B6="","",IFERROR(CHOOSE('05'!B6,'質問設定'!$B$6,'質問設定'!$B$7,'質問設定'!$B$8,'質問設定'!$B$9),"")) | I6: =IF('05'!B7="","",IFERROR(CHOOSE('05'!B7,'質問設定'!$B$6,'質問設定'!$B$7,'質問設定'!$B$8,'質問設定'!$B$9),"")) | J6: =IF('05'!B8="","",IFERROR(CHOOSE('05'!B8,'質問設定'!$B$6,'質問設定'!$B$7,'質問設定'!$B$8,'質問設定'!$B$9),"")) | K6: =IF('05'!B9="","",IFERROR(CHOOSE('05'!B9,'質問設定'!$B$6,'質問設定'!$B$7,'質問設定'!$B$8,'質問設定'!$B$9),"")) | L6: =IF('05'!B10="","",IFERROR(CHOOSE('05'!B10,'質問設定'!$B$6,'質問設定'!$B$7,'質問設定'!$B$8,'質問設定'!$B$9),"")) | M6: =IF('05'!B11="","",IFERROR(CHOOSE('05'!B11,'質問設定'!$B$6,'質問設定'!$B$7,'質問設定'!$B$8,'質問設定'!$B$9),"")) | N6: =IF('05'!B12="","",IFERROR(CHOOSE('05'!B12,'質問設定'!$B$6,'質問設定'!$B$7,'質問設定'!$B$8,'質問設定'!$B$9),"")) | O6: =IF('05'!B13="","",IFERROR(CHOOSE('05'!B13,'質問設定'!$B$6,'質問設定'!$B$7,'質問設定'!$B$8,'質問設定'!$B$9),""))
A7: 06 | F7: =IF('06'!B4="","",IFERROR(CHOOSE('06'!B4,'質問設定'!$B$6,'質問設定'!$B$7,'質問設定'!$B$8,'質問設定'!$B$9),"")) | G7: =IF('06'!B5="","",IFERROR(CHOOSE('06'!B5,'質問設定'!$B$6,'質問設定'!$B$7,'質問設定'!$B$8,'質問設定'!$B$9),"")) | H7: =IF('06'!B6="","",IFERROR(CHOOSE('06'!B6,'質問設定'!$B$6,'質問設定'!$B$7,'質問設定'!$B$8,'質問設定'!$B$9),"")) | I7: =IF('06'!B7="","",IFERROR(CHOOSE('06'!B7,'質問設定'!$B$6,'質問設定'!$B$7,'質問設定'!$B$8,'質問設定'!$B$9),"")) | J7: =IF('06'!B8="","",IFERROR(CHOOSE('06'!B8,'質問設定'!$B$6,'質問設定'!$B$7,'質問設定'!$B$8,'質問設定'!$B$9),"")) | K7: =IF('06'!B9="","",IFERROR(CHOOSE('06'!B9,'質問設定'!$B$6,'質問設定'!$B$7,'質問設定'!$B$8,'質問設定'!$B$9),"")) | L7: =IF('06'!B10="","",IFERROR(CHOOSE('06'!B10,'質問設定'!$B$6,'質問設定'!$B$7,'質問設定'!$B$8,'質問設定'!$B$9),"")) | M7: =IF('06'!B11="","",IFERROR(CHOOSE('06'!B11,'質問設定'!$B$6,'質問設定'!$B$7,'質問設定'!$B$8,'質問設定'!$B$9),"")) | N7: =IF('06'!B12="","",IFERROR(CHOOSE('06'!B12,'質問設定'!$B$6,'質問設定'!$B$7,'質問設定'!$B$8,'質問設定'!$B$9),"")) | O7: =IF('06'!B13="","",IFERROR(CHOOSE('06'!B13,'質問設定'!$B$6,'質問設定'!$B$7,'質問設定'!$B$8,'質問設定'!$B$9),""))
A8: 07 | F8: =IF('07'!B4="","",IFERROR(CHOOSE('07'!B4,'質問設定'!$B$6,'質問設定'!$B$7,'質問設定'!$B$8,'質問設定'!$B$9),"")) | G8: =IF('07'!B5="","",IFERROR(CHOOSE('07'!B5,'質問設定'!$B$6,'質問設定'!$B$7,'質問設定'!$B$8,'質問設定'!$B$9),"")) | H8: =IF('07'!B6="","",IFERROR(CHOOSE('07'!B6,'質問設定'!$B$6,'質問設定'!$B$7,'質問設定'!$B$8,'質問設定'!$B$9),"")) | I8: =IF('07'!B7="","",IFERROR(CHOOSE('07'!B7,'質問設定'!$B$6,'質問設定'!$B$7,'質問設定'!$B$8,'質問設定'!$B$9),"")) | J8: =IF('07'!B8="","",IFERROR(CHOOSE('07'!B8,'質問設定'!$B$6,'質問設定'!$B$7,'質問設定'!$B$8,'質問設定'!$B$9),"")) | K8: =IF('07'!B9="","",IFERROR(CHOOSE('07'!B9,'質問設定'!$B$6,'質問設定'!$B$7,'質問設定'!$B$8,'質問設定'!$B$9),"")) | L8: =IF('07'!B10="","",IFERROR(CHOOSE('07'!B10,'質問設定'!$B$6,'質問設定'!$B$7,'質問設定'!$B$8,'質問設定'!$B$9),"")) | M8: =IF('07'!B11="","",IFERROR(CHOOSE('07'!B11,'質問設定'!$B$6,'質問設定'!$B$7,'質問設定'!$B$8,'質問設定'!$B$9),"")) | N8: =IF('07'!B12="","",IFERROR(CHOOSE('07'!B12,'質問設定'!$B$6,'質問設定'!$B$7,'質問設定'!$B$8,'質問設定'!$B$9),"")) | O8: =IF('07'!B13="","",IFERROR(CHOOSE('07'!B13,'質問設定'!$B$6,'質問設定'!$B$7,'質問設定'!$B$8,'質問設定'!$B$9),""))
A9: 08 | F9: =IF('08'!B4="","",IFERROR(CHOOSE('08'!B4,'質問設定'!$B$6,'質問設定'!$B$7,'質問設定'!$B$8,'質問設定'!$B$9),"")) | G9: =IF('08'!B5="","",IFERROR(CHOOSE('08'!B5,'質問設定'!$B$6,'質問設定'!$B$7,'質問設定'!$B$8,'質問設定'!$B$9),"")) | H9: =IF('08'!B6="","",IFERROR(CHOOSE('08'!B6,'質問設定'!$B$6,'質問設定'!$B$7,'質問設定'!$B$8,'質問設定'!$B$9),"")) | I9: =IF('08'!B7="","",IFERROR(CHOOSE('08'!B7,'質問設定'!$B$6,'質問設定'!$B$7,'質問設定'!$B$8,'質問設定'!$B$9),"")) | J9: =IF('08'!B8="","",IFERROR(CHOOSE('08'!B8,'質問設定'!$B$6,'質問設定'!$B$7,'質問設定'!$B$8,'質問設定'!$B$9),"")) | K9: =IF('08'!B9="","",IFERROR(CHOOSE('08'!B9,'質問設定'!$B$6,'質問設定'!$B$7,'質問設定'!$B$8,'質問設定'!$B$9),"")) | L9: =IF('08'!B10="","",IFERROR(CHOOSE('08'!B10,'質問設定'!$B$6,'質問設定'!$B$7,'質問設定'!$B$8,'質問設定'!$B$9),"")) | M9: =IF('08'!B11="","",IFERROR(CHOOSE('08'!B11,'質問設定'!$B$6,'質問設定'!$B$7,'質問設定'!$B$8,'質問設定'!$B$9),"")) | N9: =IF('08'!B12="","",IFERROR(CHOOSE('08'!B12,'質問設定'!$B$6,'質問設定'!$B$7,'質問設定'!$B$8,'質問設定'!$B$9),"")) | O9: =IF('08'!B13="","",IFERROR(CHOOSE('08'!B13,'質問設定'!$B$6,'質問設定'!$B$7,'質問設定'!$B$8,'質問設定'!$B$9),""))
A10: 09 | F10: =IF('09'!B4="","",IFERROR(CHOOSE('09'!B4,'質問設定'!$B$6,'質問設定'!$B$7,'質問設定'!$B$8,'質問設定'!$B$9),"")) | G10: =IF('09'!B5="","",IFERROR(CHOOSE('09'!B5,'質問設定'!$B$6,'質問設定'!$B$7,'質問設定'!$B$8,'質問設定'!$B$9),"")) | H10: =IF('09'!B6="","",IFERROR(CHOOSE('09'!B6,'質問設定'!$B$6,'質問設定'!$B$7,'質問設定'!$B$8,'質問設定'!$B$9),"")) | I10: =IF('09'!B7="","",IFERROR(CHOOSE('09'!B7,'質問設定'!$B$6,'質問設定'!$B$7,'質問設定'!$B$8,'質問設定'!$B$9),"")) | J10: =IF('09'!B8="","",IFERROR(CHOOSE('09'!B8,'質問設定'!$B$6,'質問設定'!$B$7,'質問設定'!$B$8,'質問設定'!$B$9),"")) | K10: =IF('09'!B9="","",IFERROR(CHOOSE('09'!B9,'質問設定'!$B$6,'質問設定'!$B$7,'質問設定'!$B$8,'質問設定'!$B$9),"")) | L10: =IF('09'!B10="","",IFERROR(CHOOSE('09'!B10,'質問設定'!$B$6,'質問設定'!$B$7,'質問設定'!$B$8,'質問設定'!$B$9),"")) | M10: =IF('09'!B11="","",IFERROR(CHOOSE('09'!B11,'質問設定'!$B$6,'質問設定'!$B$7,'質問設定'!$B$8,'質問設定'!$B$9),"")) | N10: =IF('09'!B12="","",IFERROR(CHOOSE('09'!B12,'質問設定'!$B$6,'質問設定'!$B$7,'質問設定'!$B$8,'質問設定'!$B$9),"")) | O10: =IF('09'!B13="","",IFERROR(CHOOSE('09'!B13,'質問設定'!$B$6,'質問設定'!$B$7,'質問設定'!$B$8,'質問設定'!$B$9),""))
A11: 10 | F11: =IF('10'!B4="","",IFERROR(CHOOSE('10'!B4,'質問設定'!$B$6,'質問設定'!$B$7,'質問設定'!$B$8,'質問設定'!$B$9),"")) | G11: =IF('10'!B5="","",IFERROR(CHOOSE('10'!B5,'質問設定'!$B$6,'質問設定'!$B$7,'質問設定'!$B$8,'質問設定'!$B$9),"")) | H11: =IF('10'!B6="","",IFERROR(CHOOSE('10'!B6,'質問設定'!$B$6,'質問設定'!$B$7,'質問設定'!$B$8,'質問設定'!$B$9),"")) | I11: =IF('10'!B7="","",IFERROR(CHOOSE('10'!B7,'質問設定'!$B$6,'質問設定'!$B$7,'質問設定'!$B$8,'質問設定'!$B$9),"")) | J11: =IF('10'!B8="","",IFERROR(CHOOSE('10'!B8,'質問設定'!$B$6,'質問設定'!$B$7,'質問設定'!$B$8,'質問設定'!$B$9),"")) | K11: =IF('10'!B9="","",IFERROR(CHOOSE('10'!B9,'質問設定'!$B$6,'質問設定'!$B$7,'質問設定'!$B$8,'質問設定'!$B$9),"")) | L11: =IF('10'!B10="","",IFERROR(CHOOSE('10'!B10,'質問設定'!$B$6,'質問設定'!$B$7,'質問設定'!$B$8,'質問設定'!$B$9),"")) | M11: =IF('10'!B11="","",IFERROR(CHOOSE('10'!B11,'質問設定'!$B$6,'質問設定'!$B$7,'質問設定'!$B$8,'質問設定'!$B$9),"")) | N11: =IF('10'!B12="","",IFERROR(CHOOSE('10'!B12,'質問設定'!$B$6,'質問設定'!$B$7,'質問設定'!$B$8,'質問設定'!$B$9),"")) | O11: =IF('10'!B13="","",IFERROR(CHOOSE('10'!B13,'質問設定'!$B$6,'質問設定'!$B$7,'質問設定'!$B$8,'質問設定'!$B$9),""))
A12: 11 | F12: =IF('11'!B4="","",IFERROR(CHOOSE('11'!B4,'質問設定'!$B$6,'質問設定'!$B$7,'質問設定'!$B$8,'質問設定'!$B$9),"")) | G12: =IF('11'!B5="","",IFERROR(CHOOSE('11'!B5,'質問設定'!$B$6,'質問設定'!$B$7,'質問設定'!$B$8,'質問設定'!$B$9),"")) | H12: =IF('11'!B6="","",IFERROR(CHOOSE('11'!B6,'質問設定'!$B$6,'質問設定'!$B$7,'質問設定'!$B$8,'質問設定'!$B$9),"")) | I12: =IF('11'!B7="","",IFERROR(CHOOSE('11'!B7,'質問設定'!$B$6,'質問設定'!$B$7,'質問設定'!$B$8,'質問設定'!$B$9),"")) | J12: =IF('11'!B8="","",IFERROR(CHOOSE('11'!B8,'質問設定'!$B$6,'質問設定'!$B$7,'質問設定'!$B$8,'質問設定'!$B$9),"")) | K12: =IF('11'!B9="","",IFERROR(CHOOSE('11'!B9,'質問設定'!$B$6,'質問設定'!$B$7,'質問設定'!$B$8,'質問設定'!$B$9),"")) | L12: =IF('11'!B10="","",IFERROR(CHOOSE('11'!B10,'質問設定'!$B$6,'質問設定'!$B$7,'質問設定'!$B$8,'質問設定'!$B$9),"")) | M12: =IF('11'!B11="","",IFERROR(CHOOSE('11'!B11,'質問設定'!$B$6,'質問設定'!$B$7,'質問設定'!$B$8,'質問設定'!$B$9),"")) | N12: =IF('11'!B12="","",IFERROR(CHOOSE('11'!B12,'質問設定'!$B$6,'質問設定'!$B$7,'質問設定'!$B$8,'質問設定'!$B$9),"")) | O12: =IF('11'!B13="","",IFERROR(CHOOSE('11'!B13,'質問設定'!$B$6,'質問設定'!$B$7,'質問設定'!$B$8,'質問設定'!$B$9),""))
A13: 12 | F13: =IF('12'!B4="","",IFERROR(CHOOSE('12'!B4,'質問設定'!$B$6,'質問設定'!$B$7,'質問設定'!$B$8,'質問設定'!$B$9),"")) | G13: =IF('12'!B5="","",IFERROR(CHOOSE('12'!B5,'質問設定'!$B$6,'質問設定'!$B$7,'質問設定'!$B$8,'質問設定'!$B$9),"")) | H13: =IF('12'!B6="","",IFERROR(CHOOSE('12'!B6,'質問設定'!$B$6,'質問設定'!$B$7,'質問設定'!$B$8,'質問設定'!$B$9),"")) | I13: =IF('12'!B7="","",IFERROR(CHOOSE('12'!B7,'質問設定'!$B$6,'質問設定'!$B$7,'質問設定'!$B$8,'質問設定'!$B$9),"")) | J13: =IF('12'!B8="","",IFERROR(CHOOSE('12'!B8,'質問設定'!$B$6,'質問設定'!$B$7,'質問設定'!$B$8,'質問設定'!$B$9),"")) | K13: =IF('12'!B9="","",IFERROR(CHOOSE('12'!B9,'質問設定'!$B$6,'質問設定'!$B$7,'質問設定'!$B$8,'質問設定'!$B$9),"")) | L13: =IF('12'!B10="","",IFERROR(CHOOSE('12'!B10,'質問設定'!$B$6,'質問設定'!$B$7,'質問設定'!$B$8,'質問設定'!$B$9),"")) | M13: =IF('12'!B11="","",IFERROR(CHOOSE('12'!B11,'質問設定'!$B$6,'質問設定'!$B$7,'質問設定'!$B$8,'質問設定'!$B$9),"")) | N13: =IF('12'!B12="","",IFERROR(CHOOSE('12'!B12,'質問設定'!$B$6,'質問設定'!$B$7,'質問設定'!$B$8,'質問設定'!$B$9),"")) | O13: =IF('12'!B13="","",IFERROR(CHOOSE('12'!B13,'質問設定'!$B$6,'質問設定'!$B$7,'質問設定'!$B$8,'質問設定'!$B$9),""))
A14: 13 | F14: =IF('13'!B4="","",IFERROR(CHOOSE('13'!B4,'質問設定'!$B$6,'質問設定'!$B$7,'質問設定'!$B$8,'質問設定'!$B$9),"")) | G14: =IF('13'!B5="","",IFERROR(CHOOSE('13'!B5,'質問設定'!$B$6,'質問設定'!$B$7,'質問設定'!$B$8,'質問設定'!$B$9),"")) | H14: =IF('13'!B6="","",IFERROR(CHOOSE('13'!B6,'質問設定'!$B$6,'質問設定'!$B$7,'質問設定'!$B$8,'質問設定'!$B$9),"")) | I14: =IF('13'!B7="","",IFERROR(CHOOSE('13'!B7,'質問設定'!$B$6,'質問設定'!$B$7,'質問設定'!$B$8,'質問設定'!$B$9),"")) | J14: =IF('13'!B8="","",IFERROR(CHOOSE('13'!B8,'質問設定'!$B$6,'質問設定'!$B$7,'質問設定'!$B$8,'質問設定'!$B$9),"")) | K14: =IF('13'!B9="","",IFERROR(CHOOSE('13'!B9,'質問設定'!$B$6,'質問設定'!$B$7,'質問設定'!$B$8,'質問設定'!$B$9),"")) | L14: =IF('13'!B10="","",IFERROR(CHOOSE('13'!B10,'質問設定'!$B$6,'質問設定'!$B$7,'質問設定'!$B$8,'質問設定'!$B$9),"")) | M14: =IF('13'!B11="","",IFERROR(CHOOSE('13'!B11,'質問設定'!$B$6,'質問設定'!$B$7,'質問設定'!$B$8,'質問設定'!$B$9),"")) | N14: =IF('13'!B12="","",IFERROR(CHOOSE('13'!B12,'質問設定'!$B$6,'質問設定'!$B$7,'質問設定'!$B$8,'質問設定'!$B$9),"")) | O14: =IF('13'!B13="","",IFERROR(CHOOSE('13'!B13,'質問設定'!$B$6,'質問設定'!$B$7,'質問設定'!$B$8,'質問設定'!$B$9),""))
A15: 14 | F15: =IF('14'!B4="","",IFERROR(CHOOSE('14'!B4,'質問設定'!$B$6,'質問設定'!$B$7,'質問設定'!$B$8,'質問設定'!$B$9),"")) | G15: =IF('14'!B5="","",IFERROR(CHOOSE('14'!B5,'質問設定'!$B$6,'質問設定'!$B$7,'質問設定'!$B$8,'質問設定'!$B$9),"")) | H15: =IF('14'!B6="","",IFERROR(CHOOSE('14'!B6,'質問設定'!$B$6,'質問設定'!$B$7,'質問設定'!$B$8,'質問設定'!$B$9),"")) | I15: =IF('14'!B7="","",IFERROR(CHOOSE('14'!B7,'質問設定'!$B$6,'質問設定'!$B$7,'質問設定'!$B$8,'質問設定'!$B$9),"")) | J15: =IF('14'!B8="","",IFERROR(CHOOSE('14'!B8,'質問設定'!$B$6,'質問設定'!$B$7,'質問設定'!$B$8,'質問設定'!$B$9),"")) | K15: =IF('14'!B9="","",IFERROR(CHOOSE('14'!B9,'質問設定'!$B$6,'質問設定'!$B$7,'質問設定'!$B$8,'質問設定'!$B$9),"")) | L15: =IF('14'!B10="","",IFERROR(CHOOSE('14'!B10,'質問設定'!$B$6,'質問設定'!$B$7,'質問設定'!$B$8,'質問設定'!$B$9),"")) | M15: =IF('14'!B11="","",IFERROR(CHOOSE('14'!B11,'質問設定'!$B$6,'質問設定'!$B$7,'質問設定'!$B$8,'質問設定'!$B$9),"")) | N15: =IF('14'!B12="","",IFERROR(CHOOSE('14'!B12,'質問設定'!$B$6,'質問設定'!$B$7,'質問設定'!$B$8,'質問設定'!$B$9),"")) | O15: =IF('14'!B13="","",IFERROR(CHOOSE('14'!B13,'質問設定'!$B$6,'質問設定'!$B$7,'質問設定'!$B$8,'質問設定'!$B$9),""))
A16: 15 | F16: =IF('15'!B4="","",IFERROR(CHOOSE('15'!B4,'質問設定'!$B$6,'質問設定'!$B$7,'質問設定'!$B$8,'質問設定'!$B$9),"")) | G16: =IF('15'!B5="","",IFERROR(CHOOSE('15'!B5,'質問設定'!$B$6,'質問設定'!$B$7,'質問設定'!$B$8,'質問設定'!$B$9),"")) | H16: =IF('15'!B6="","",IFERROR(CHOOSE('15'!B6,'質問設定'!$B$6,'質問設定'!$B$7,'質問設定'!$B$8,'質問設定'!$B$9),"")) | I16: =IF('15'!B7="","",IFERROR(CHOOSE('15'!B7,'質問設定'!$B$6,'質問設定'!$B$7,'質問設定'!$B$8,'質問設定'!$B$9),"")) | J16: =IF('15'!B8="","",IFERROR(CHOOSE('15'!B8,'質問設定'!$B$6,'質問設定'!$B$7,'質問設定'!$B$8,'質問設定'!$B$9),"")) | K16: =IF('15'!B9="","",IFERROR(CHOOSE('15'!B9,'質問設定'!$B$6,'質問設定'!$B$7,'質問設定'!$B$8,'質問設定'!$B$9),"")) | L16: =IF('15'!B10="","",IFERROR(CHOOSE('15'!B10,'質問設定'!$B$6,'質問設定'!$B$7,'質問設定'!$B$8,'質問設定'!$B$9),"")) | M16: =IF('15'!B11="","",IFERROR(CHOOSE('15'!B11,'質問設定'!$B$6,'質問設定'!$B$7,'質問設定'!$B$8,'質問設定'!$B$9),"")) | N16: =IF('15'!B12="","",IFERROR(CHOOSE('15'!B12,'質問設定'!$B$6,'質問設定'!$B$7,'質問設定'!$B$8,'質問設定'!$B$9),"")) | O16: =IF('15'!B13="","",IFERROR(CHOOSE('15'!B13,'質問設定'!$B$6,'質問設定'!$B$7,'質問設定'!$B$8,'質問設定'!$B$9),""))
A17: 16 | F17: =IF('16'!B4="","",IFERROR(CHOOSE('16'!B4,'質問設定'!$B$6,'質問設定'!$B$7,'質問設定'!$B$8,'質問設定'!$B$9),"")) | G17: =IF('16'!B5="","",IFERROR(CHOOSE('16'!B5,'質問設定'!$B$6,'質問設定'!$B$7,'質問設定'!$B$8,'質問設定'!$B$9),"")) | H17: =IF('16'!B6="","",IFERROR(CHOOSE('16'!B6,'質問設定'!$B$6,'質問設定'!$B$7,'質問設定'!$B$8,'質問設定'!$B$9),"")) | I17: =IF('16'!B7="","",IFERROR(CHOOSE('16'!B7,'質問設定'!$B$6,'質問設定'!$B$7,'質問設定'!$B$8,'質問設定'!$B$9),"")) | J17: =IF('16'!B8="","",IFERROR(CHOOSE('16'!B8,'質問設定'!$B$6,'質問設定'!$B$7,'質問設定'!$B$8,'質問設定'!$B$9),"")) | K17: =IF('16'!B9="","",IFERROR(CHOOSE('16'!B9,'質問設定'!$B$6,'質問設定'!$B$7,'質問設定'!$B$8,'質問設定'!$B$9),"")) | L17: =IF('16'!B10="","",IFERROR(CHOOSE('16'!B10,'質問設定'!$B$6,'質問設定'!$B$7,'質問設定'!$B$8,'質問設定'!$B$9),"")) | M17: =IF('16'!B11="","",IFERROR(CHOOSE('16'!B11,'質問設定'!$B$6,'質問設定'!$B$7,'質問設定'!$B$8,'質問設定'!$B$9),"")) | N17: =IF('16'!B12="","",IFERROR(CHOOSE('16'!B12,'質問設定'!$B$6,'質問設定'!$B$7,'質問設定'!$B$8,'質問設定'!$B$9),"")) | O17: =IF('16'!B13="","",IFERROR(CHOOSE('16'!B13,'質問設定'!$B$6,'質問設定'!$B$7,'質問設定'!$B$8,'質問設定'!$B$9),""))
A18: 17 | F18: =IF('17'!B4="","",IFERROR(CHOOSE('17'!B4,'質問設定'!$B$6,'質問設定'!$B$7,'質問設定'!$B$8,'質問設定'!$B$9),"")) | G18: =IF('17'!B5="","",IFERROR(CHOOSE('17'!B5,'質問設定'!$B$6,'質問設定'!$B$7,'質問設定'!$B$8,'質問設定'!$B$9),"")) | H18: =IF('17'!B6="","",IFERROR(CHOOSE('17'!B6,'質問設定'!$B$6,'質問設定'!$B$7,'質問設定'!$B$8,'質問設定'!$B$9),"")) | I18: =IF('17'!B7="","",IFERROR(CHOOSE('17'!B7,'質問設定'!$B$6,'質問設定'!$B$7,'質問設定'!$B$8,'質問設定'!$B$9),"")) | J18: =IF('17'!B8="","",IFERROR(CHOOSE('17'!B8,'質問設定'!$B$6,'質問設定'!$B$7,'質問設定'!$B$8,'質問設定'!$B$9),"")) | K18: =IF('17'!B9="","",IFERROR(CHOOSE('17'!B9,'質問設定'!$B$6,'質問設定'!$B$7,'質問設定'!$B$8,'質問設定'!$B$9),"")) | L18: =IF('17'!B10="","",IFERROR(CHOOSE('17'!B10,'質問設定'!$B$6,'質問設定'!$B$7,'質問設定'!$B$8,'質問設定'!$B$9),"")) | M18: =IF('17'!B11="","",IFERROR(CHOOSE('17'!B11,'質問設定'!$B$6,'質問設定'!$B$7,'質問設定'!$B$8,'質問設定'!$B$9),"")) | N18: =IF('17'!B12="","",IFERROR(CHOOSE('17'!B12,'質問設定'!$B$6,'質問設定'!$B$7,'質問設定'!$B$8,'質問設定'!$B$9),"")) | O18: =IF('17'!B13="","",IFERROR(CHOOSE('17'!B13,'質問設定'!$B$6,'質問設定'!$B$7,'質問設定'!$B$8,'質問設定'!$B$9),""))
A19: 18 | F19: =IF('18'!B4="","",IFERROR(CHOOSE('18'!B4,'質問設定'!$B$6,'質問設定'!$B$7,'質問設定'!$B$8,'質問設定'!$B$9),"")) | G19: =IF('18'!B5="","",IFERROR(CHOOSE('18'!B5,'質問設定'!$B$6,'質問設定'!$B$7,'質問設定'!$B$8,'質問設定'!$B$9),"")) | H19: =IF('18'!B6="","",IFERROR(CHOOSE('18'!B6,'質問設定'!$B$6,'質問設定'!$B$7,'質問設定'!$B$8,'質問設定'!$B$9),"")) | I19: =IF('18'!B7="","",IFERROR(CHOOSE('18'!B7,'質問設定'!$B$6,'質問設定'!$B$7,'質問設定'!$B$8,'質問設定'!$B$9),"")) | J19: =IF('18'!B8="","",IFERROR(CHOOSE('18'!B8,'質問設定'!$B$6,'質問設定'!$B$7,'質問設定'!$B$8,'質問設定'!$B$9),"")) | K19: =IF('18'!B9="","",IFERROR(CHOOSE('18'!B9,'質問設定'!$B$6,'質問設定'!$B$7,'質問設定'!$B$8,'質問設定'!$B$9),"")) | L19: =IF('18'!B10="","",IFERROR(CHOOSE('18'!B10,'質問設定'!$B$6,'質問設定'!$B$7,'質問設定'!$B$8,'質問設定'!$B$9),"")) | M19: =IF('18'!B11="","",IFERROR(CHOOSE('18'!B11,'質問設定'!$B$6,'質問設定'!$B$7,'質問設定'!$B$8,'質問設定'!$B$9),"")) | N19: =IF('18'!B12="","",IFERROR(CHOOSE('18'!B12,'質問設定'!$B$6,'質問設定'!$B$7,'質問設定'!$B$8,'質問設定'!$B$9),"")) | O19: =IF('18'!B13="","",IFERROR(CHOOSE('18'!B13,'質問設定'!$B$6,'質問設定'!$B$7,'質問設定'!$B$8,'質問設定'!$B$9),""))
A20: 19 | F20: =IF('19'!B4="","",IFERROR(CHOOSE('19'!B4,'質問設定'!$B$6,'質問設定'!$B$7,'質問設定'!$B$8,'質問設定'!$B$9),"")) | G20: =IF('19'!B5="","",IFERROR(CHOOSE('19'!B5,'質問設定'!$B$6,'質問設定'!$B$7,'質問設定'!$B$8,'質問設定'!$B$9),"")) | H20: =IF('19'!B6="","",IFERROR(CHOOSE('19'!B6,'質問設定'!$B$6,'質問設定'!$B$7,'質問設定'!$B$8,'質問設定'!$B$9),"")) | I20: =IF('19'!B7="","",IFERROR(CHOOSE('19'!B7,'質問設定'!$B$6,'質問設定'!$B$7,'質問設定'!$B$8,'質問設定'!$B$9),"")) | J20: =IF('19'!B8="","",IFERROR(CHOOSE('19'!B8,'質問設定'!$B$6,'質問設定'!$B$7,'質問設定'!$B$8,'質問設定'!$B$9),"")) | K20: =IF('19'!B9="","",IFERROR(CHOOSE('19'!B9,'質問設定'!$B$6,'質問設定'!$B$7,'質問設定'!$B$8,'質問設定'!$B$9),"")) | L20: =IF('19'!B10="","",IFERROR(CHOOSE('19'!B10,'質問設定'!$B$6,'質問設定'!$B$7,'質問設定'!$B$8,'質問設定'!$B$9),"")) | M20: =IF('19'!B11="","",IFERROR(CHOOSE('19'!B11,'質問設定'!$B$6,'質問設定'!$B$7,'質問設定'!$B$8,'質問設定'!$B$9),"")) | N20: =IF('19'!B12="","",IFERROR(CHOOSE('19'!B12,'質問設定'!$B$6,'質問設定'!$B$7,'質問設定'!$B$8,'質問設定'!$B$9),"")) | O20: =IF('19'!B13="","",IFERROR(CHOOSE('19'!B13,'質問設定'!$B$6,'質問設定'!$B$7,'質問設定'!$B$8,'質問設定'!$B$9),""))
A21: 20 | F21: =IF('20'!B4="","",IFERROR(CHOOSE('20'!B4,'質問設定'!$B$6,'質問設定'!$B$7,'質問設定'!$B$8,'質問設定'!$B$9),"")) | G21: =IF('20'!B5="","",IFERROR(CHOOSE('20'!B5,'質問設定'!$B$6,'質問設定'!$B$7,'質問設定'!$B$8,'質問設定'!$B$9),"")) | H21: =IF('20'!B6="","",IFERROR(CHOOSE('20'!B6,'質問設定'!$B$6,'質問設定'!$B$7,'質問設定'!$B$8,'質問設定'!$B$9),"")) | I21: =IF('20'!B7="","",IFERROR(CHOOSE('20'!B7,'質問設定'!$B$6,'質問設定'!$B$7,'質問設定'!$B$8,'質問設定'!$B$9),"")) | J21: =IF('20'!B8="","",IFERROR(CHOOSE('20'!B8,'質問設定'!$B$6,'質問設定'!$B$7,'質問設定'!$B$8,'質問設定'!$B$9),"")) | K21: =IF('20'!B9="","",IFERROR(CHOOSE('20'!B9,'質問設定'!$B$6,'質問設定'!$B$7,'質問設定'!$B$8,'質問設定'!$B$9),"")) | L21: =IF('20'!B10="","",IFERROR(CHOOSE('20'!B10,'質問設定'!$B$6,'質問設定'!$B$7,'質問設定'!$B$8,'質問設定'!$B$9),"")) | M21: =IF('20'!B11="","",IFERROR(CHOOSE('20'!B11,'質問設定'!$B$6,'質問設定'!$B$7,'質問設定'!$B$8,'質問設定'!$B$9),"")) | N21: =IF('20'!B12="","",IFERROR(CHOOSE('20'!B12,'質問設定'!$B$6,'質問設定'!$B$7,'質問設定'!$B$8,'質問設定'!$B$9),"")) | O21: =IF('20'!B13="","",IFERROR(CHOOSE('20'!B13,'質問設定'!$B$6,'質問設定'!$B$7,'質問設定'!$B$8,'質問設定'!$B$9),""))
A22: 21 | F22: =IF('21'!B4="","",IFERROR(CHOOSE('21'!B4,'質問設定'!$B$6,'質問設定'!$B$7,'質問設定'!$B$8,'質問設定'!$B$9),"")) | G22: =IF('21'!B5="","",IFERROR(CHOOSE('21'!B5,'質問設定'!$B$6,'質問設定'!$B$7,'質問設定'!$B$8,'質問設定'!$B$9),"")) | H22: =IF('21'!B6="","",IFERROR(CHOOSE('21'!B6,'質問設定'!$B$6,'質問設定'!$B$7,'質問設定'!$B$8,'質問設定'!$B$9),"")) | I22: =IF('21'!B7="","",IFERROR(CHOOSE('21'!B7,'質問設定'!$B$6,'質問設定'!$B$7,'質問設定'!$B$8,'質問設定'!$B$9),"")) | J22: =IF('21'!B8="","",IFERROR(CHOOSE('21'!B8,'質問設定'!$B$6,'質問設定'!$B$7,'質問設定'!$B$8,'質問設定'!$B$9),"")) | K22: =IF('21'!B9="","",IFERROR(CHOOSE('21'!B9,'質問設定'!$B$6,'質問設定'!$B$7,'質問設定'!$B$8,'質問設定'!$B$9),"")) | L22: =IF('21'!B10="","",IFERROR(CHOOSE('21'!B10,'質問設定'!$B$6,'質問設定'!$B$7,'質問設定'!$B$8,'質問設定'!$B$9),"")) | M22: =IF('21'!B11="","",IFERROR(CHOOSE('21'!B11,'質問設定'!$B$6,'質問設定'!$B$7,'質問設定'!$B$8,'質問設定'!$B$9),"")) | N22: =IF('21'!B12="","",IFERROR(CHOOSE('21'!B12,'質問設定'!$B$6,'質問設定'!$B$7,'質問設定'!$B$8,'質問設定'!$B$9),"")) | O22: =IF('21'!B13="","",IFERROR(CHOOSE('21'!B13,'質問設定'!$B$6,'質問設定'!$B$7,'質問設定'!$B$8,'質問設定'!$B$9),""))
A23: 22 | F23: =IF('22'!B4="","",IFERROR(CHOOSE('22'!B4,'質問設定'!$B$6,'質問設定'!$B$7,'質問設定'!$B$8,'質問設定'!$B$9),"")) | G23: =IF('22'!B5="","",IFERROR(CHOOSE('22'!B5,'質問設定'!$B$6,'質問設定'!$B$7,'質問設定'!$B$8,'質問設定'!$B$9),"")) | H23: =IF('22'!B6="","",IFERROR(CHOOSE('22'!B6,'質問設定'!$B$6,'質問設定'!$B$7,'質問設定'!$B$8,'質問設定'!$B$9),"")) | I23: =IF('22'!B7="","",IFERROR(CHOOSE('22'!B7,'質問設定'!$B$6,'質問設定'!$B$7,'質問設定'!$B$8,'質問設定'!$B$9),"")) | J23: =IF('22'!B8="","",IFERROR(CHOOSE('22'!B8,'質問設定'!$B$6,'質問設定'!$B$7,'質問設定'!$B$8,'質問設定'!$B$9),"")) | K23: =IF('22'!B9="","",IFERROR(CHOOSE('22'!B9,'質問設定'!$B$6,'質問設定'!$B$7,'質問設定'!$B$8,'質問設定'!$B$9),"")) | L23: =IF('22'!B10="","",IFERROR(CHOOSE('22'!B10,'質問設定'!$B$6,'質問設定'!$B$7,'質問設定'!$B$8,'質問設定'!$B$9),"")) | M23: =IF('22'!B11="","",IFERROR(CHOOSE('22'!B11,'質問設定'!$B$6,'質問設定'!$B$7,'質問設定'!$B$8,'質問設定'!$B$9),"")) | N23: =IF('22'!B12="","",IFERROR(CHOOSE('22'!B12,'質問設定'!$B$6,'質問設定'!$B$7,'質問設定'!$B$8,'質問設定'!$B$9),"")) | O23: =IF('22'!B13="","",IFERROR(CHOOSE('22'!B13,'質問設定'!$B$6,'質問設定'!$B$7,'質問設定'!$B$8,'質問設定'!$B$9),""))
A24: 23 | F24: =IF('23'!B4="","",IFERROR(CHOOSE('23'!B4,'質問設定'!$B$6,'質問設定'!$B$7,'質問設定'!$B$8,'質問設定'!$B$9),"")) | G24: =IF('23'!B5="","",IFERROR(CHOOSE('23'!B5,'質問設定'!$B$6,'質問設定'!$B$7,'質問設定'!$B$8,'質問設定'!$B$9),"")) | H24: =IF('23'!B6="","",IFERROR(CHOOSE('23'!B6,'質問設定'!$B$6,'質問設定'!$B$7,'質問設定'!$B$8,'質問設定'!$B$9),"")) | I24: =IF('23'!B7="","",IFERROR(CHOOSE('23'!B7,'質問設定'!$B$6,'質問設定'!$B$7,'質問設定'!$B$8,'質問設定'!$B$9),"")) | J24: =IF('23'!B8="","",IFERROR(CHOOSE('23'!B8,'質問設定'!$B$6,'質問設定'!$B$7,'質問設定'!$B$8,'質問設定'!$B$9),"")) | K24: =IF('23'!B9="","",IFERROR(CHOOSE('23'!B9,'質問設定'!$B$6,'質問設定'!$B$7,'質問設定'!$B$8,'質問設定'!$B$9),"")) | L24: =IF('23'!B10="","",IFERROR(CHOOSE('23'!B10,'質問設定'!$B$6,'質問設定'!$B$7,'質問設定'!$B$8,'質問設定'!$B$9),"")) | M24: =IF('23'!B11="","",IFERROR(CHOOSE('23'!B11,'質問設定'!$B$6,'質問設定'!$B$7,'質問設定'!$B$8,'質問設定'!$B$9),"")) | N24: =IF('23'!B12="","",IFERROR(CHOOSE('23'!B12,'質問設定'!$B$6,'質問設定'!$B$7,'質問設定'!$B$8,'質問設定'!$B$9),"")) | O24: =IF('23'!B13="","",IFERROR(CHOOSE('23'!B13,'質問設定'!$B$6,'質問設定'!$B$7,'質問設定'!$B$8,'質問設定'!$B$9),""))
A25: 24 | F25: =IF('24'!B4="","",IFERROR(CHOOSE('24'!B4,'質問設定'!$B$6,'質問設定'!$B$7,'質問設定'!$B$8,'質問設定'!$B$9),"")) | G25: =IF('24'!B5="","",IFERROR(CHOOSE('24'!B5,'質問設定'!$B$6,'質問設定'!$B$7,'質問設定'!$B$8,'質問設定'!$B$9),"")) | H25: =IF('24'!B6="","",IFERROR(CHOOSE('24'!B6,'質問設定'!$B$6,'質問設定'!$B$7,'質問設定'!$B$8,'質問設定'!$B$9),"")) | I25: =IF('24'!B7="","",IFERROR(CHOOSE('24'!B7,'質問設定'!$B$6,'質問設定'!$B$7,'質問設定'!$B$8,'質問設定'!$B$9),"")) | J25: =IF('24'!B8="","",IFERROR(CHOOSE('24'!B8,'質問設定'!$B$6,'質問設定'!$B$7,'質問設定'!$B$8,'質問設定'!$B$9),"")) | K25: =IF('24'!B9="","",IFERROR(CHOOSE('24'!B9,'質問設定'!$B$6,'質問設定'!$B$7,'質問設定'!$B$8,'質問設定'!$B$9),"")) | L25: =IF('24'!B10="","",IFERROR(CHOOSE('24'!B10,'質問設定'!$B$6,'質問設定'!$B$7,'質問設定'!$B$8,'質問設定'!$B$9),"")) | M25: =IF('24'!B11="","",IFERROR(CHOOSE('24'!B11,'質問設定'!$B$6,'質問設定'!$B$7,'質問設定'!$B$8,'質問設定'!$B$9),"")) | N25: =IF('24'!B12="","",IFERROR(CHOOSE('24'!B12,'質問設定'!$B$6,'質問設定'!$B$7,'質問設定'!$B$8,'質問設定'!$B$9),"")) | O25: =IF('24'!B13="","",IFERROR(CHOOSE('24'!B13,'質問設定'!$B$6,'質問設定'!$B$7,'質問設定'!$B$8,'質問設定'!$B$9),""))
A26: 25 | F26: =IF('25'!B4="","",IFERROR(CHOOSE('25'!B4,'質問設定'!$B$6,'質問設定'!$B$7,'質問設定'!$B$8,'質問設定'!$B$9),"")) | G26: =IF('25'!B5="","",IFERROR(CHOOSE('25'!B5,'質問設定'!$B$6,'質問設定'!$B$7,'質問設定'!$B$8,'質問設定'!$B$9),"")) | H26: =IF('25'!B6="","",IFERROR(CHOOSE('25'!B6,'質問設定'!$B$6,'質問設定'!$B$7,'質問設定'!$B$8,'質問設定'!$B$9),"")) | I26: =IF('25'!B7="","",IFERROR(CHOOSE('25'!B7,'質問設定'!$B$6,'質問設定'!$B$7,'質問設定'!$B$8,'質問設定'!$B$9),"")) | J26: =IF('25'!B8="","",IFERROR(CHOOSE('25'!B8,'質問設定'!$B$6,'質問設定'!$B$7,'質問設定'!$B$8,'質問設定'!$B$9),"")) | K26: =IF('25'!B9="","",IFERROR(CHOOSE('25'!B9,'質問設定'!$B$6,'質問設定'!$B$7,'質問設定'!$B$8,'質問設定'!$B$9),"")) | L26: =IF('25'!B10="","",IFERROR(CHOOSE('25'!B10,'質問設定'!$B$6,'質問設定'!$B$7,'質問設定'!$B$8,'質問設定'!$B$9),"")) | M26: =IF('25'!B11="","",IFERROR(CHOOSE('25'!B11,'質問設定'!$B$6,'質問設定'!$B$7,'質問設定'!$B$8,'質問設定'!$B$9),"")) | N26: =IF('25'!B12="","",IFERROR(CHOOSE('25'!B12,'質問設定'!$B$6,'質問設定'!$B$7,'質問設定'!$B$8,'質問設定'!$B$9),"")) | O26: =IF('25'!B13="","",IFERROR(CHOOSE('25'!B13,'質問設定'!$B$6,'質問設定'!$B$7,'質問設定'!$B$8,'質問設定'!$B$9),""))
A27: 26 | F27: =IF('26'!B4="","",IFERROR(CHOOSE('26'!B4,'質問設定'!$B$6,'質問設定'!$B$7,'質問設定'!$B$8,'質問設定'!$B$9),"")) | G27: =IF('26'!B5="","",IFERROR(CHOOSE('26'!B5,'質問設定'!$B$6,'質問設定'!$B$7,'質問設定'!$B$8,'質問設定'!$B$9),"")) | H27: =IF('26'!B6="","",IFERROR(CHOOSE('26'!B6,'質問設定'!$B$6,'質問設定'!$B$7,'質問設定'!$B$8,'質問設定'!$B$9),"")) | I27: =IF('26'!B7="","",IFERROR(CHOOSE('26'!B7,'質問設定'!$B$6,'質問設定'!$B$7,'質問設定'!$B$8,'質問設定'!$B$9),"")) | J27: =IF('26'!B8="","",IFERROR(CHOOSE('26'!B8,'質問設定'!$B$6,'質問設定'!$B$7,'質問設定'!$B$8,'質問設定'!$B$9),"")) | K27: =IF('26'!B9="","",IFERROR(CHOOSE('26'!B9,'質問設定'!$B$6,'質問設定'!$B$7,'質問設定'!$B$8,'質問設定'!$B$9),"")) | L27: =IF('26'!B10="","",IFERROR(CHOOSE('26'!B10,'質問設定'!$B$6,'質問設定'!$B$7,'質問設定'!$B$8,'質問設定'!$B$9),"")) | M27: =IF('26'!B11="","",IFERROR(CHOOSE('26'!B11,'質問設定'!$B$6,'質問設定'!$B$7,'質問設定'!$B$8,'質問設定'!$B$9),"")) | N27: =IF('26'!B12="","",IFERROR(CHOOSE('26'!B12,'質問設定'!$B$6,'質問設定'!$B$7,'質問設定'!$B$8,'質問設定'!$B$9),"")) | O27: =IF('26'!B13="","",IFERROR(CHOOSE('26'!B13,'質問設定'!$B$6,'質問設定'!$B$7,'質問設定'!$B$8,'質問設定'!$B$9),""))
A28: 27 | F28: =IF('27'!B4="","",IFERROR(CHOOSE('27'!B4,'質問設定'!$B$6,'質問設定'!$B$7,'質問設定'!$B$8,'質問設定'!$B$9),"")) | G28: =IF('27'!B5="","",IFERROR(CHOOSE('27'!B5,'質問設定'!$B$6,'質問設定'!$B$7,'質問設定'!$B$8,'質問設定'!$B$9),"")) | H28: =IF('27'!B6="","",IFERROR(CHOOSE('27'!B6,'質問設定'!$B$6,'質問設定'!$B$7,'質問設定'!$B$8,'質問設定'!$B$9),"")) | I28: =IF('27'!B7="","",IFERROR(CHOOSE('27'!B7,'質問設定'!$B$6,'質問設定'!$B$7,'質問設定'!$B$8,'質問設定'!$B$9),"")) | J28: =IF('27'!B8="","",IFERROR(CHOOSE('27'!B8,'質問設定'!$B$6,'質問設定'!$B$7,'質問設定'!$B$8,'質問設定'!$B$9),"")) | K28: =IF('27'!B9="","",IFERROR(CHOOSE('27'!B9,'質問設定'!$B$6,'質問設定'!$B$7,'質問設定'!$B$8,'質問設定'!$B$9),"")) | L28: =IF('27'!B10="","",IFERROR(CHOOSE('27'!B10,'質問設定'!$B$6,'質問設定'!$B$7,'質問設定'!$B$8,'質問設定'!$B$9),"")) | M28: =IF('27'!B11="","",IFERROR(CHOOSE('27'!B11,'質問設定'!$B$6,'質問設定'!$B$7,'質問設定'!$B$8,'質問設定'!$B$9),"")) | N28: =IF('27'!B12="","",IFERROR(CHOOSE('27'!B12,'質問設定'!$B$6,'質問設定'!$B$7,'質問設定'!$B$8,'質問設定'!$B$9),"")) | O28: =IF('27'!B13="","",IFERROR(CHOOSE('27'!B13,'質問設定'!$B$6,'質問設定'!$B$7,'質問設定'!$B$8,'質問設定'!$B$9),""))
A29: 28 | F29: =IF('28'!B4="","",IFERROR(CHOOSE('28'!B4,'質問設定'!$B$6,'質問設定'!$B$7,'質問設定'!$B$8,'質問設定'!$B$9),"")) | G29: =IF('28'!B5="","",IFERROR(CHOOSE('28'!B5,'質問設定'!$B$6,'質問設定'!$B$7,'質問設定'!$B$8,'質問設定'!$B$9),"")) | H29: =IF('28'!B6="","",IFERROR(CHOOSE('28'!B6,'質問設定'!$B$6,'質問設定'!$B$7,'質問設定'!$B$8,'質問設定'!$B$9),"")) | I29: =IF('28'!B7="","",IFERROR(CHOOSE('28'!B7,'質問設定'!$B$6,'質問設定'!$B$7,'質問設定'!$B$8,'質問設定'!$B$9),"")) | J29: =IF('28'!B8="","",IFERROR(CHOOSE('28'!B8,'質問設定'!$B$6,'質問設定'!$B$7,'質問設定'!$B$8,'質問設定'!$B$9),"")) | K29: =IF('28'!B9="","",IFERROR(CHOOSE('28'!B9,'質問設定'!$B$6,'質問設定'!$B$7,'質問設定'!$B$8,'質問設定'!$B$9),"")) | L29: =IF('28'!B10="","",IFERROR(CHOOSE('28'!B10,'質問設定'!$B$6,'質問設定'!$B$7,'質問設定'!$B$8,'質問設定'!$B$9),"")) | M29: =IF('28'!B11="","",IFERROR(CHOOSE('28'!B11,'質問設定'!$B$6,'質問設定'!$B$7,'質問設定'!$B$8,'質問設定'!$B$9),"")) | N29: =IF('28'!B12="","",IFERROR(CHOOSE('28'!B12,'質問設定'!$B$6,'質問設定'!$B$7,'質問設定'!$B$8,'質問設定'!$B$9),"")) | O29: =IF('28'!B13="","",IFERROR(CHOOSE('28'!B13,'質問設定'!$B$6,'質問設定'!$B$7,'質問設定'!$B$8,'質問設定'!$B$9),""))
A30: 29 | F30: =IF('29'!B4="","",IFERROR(CHOOSE('29'!B4,'質問設定'!$B$6,'質問設定'!$B$7,'質問設定'!$B$8,'質問設定'!$B$9),"")) | G30: =IF('29'!B5="","",IFERROR(CHOOSE('29'!B5,'質問設定'!$B$6,'質問設定'!$B$7,'質問設定'!$B$8,'質問設定'!$B$9),"")) | H30: =IF('29'!B6="","",IFERROR(CHOOSE('29'!B6,'質問設定'!$B$6,'質問設定'!$B$7,'質問設定'!$B$8,'質問設定'!$B$9),"")) | I30: =IF('29'!B7="","",IFERROR(CHOOSE('29'!B7,'質問設定'!$B$6,'質問設定'!$B$7,'質問設定'!$B$8,'質問設定'!$B$9),"")) | J30: =IF('29'!B8="","",IFERROR(CHOOSE('29'!B8,'質問設定'!$B$6,'質問設定'!$B$7,'質問設定'!$B$8,'質問設定'!$B$9),"")) | K30: =IF('29'!B9="","",IFERROR(CHOOSE('29'!B9,'質問設定'!$B$6,'質問設定'!$B$7,'質問設定'!$B$8,'質問設定'!$B$9),"")) | L30: =IF('29'!B10="","",IFERROR(CHOOSE('29'!B10,'質問設定'!$B$6,'質問設定'!$B$7,'質問設定'!$B$8,'質問設定'!$B$9),"")) | M30: =IF('29'!B11="","",IFERROR(CHOOSE('29'!B11,'質問設定'!$B$6,'質問設定'!$B$7,'質問設定'!$B$8,'質問設定'!$B$9),"")) | N30: =IF('29'!B12="","",IFERROR(CHOOSE('29'!B12,'質問設定'!$B$6,'質問設定'!$B$7,'質問設定'!$B$8,'質問設定'!$B$9),"")) | O30: =IF('29'!B13="","",IFERROR(CHOOSE('29'!B13,'質問設定'!$B$6,'質問設定'!$B$7,'質問設定'!$B$8,'質問設定'!$B$9),""))
A31: 30 | F31: =IF('30'!B4="","",IFERROR(CHOOSE('30'!B4,'質問設定'!$B$6,'質問設定'!$B$7,'質問設定'!$B$8,'質問設定'!$B$9),"")) | G31: =IF('30'!B5="","",IFERROR(CHOOSE('30'!B5,'質問設定'!$B$6,'質問設定'!$B$7,'質問設定'!$B$8,'質問設定'!$B$9),"")) | H31: =IF('30'!B6="","",IFERROR(CHOOSE('30'!B6,'質問設定'!$B$6,'質問設定'!$B$7,'質問設定'!$B$8,'質問設定'!$B$9),"")) | I31: =IF('30'!B7="","",IFERROR(CHOOSE('30'!B7,'質問設定'!$B$6,'質問設定'!$B$7,'質問設定'!$B$8,'質問設定'!$B$9),"")) | J31: =IF('30'!B8="","",IFERROR(CHOOSE('30'!B8,'質問設定'!$B$6,'質問設定'!$B$7,'質問設定'!$B$8,'質問設定'!$B$9),"")) | K31: =IF('30'!B9="","",IFERROR(CHOOSE('30'!B9,'質問設定'!$B$6,'質問設定'!$B$7,'質問設定'!$B$8,'質問設定'!$B$9),"")) | L31: =IF('30'!B10="","",IFERROR(CHOOSE('30'!B10,'質問設定'!$B$6,'質問設定'!$B$7,'質問設定'!$B$8,'質問設定'!$B$9),"")) | M31: =IF('30'!B11="","",IFERROR(CHOOSE('30'!B11,'質問設定'!$B$6,'質問設定'!$B$7,'質問設定'!$B$8,'質問設定'!$B$9),"")) | N31: =IF('30'!B12="","",IFERROR(CHOOSE('30'!B12,'質問設定'!$B$6,'質問設定'!$B$7,'質問設定'!$B$8,'質問設定'!$B$9),"")) | O31: =IF('30'!B13="","",IFERROR(CHOOSE('30'!B13,'質問設定'!$B$6,'質問設定'!$B$7,'質問設定'!$B$8,'質問設定'!$B$9),""))
A32: 31 | F32: =IF('31'!B4="","",IFERROR(CHOOSE('31'!B4,'質問設定'!$B$6,'質問設定'!$B$7,'質問設定'!$B$8,'質問設定'!$B$9),"")) | G32: =IF('31'!B5="","",IFERROR(CHOOSE('31'!B5,'質問設定'!$B$6,'質問設定'!$B$7,'質問設定'!$B$8,'質問設定'!$B$9),"")) | H32: =IF('31'!B6="","",IFERROR(CHOOSE('31'!B6,'質問設定'!$B$6,'質問設定'!$B$7,'質問設定'!$B$8,'質問設定'!$B$9),"")) | I32: =IF('31'!B7="","",IFERROR(CHOOSE('31'!B7,'質問設定'!$B$6,'質問設定'!$B$7,'質問設定'!$B$8,'質問設定'!$B$9),"")) | J32: =IF('31'!B8="","",IFERROR(CHOOSE('31'!B8,'質問設定'!$B$6,'質問設定'!$B$7,'質問設定'!$B$8,'質問設定'!$B$9),"")) | K32: =IF('31'!B9="","",IFERROR(CHOOSE('31'!B9,'質問設定'!$B$6,'質問設定'!$B$7,'質問設定'!$B$8,'質問設定'!$B$9),"")) | L32: =IF('31'!B10="","",IFERROR(CHOOSE('31'!B10,'質問設定'!$B$6,'質問設定'!$B$7,'質問設定'!$B$8,'質問設定'!$B$9),"")) | M32: =IF('31'!B11="","",IFERROR(CHOOSE('31'!B11,'質問設定'!$B$6,'質問設定'!$B$7,'質問設定'!$B$8,'質問設定'!$B$9),"")) | N32: =IF('31'!B12="","",IFERROR(CHOOSE('31'!B12,'質問設定'!$B$6,'質問設定'!$B$7,'質問設定'!$B$8,'質問設定'!$B$9),"")) | O32: =IF('31'!B13="","",IFERROR(CHOOSE('31'!B13,'質問設定'!$B$6,'質問設定'!$B$7,'質問設定'!$B$8,'質問設定'!$B$9),""))
A33: 32 | F33: =IF('32'!B4="","",IFERROR(CHOOSE('32'!B4,'質問設定'!$B$6,'質問設定'!$B$7,'質問設定'!$B$8,'質問設定'!$B$9),"")) | G33: =IF('32'!B5="","",IFERROR(CHOOSE('32'!B5,'質問設定'!$B$6,'質問設定'!$B$7,'質問設定'!$B$8,'質問設定'!$B$9),"")) | H33: =IF('32'!B6="","",IFERROR(CHOOSE('32'!B6,'質問設定'!$B$6,'質問設定'!$B$7,'質問設定'!$B$8,'質問設定'!$B$9),"")) | I33: =IF('32'!B7="","",IFERROR(CHOOSE('32'!B7,'質問設定'!$B$6,'質問設定'!$B$7,'質問設定'!$B$8,'質問設定'!$B$9),"")) | J33: =IF('32'!B8="","",IFERROR(CHOOSE('32'!B8,'質問設定'!$B$6,'質問設定'!$B$7,'質問設定'!$B$8,'質問設定'!$B$9),"")) | K33: =IF('32'!B9="","",IFERROR(CHOOSE('32'!B9,'質問設定'!$B$6,'質問設定'!$B$7,'質問設定'!$B$8,'質問設定'!$B$9),"")) | L33: =IF('32'!B10="","",IFERROR(CHOOSE('32'!B10,'質問設定'!$B$6,'質問設定'!$B$7,'質問設定'!$B$8,'質問設定'!$B$9),"")) | M33: =IF('32'!B11="","",IFERROR(CHOOSE('32'!B11,'質問設定'!$B$6,'質問設定'!$B$7,'質問設定'!$B$8,'質問設定'!$B$9),"")) | N33: =IF('32'!B12="","",IFERROR(CHOOSE('32'!B12,'質問設定'!$B$6,'質問設定'!$B$7,'質問設定'!$B$8,'質問設定'!$B$9),"")) | O33: =IF('32'!B13="","",IFERROR(CHOOSE('32'!B13,'質問設定'!$B$6,'質問設定'!$B$7,'質問設定'!$B$8,'質問設定'!$B$9),""))
A34: 33 | F34: =IF('33'!B4="","",IFERROR(CHOOSE('33'!B4,'質問設定'!$B$6,'質問設定'!$B$7,'質問設定'!$B$8,'質問設定'!$B$9),"")) | G34: =IF('33'!B5="","",IFERROR(CHOOSE('33'!B5,'質問設定'!$B$6,'質問設定'!$B$7,'質問設定'!$B$8,'質問設定'!$B$9),"")) | H34: =IF('33'!B6="","",IFERROR(CHOOSE('33'!B6,'質問設定'!$B$6,'質問設定'!$B$7,'質問設定'!$B$8,'質問設定'!$B$9),"")) | I34: =IF('33'!B7="","",IFERROR(CHOOSE('33'!B7,'質問設定'!$B$6,'質問設定'!$B$7,'質問設定'!$B$8,'質問設定'!$B$9),"")) | J34: =IF('33'!B8="","",IFERROR(CHOOSE('33'!B8,'質問設定'!$B$6,'質問設定'!$B$7,'質問設定'!$B$8,'質問設定'!$B$9),"")) | K34: =IF('33'!B9="","",IFERROR(CHOOSE('33'!B9,'質問設定'!$B$6,'質問設定'!$B$7,'質問設定'!$B$8,'質問設定'!$B$9),"")) | L34: =IF('33'!B10="","",IFERROR(CHOOSE('33'!B10,'質問設定'!$B$6,'質問設定'!$B$7,'質問設定'!$B$8,'質問設定'!$B$9),"")) | M34: =IF('33'!B11="","",IFERROR(CHOOSE('33'!B11,'質問設定'!$B$6,'質問設定'!$B$7,'質問設定'!$B$8,'質問設定'!$B$9),"")) | N34: =IF('33'!B12="","",IFERROR(CHOOSE('33'!B12,'質問設定'!$B$6,'質問設定'!$B$7,'質問設定'!$B$8,'質問設定'!$B$9),"")) | O34: =IF('33'!B13="","",IFERROR(CHOOSE('33'!B13,'質問設定'!$B$6,'質問設定'!$B$7,'質問設定'!$B$8,'質問設定'!$B$9),""))
A35: 34 | F35: =IF('34'!B4="","",IFERROR(CHOOSE('34'!B4,'質問設定'!$B$6,'質問設定'!$B$7,'質問設定'!$B$8,'質問設定'!$B$9),"")) | G35: =IF('34'!B5="","",IFERROR(CHOOSE('34'!B5,'質問設定'!$B$6,'質問設定'!$B$7,'質問設定'!$B$8,'質問設定'!$B$9),"")) | H35: =IF('34'!B6="","",IFERROR(CHOOSE('34'!B6,'質問設定'!$B$6,'質問設定'!$B$7,'質問設定'!$B$8,'質問設定'!$B$9),"")) | I35: =IF('34'!B7="","",IFERROR(CHOOSE('34'!B7,'質問設定'!$B$6,'質問設定'!$B$7,'質問設定'!$B$8,'質問設定'!$B$9),"")) | J35: =IF('34'!B8="","",IFERROR(CHOOSE('34'!B8,'質問設定'!$B$6,'質問設定'!$B$7,'質問設定'!$B$8,'質問設定'!$B$9),"")) | K35: =IF('34'!B9="","",IFERROR(CHOOSE('34'!B9,'質問設定'!$B$6,'質問設定'!$B$7,'質問設定'!$B$8,'質問設定'!$B$9),"")) | L35: =IF('34'!B10="","",IFERROR(CHOOSE('34'!B10,'質問設定'!$B$6,'質問設定'!$B$7,'質問設定'!$B$8,'質問設定'!$B$9),"")) | M35: =IF('34'!B11="","",IFERROR(CHOOSE('34'!B11,'質問設定'!$B$6,'質問設定'!$B$7,'質問設定'!$B$8,'質問設定'!$B$9),"")) | N35: =IF('34'!B12="","",IFERROR(CHOOSE('34'!B12,'質問設定'!$B$6,'質問設定'!$B$7,'質問設定'!$B$8,'質問設定'!$B$9),"")) | O35: =IF('34'!B13="","",IFERROR(CHOOSE('34'!B13,'質問設定'!$B$6,'質問設定'!$B$7,'質問設定'!$B$8,'質問設定'!$B$9),""))
A36: 35 | F36: =IF('35'!B4="","",IFERROR(CHOOSE('35'!B4,'質問設定'!$B$6,'質問設定'!$B$7,'質問設定'!$B$8,'質問設定'!$B$9),"")) | G36: =IF('35'!B5="","",IFERROR(CHOOSE('35'!B5,'質問設定'!$B$6,'質問設定'!$B$7,'質問設定'!$B$8,'質問設定'!$B$9),"")) | H36: =IF('35'!B6="","",IFERROR(CHOOSE('35'!B6,'質問設定'!$B$6,'質問設定'!$B$7,'質問設定'!$B$8,'質問設定'!$B$9),"")) | I36: =IF('35'!B7="","",IFERROR(CHOOSE('35'!B7,'質問設定'!$B$6,'質問設定'!$B$7,'質問設定'!$B$8,'質問設定'!$B$9),"")) | J36: =IF('35'!B8="","",IFERROR(CHOOSE('35'!B8,'質問設定'!$B$6,'質問設定'!$B$7,'質問設定'!$B$8,'質問設定'!$B$9),"")) | K36: =IF('35'!B9="","",IFERROR(CHOOSE('35'!B9,'質問設定'!$B$6,'質問設定'!$B$7,'質問設定'!$B$8,'質問設定'!$B$9),"")) | L36: =IF('35'!B10="","",IFERROR(CHOOSE('35'!B10,'質問設定'!$B$6,'質問設定'!$B$7,'質問設定'!$B$8,'質問設定'!$B$9),"")) | M36: =IF('35'!B11="","",IFERROR(CHOOSE('35'!B11,'質問設定'!$B$6,'質問設定'!$B$7,'質問設定'!$B$8,'質問設定'!$B$9),"")) | N36: =IF('35'!B12="","",IFERROR(CHOOSE('35'!B12,'質問設定'!$B$6,'質問設定'!$B$7,'質問設定'!$B$8,'質問設定'!$B$9),"")) | O36: =IF('35'!B13="","",IFERROR(CHOOSE('35'!B13,'質問設定'!$B$6,'質問設定'!$B$7,'質問設定'!$B$8,'質問設定'!$B$9),""))
A37: 36 | F37: =IF('36'!B4="","",IFERROR(CHOOSE('36'!B4,'質問設定'!$B$6,'質問設定'!$B$7,'質問設定'!$B$8,'質問設定'!$B$9),"")) | G37: =IF('36'!B5="","",IFERROR(CHOOSE('36'!B5,'質問設定'!$B$6,'質問設定'!$B$7,'質問設定'!$B$8,'質問設定'!$B$9),"")) | H37: =IF('36'!B6="","",IFERROR(CHOOSE('36'!B6,'質問設定'!$B$6,'質問設定'!$B$7,'質問設定'!$B$8,'質問設定'!$B$9),"")) | I37: =IF('36'!B7="","",IFERROR(CHOOSE('36'!B7,'質問設定'!$B$6,'質問設定'!$B$7,'質問設定'!$B$8,'質問設定'!$B$9),"")) | J37: =IF('36'!B8="","",IFERROR(CHOOSE('36'!B8,'質問設定'!$B$6,'質問設定'!$B$7,'質問設定'!$B$8,'質問設定'!$B$9),"")) | K37: =IF('36'!B9="","",IFERROR(CHOOSE('36'!B9,'質問設定'!$B$6,'質問設定'!$B$7,'質問設定'!$B$8,'質問設定'!$B$9),"")) | L37: =IF('36'!B10="","",IFERROR(CHOOSE('36'!B10,'質問設定'!$B$6,'質問設定'!$B$7,'質問設定'!$B$8,'質問設定'!$B$9),"")) | M37: =IF('36'!B11="","",IFERROR(CHOOSE('36'!B11,'質問設定'!$B$6,'質問設定'!$B$7,'質問設定'!$B$8,'質問設定'!$B$9),"")) | N37: =IF('36'!B12="","",IFERROR(CHOOSE('36'!B12,'質問設定'!$B$6,'質問設定'!$B$7,'質問設定'!$B$8,'質問設定'!$B$9),"")) | O37: =IF('36'!B13="","",IFERROR(CHOOSE('36'!B13,'質問設定'!$B$6,'質問設定'!$B$7,'質問設定'!$B$8,'質問設定'!$B$9),""))
A38: 37 | F38: =IF('37'!B4="","",IFERROR(CHOOSE('37'!B4,'質問設定'!$B$6,'質問設定'!$B$7,'質問設定'!$B$8,'質問設定'!$B$9),"")) | G38: =IF('37'!B5="","",IFERROR(CHOOSE('37'!B5,'質問設定'!$B$6,'質問設定'!$B$7,'質問設定'!$B$8,'質問設定'!$B$9),"")) | H38: =IF('37'!B6="","",IFERROR(CHOOSE('37'!B6,'質問設定'!$B$6,'質問設定'!$B$7,'質問設定'!$B$8,'質問設定'!$B$9),"")) | I38: =IF('37'!B7="","",IFERROR(CHOOSE('37'!B7,'質問設定'!$B$6,'質問設定'!$B$7,'質問設定'!$B$8,'質問設定'!$B$9),"")) | J38: =IF('37'!B8="","",IFERROR(CHOOSE('37'!B8,'質問設定'!$B$6,'質問設定'!$B$7,'質問設定'!$B$8,'質問設定'!$B$9),"")) | K38: =IF('37'!B9="","",IFERROR(CHOOSE('37'!B9,'質問設定'!$B$6,'質問設定'!$B$7,'質問設定'!$B$8,'質問設定'!$B$9),"")) | L38: =IF('37'!B10="","",IFERROR(CHOOSE('37'!B10,'質問設定'!$B$6,'質問設定'!$B$7,'質問設定'!$B$8,'質問設定'!$B$9),"")) | M38: =IF('37'!B11="","",IFERROR(CHOOSE('37'!B11,'質問設定'!$B$6,'質問設定'!$B$7,'質問設定'!$B$8,'質問設定'!$B$9),"")) | N38: =IF('37'!B12="","",IFERROR(CHOOSE('37'!B12,'質問設定'!$B$6,'質問設定'!$B$7,'質問設定'!$B$8,'質問設定'!$B$9),"")) | O38: =IF('37'!B13="","",IFERROR(CHOOSE('37'!B13,'質問設定'!$B$6,'質問設定'!$B$7,'質問設定'!$B$8,'質問設定'!$B$9),""))
A39: 38 | F39: =IF('38'!B4="","",IFERROR(CHOOSE('38'!B4,'質問設定'!$B$6,'質問設定'!$B$7,'質問設定'!$B$8,'質問設定'!$B$9),"")) | G39: =IF('38'!B5="","",IFERROR(CHOOSE('38'!B5,'質問設定'!$B$6,'質問設定'!$B$7,'質問設定'!$B$8,'質問設定'!$B$9),"")) | H39: =IF('38'!B6="","",IFERROR(CHOOSE('38'!B6,'質問設定'!$B$6,'質問設定'!$B$7,'質問設定'!$B$8,'質問設定'!$B$9),"")) | I39: =IF('38'!B7="","",IFERROR(CHOOSE('38'!B7,'質問設定'!$B$6,'質問設定'!$B$7,'質問設定'!$B$8,'質問設定'!$B$9),"")) | J39: =IF('38'!B8="","",IFERROR(CHOOSE('38'!B8,'質問設定'!$B$6,'質問設定'!$B$7,'質問設定'!$B$8,'質問設定'!$B$9),"")) | K39: =IF('38'!B9="","",IFERROR(CHOOSE('38'!B9,'質問設定'!$B$6,'質問設定'!$B$7,'質問設定'!$B$8,'質問設定'!$B$9),"")) | L39: =IF('38'!B10="","",IFERROR(CHOOSE('38'!B10,'質問設定'!$B$6,'質問設定'!$B$7,'質問設定'!$B$8,'質問設定'!$B$9),"")) | M39: =IF('38'!B11="","",IFERROR(CHOOSE('38'!B11,'質問設定'!$B$6,'質問設定'!$B$7,'質問設定'!$B$8,'質問設定'!$B$9),"")) | N39: =IF('38'!B12="","",IFERROR(CHOOSE('38'!B12,'質問設定'!$B$6,'質問設定'!$B$7,'質問設定'!$B$8,'質問設定'!$B$9),"")) | O39: =IF('38'!B13="","",IFERROR(CHOOSE('38'!B13,'質問設定'!$B$6,'質問設定'!$B$7,'質問設定'!$B$8,'質問設定'!$B$9),""))
A40: 39 | F40: =IF('39'!B4="","",IFERROR(CHOOSE('39'!B4,'質問設定'!$B$6,'質問設定'!$B$7,'質問設定'!$B$8,'質問設定'!$B$9),"")) | G40: =IF('39'!B5="","",IFERROR(CHOOSE('39'!B5,'質問設定'!$B$6,'質問設定'!$B$7,'質問設定'!$B$8,'質問設定'!$B$9),"")) | H40: =IF('39'!B6="","",IFERROR(CHOOSE('39'!B6,'質問設定'!$B$6,'質問設定'!$B$7,'質問設定'!$B$8,'質問設定'!$B$9),"")) | I40: =IF('39'!B7="","",IFERROR(CHOOSE('39'!B7,'質問設定'!$B$6,'質問設定'!$B$7,'質問設定'!$B$8,'質問設定'!$B$9),"")) | J40: =IF('39'!B8="","",IFERROR(CHOOSE('39'!B8,'質問設定'!$B$6,'質問設定'!$B$7,'質問設定'!$B$8,'質問設定'!$B$9),"")) | K40: =IF('39'!B9="","",IFERROR(CHOOSE('39'!B9,'質問設定'!$B$6,'質問設定'!$B$7,'質問設定'!$B$8,'質問設定'!$B$9),"")) | L40: =IF('39'!B10="","",IFERROR(CHOOSE('39'!B10,'質問設定'!$B$6,'質問設定'!$B$7,'質問設定'!$B$8,'質問設定'!$B$9),"")) | M40: =IF('39'!B11="","",IFERROR(CHOOSE('39'!B11,'質問設定'!$B$6,'質問設定'!$B$7,'質問設定'!$B$8,'質問設定'!$B$9),"")) | N40: =IF('39'!B12="","",IFERROR(CHOOSE('39'!B12,'質問設定'!$B$6,'質問設定'!$B$7,'質問設定'!$B$8,'質問設定'!$B$9),"")) | O40: =IF('39'!B13="","",IFERROR(CHOOSE('39'!B13,'質問設定'!$B$6,'質問設定'!$B$7,'質問設定'!$B$8,'質問設定'!$B$9),""))
...

Sheet 使い方
A1: 共同編集ブック（中学年・10項目）
A3: ■ いちばん大切
A4: ・設問や選択肢を変えたいときは「質問設定」シートだけを編集してください。
A5: ・個人シートの設問文と、Sheet1 の列見出し・回答テキストは自動で連動します。
A7: ■ ツールへの読み込み
A8: ・ツールが読むのは Sheet1 だけです。
A9: ・列の形は Forms の Excel 出力と同じです（ID／時刻／メール／名前／設問…）。
A10: ・学級力ツールでは学年段階を「中学年」に合わせてから読み込んでください。
A12: ■ 子ども（入力）
A13: 1. 自分の出席番号シート（01〜45）を開く
A14: 2. B列に 1〜4 を入れる（プルダウンあり）
A16: ■ 先生
... A21: ※ 開始時刻・完了時刻・メール・名前は空欄で問題ありません。

Sheet 01
A1: 出席番号 01 の回答シート
A2: B列に 1〜4 の数字を入れてください（4=とてもそう思う … 1=そう思わない）。設問文は「質問設定」シートと連動しています。
A3: 設問 | B3: 回答(1-4)
A4: =IF('質問設定'!C12="","",'質問設定'!C12)
A5: =IF('質問設定'!C13="","",'質問設定'!C13)
A6: =IF('質問設定'!C14="","",'質問設定'!C14)
A7: =IF('質問設定'!C15="","",'質問設定'!C15)
A8: =IF('質問設定'!C16="","",'質問設定'!C16)
A9: =IF('質問設定'!C17="","",'質問設定'!C17)
A10: =IF('質問設定'!C18="","",'質問設定'!C18)
A11: =IF('質問設定'!C19="","",'質問設定'!C19)
A12: =IF('質問設定'!C20="","",'質問設定'!C20)
A13: =IF('質問設定'!C21="","",'質問設定'!C21)

Sheet 02
A1: 出席番号 02 の回答シート
A2: B列に 1〜4 の数字を入れてください（4=とてもそう思う … 1=そう思わない）。設問文は「質問設定」シートと連動しています。
A3: 設問 | B3: 回答(1-4)
A4: =IF('質問設定'!C12="","",'質問設定'!C12)
A5: =IF('質問設定'!C13="","",'質問設定'!C13)
A6: =IF('質問設定'!C14="","",'質問設定'!C14)
A7: =IF('質問設定'!C15="","",'質問設定'!C15)
A8: =IF('質問設定'!C16="","",'質問設定'!C16)
A9: =IF('質問設定'!C17="","",'質問設定'!C17)
A10: =IF('質問設定'!C18="","",'質問設定'!C18)
A11: =IF('質問設定'!C19="","",'質問設定'!C19)
A12: =IF('質問設定'!C20="","",'質問設定'!C20)
A13: =IF('質問設定'!C21="","",'質問設定'!C21)

Sheet 03
A1: 出席番号 03 の回答シート
A2: B列に 1〜4 の数字を入れてください（4=とてもそう思う … 1=そう思わない）。設問文は「質問設定」シートと連動しています。
A3: 設問 | B3: 回答(1-4)
A4: =IF('質問設定'!C12="","",'質問設定'!C12)
A5: =IF('質問設定'!C13="","",'質問設定'!C13)
A6: =IF('質問設定'!C14="","",'質問設定'!C14)
A7: =IF('質問設定'!C15="","",'質問設定'!C15)
A8: =IF('質問設定'!C16="","",'質問設定'!C16)
A9: =IF('質問設定'!C17="","",'質問設定'!C17)
A10: =IF('質問設定'!C18="","",'質問設定'!C18)
A11: =IF('質問設定'!C19="","",'質問設定'!C19)
A12: =IF('質問設定'!C20="","",'質問設定'!C20)
A13: =IF('質問設定'!C21="","",'質問設定'!C21)

Sheet 04
A1: 出席番号 04 の回答シート
A2: B列に 1〜4 の数字を入れてください（4=とてもそう思う … 1=そう思わない）。設問文は「質問設定」シートと連動しています。
A3: 設問 | B3: 回答(1-4)
A4: =IF('質問設定'!C12="","",'質問設定'!C12)
A5: =IF('質問設定'!C13="","",'質問設定'!C13)
A6: =IF('質問設定'!C14="","",'質問設定'!C14)
A7: =IF('質問設定'!C15="","",'質問設定'!C15)
A8: =IF('質問設定'!C16="","",'質問設定'!C16)
A9: =IF('質問設定'!C17="","",'質問設定'!C17)
A10: =IF('質問設定'!C18="","",'質問設定'!C18)
A11: =IF('質問設定'!C19="","",'質問設定'!C19)
A12: =IF('質問設定'!C20="","",'質問設定'!C20)
A13: =IF('質問設定'!C21="","",'質問設定'!C21)

Sheet 05
A1: 出席番号 05 の回答シート
A2: B列に 1〜4 の数字を入れてください（4=とてもそう思う … 1=そう思わない）。設問文は「質問設定」シートと連動しています。
A3: 設問 | B3: 回答(1-4)
A4: =IF('質問設定'!C12="","",'質問設定'!C12)
A5: =IF('質問設定'!C13="","",'質問設定'!C13)
A6: =IF('質問設定'!C14="","",'質問設定'!C14)
A7: =IF('質問設定'!C15="","",'質問設定'!C15)
A8: =IF('質問設定'!C16="","",'質問設定'!C16)
A9: =IF('質問設定'!C17="","",'質問設定'!C17)
A10: =IF('質問設定'!C18="","",'質問設定'!C18)
A11: =IF('質問設定'!C19="","",'質問設定'!C19)
A12: =IF('質問設定'!C20="","",'質問設定'!C20)
A13: =IF('質問設定'!C21="","",'質問設定'!C21)

Sheet 06
A1: 出席番号 06 の回答シート
A2: B列に 1〜4 の数字を入れてください（4=とてもそう思う … 1=そう思わない）。設問文は「質問設定」シートと連動しています。
A3: 設問 | B3: 回答(1-4)
A4: =IF('質問設定'!C12="","",'質問設定'!C12)
A5: =IF('質問設定'!C13="","",'質問設定'!C13)
A6: =IF('質問設定'!C14="","",'質問設定'!C14)
A7: =IF('質問設定'!C15="","",'質問設定'!C15)
A8: =IF('質問設定'!C16="","",'質問設定'!C16)
A9: =IF('質問設定'!C17="","",'質問設定'!C17)
A10: =IF('質問設定'!C18="","",'質問設定'!C18)
A11: =IF('質問設定'!C19="","",'質問設定'!C19)
A12: =IF('質問設定'!C20="","",'質問設定'!C20)
A13: =IF('質問設定'!C21="","",'質問設定'!C21)

Sheet 07
A1: 出席番号 07 の回答シート
A2: B列に 1〜4 の数字を入れてください（4=とてもそう思う … 1=そう思わない）。設問文は「質問設定」シートと連動しています。
A3: 設問 | B3: 回答(1-4)
A4: =IF('質問設定'!C12="","",'質問設定'!C12)
A5: =IF('質問設定'!C13="","",'質問設定'!C13)
A6: =IF('質問設定'!C14="","",'質問設定'!C14)
A7: =IF('質問設定'!C15="","",'質問設定'!C15)
A8: =IF('質問設定'!C16="","",'質問設定'!C16)
A9: =IF('質問設定'!C17="","",'質問設定'!C17)
A10: =IF('質問設定'!C18="","",'質問設定'!C18)
A11: =IF('質問設定'!C19="","",'質問設定'!C19)
A12: =IF('質問設定'!C20="","",'質問設定'!C20)
A13: =IF('質問設定'!C21="","",'質問設定'!C21)

Sheet 08
A1: 出席番号 08 の回答シート
A2: B列に 1〜4 の数字を入れてください（4=とてもそう思う … 1=そう思わない）。設問文は「質問設定」シートと連動しています。
A3: 設問 | B3: 回答(1-4)
A4: =IF('質問設定'!C12="","",'質問設定'!C12)
A5: =IF('質問設定'!C13="","",'質問設定'!C13)
A6: =IF('質問設定'!C14="","",'質問設定'!C14)
A7: =IF('質問設定'!C15="","",'質問設定'!C15)
A8: =IF('質問設定'!C16="","",'質問設定'!C16)
A9: =IF('質問設定'!C17="","",'質問設定'!C17)
A10: =IF('質問設定'!C18="","",'質問設定'!C18)
A11: =IF('質問設定'!C19="","",'質問設定'!C19)
A12: =IF('質問設定'!C20="","",'質問設定'!C20)
A13: =IF('質問設定'!C21="","",'質問設定'!C21)

Sheet 09
A1: 出席番号 09 の回答シート
A2: B列に 1〜4 の数字を入れてください（4=とてもそう思う … 1=そう思わない）。設問文は「質問設定」シートと連動しています。
A3: 設問 | B3: 回答(1-4)
A4: =IF('質問設定'!C12="","",'質問設定'!C12)
A5: =IF('質問設定'!C13="","",'質問設定'!C13)
A6: =IF('質問設定'!C14="","",'質問設定'!C14)
A7: =IF('質問設定'!C15="","",'質問設定'!C15)
A8: =IF('質問設定'!C16="","",'質問設定'!C16)
A9: =IF('質問設定'!C17="","",'質問設定'!C17)
A10: =IF('質問設定'!C18="","",'質問設定'!C18)
A11: =IF('質問設定'!C19="","",'質問設定'!C19)
A12: =IF('質問設定'!C20="","",'質問設定'!C20)
A13: =IF('質問設定'!C21="","",'質問設定'!C21)

Sheet 10
A1: 出席番号 10 の回答シート
A2: B列に 1〜4 の数字を入れてください（4=とてもそう思う … 1=そう思わない）。設問文は「質問設定」シートと連動しています。
A3: 設問 | B3: 回答(1-4)
A4: =IF('質問設定'!C12="","",'質問設定'!C12)
A5: =IF('質問設定'!C13="","",'質問設定'!C13)
A6: =IF('質問設定'!C14="","",'質問設定'!C14)
A7: =IF('質問設定'!C15="","",'質問設定'!C15)
A8: =IF('質問設定'!C16="","",'質問設定'!C16)
A9: =IF('質問設定'!C17="","",'質問設定'!C17)
A10: =IF('質問設定'!C18="","",'質問設定'!C18)
A11: =IF('質問設定'!C19="","",'質問設定'!C19)
A12: =IF('質問設定'!C20="","",'質問設定'!C20)
A13: =IF('質問設定'!C21="","",'質問設定'!C21)

Sheet 11
A1: 出席番号 11 の回答シート
A2: B列に 1〜4 の数字を入れてください（4=とてもそう思う … 1=そう思わない）。設問文は「質問設定」シートと連動しています。
A3: 設問 | B3: 回答(1-4)
A4: =IF('質問設定'!C12="","",'質問設定'!C12)
A5: =IF('質問設定'!C13="","",'質問設定'!C13)
A6: =IF('質問設定'!C14="","",'質問設定'!C14)
A7: =IF('質問設定'!C15="","",'質問設定'!C15)
A8: =IF('質問設定'!C16="","",'質問設定'!C16)
A9: =IF('質問設定'!C17="","",'質問設定'!C17)
A10: =IF('質問設定'!C18="","",'質問設定'!C18)
A11: =IF('質問設定'!C19="","",'質問設定'!C19)
A12: =IF('質問設定'!C20="","",'質問設定'!C20)
A13: =IF('質問設定'!C21="","",'質問設定'!C21)

Sheet 12
A1: 出席番号 12 の回答シート
A2: B列に 1〜4 の数字を入れてください（4=とてもそう思う … 1=そう思わない）。設問文は「質問設定」シートと連動しています。
A3: 設問 | B3: 回答(1-4)
A4: =IF('質問設定'!C12="","",'質問設定'!C12)
A5: =IF('質問設定'!C13="","",'質問設定'!C13)
A6: =IF('質問設定'!C14="","",'質問設定'!C14)
A7: =IF('質問設定'!C15="","",'質問設定'!C15)
A8: =IF('質問設定'!C16="","",'質問設定'!C16)
A9: =IF('質問設定'!C17="","",'質問設定'!C17)
A10: =IF('質問設定'!C18="","",'質問設定'!C18)
A11: =IF('質問設定'!C19="","",'質問設定'!C19)
A12: =IF('質問設定'!C20="","",'質問設定'!C20)
A13: =IF('質問設定'!C21="","",'質問設定'!C21)

Sheet 13
A1: 出席番号 13 の回答シート
A2: B列に 1〜4 の数字を入れてください（4=とてもそう思う … 1=そう思わない）。設問文は「質問設定」シートと連動しています。
A3: 設問 | B3: 回答(1-4)
A4: =IF('質問設定'!C12="","",'質問設定'!C12)
A5: =IF('質問設定'!C13="","",'質問設定'!C13)
A6: =IF('質問設定'!C14="","",'質問設定'!C14)
A7: =IF('質問設定'!C15="","",'質問設定'!C15)
A8: =IF('質問設定'!C16="","",'質問設定'!C16)
A9: =IF('質問設定'!C17="","",'質問設定'!C17)
A10: =IF('質問設定'!C18="","",'質問設定'!C18)
A11: =IF('質問設定'!C19="","",'質問設定'!C19)
A12: =IF('質問設定'!C20="","",'質問設定'!C20)
A13: =IF('質問設定'!C21="","",'質問設定'!C21)

Sheet 14
A1: 出席番号 14 の回答シート
A2: B列に 1〜4 の数字を入れてください（4=とてもそう思う … 1=そう思わない）。設問文は「質問設定」シートと連動しています。
A3: 設問 | B3: 回答(1-4)
A4: =IF('質問設定'!C12="","",'質問設定'!C12)
A5: =IF('質問設定'!C13="","",'質問設定'!C13)
A6: =IF('質問設定'!C14="","",'質問設定'!C14)
A7: =IF('質問設定'!C15="","",'質問設定'!C15)
A8: =IF('質問設定'!C16="","",'質問設定'!C16)
A9: =IF('質問設定'!C17="","",'質問設定'!C17)
A10: =IF('質問設定'!C18="","",'質問設定'!C18)
A11: =IF('質問設定'!C19="","",'質問設定'!C19)
A12: =IF('質問設定'!C20="","",'質問設定'!C20)
A13: =IF('質問設定'!C21="","",'質問設定'!C21)

Sheet 15
A1: 出席番号 15 の回答シート
A2: B列に 1〜4 の数字を入れてください（4=とてもそう思う … 1=そう思わない）。設問文は「質問設定」シートと連動しています。
A3: 設問 | B3: 回答(1-4)
A4: =IF('質問設定'!C12="","",'質問設定'!C12)
A5: =IF('質問設定'!C13="","",'質問設定'!C13)
A6: =IF('質問設定'!C14="","",'質問設定'!C14)
A7: =IF('質問設定'!C15="","",'質問設定'!C15)
A8: =IF('質問設定'!C16="","",'質問設定'!C16)
A9: =IF('質問設定'!C17="","",'質問設定'!C17)
A10: =IF('質問設定'!C18="","",'質問設定'!C18)
A11: =IF('質問設定'!C19="","",'質問設定'!C19)
A12: =IF('質問設定'!C20="","",'質問設定'!C20)
A13: =IF('質問設定'!C21="","",'質問設定'!C21)

Sheet 16
A1: 出席番号 16 の回答シート
A2: B列に 1〜4 の数字を入れてください（4=とてもそう思う … 1=そう思わない）。設問文は「質問設定」シートと連動しています。
A3: 設問 | B3: 回答(1-4)
A4: =IF('質問設定'!C12="","",'質問設定'!C12)
A5: =IF('質問設定'!C13="","",'質問設定'!C13)
A6: =IF('質問設定'!C14="","",'質問設定'!C14)
A7: =IF('質問設定'!C15="","",'質問設定'!C15)
A8: =IF('質問設定'!C16="","",'質問設定'!C16)
A9: =IF('質問設定'!C17="","",'質問設定'!C17)
A10: =IF('質問設定'!C18="","",'質問設定'!C18)
A11: =IF('質問設定'!C19="","",'質問設定'!C19)
A12: =IF('質問設定'!C20="","",'質問設定'!C20)
A13: =IF('質問設定'!C21="","",'質問設定'!C21)

Sheet 17
A1: 出席番号 17 の回答シート
A2: B列に 1〜4 の数字を入れてください（4=とてもそう思う … 1=そう思わない）。設問文は「質問設定」シートと連動しています。
A3: 設問 | B3: 回答(1-4)
A4: =IF('質問設定'!C12="","",'質問設定'!C12)
A5: =IF('質問設定'!C13="","",'質問設定'!C13)
A6: =IF('質問設定'!C14="","",'質問設定'!C14)
A7: =IF('質問設定'!C15="","",'質問設定'!C15)
A8: =IF('質問設定'!C16="","",'質問設定'!C16)
A9: =IF('質問設定'!C17="","",'質問設定'!C17)
A10: =IF('質問設定'!C18="","",'質問設定'!C18)
A11: =IF('質問設定'!C19="","",'質問設定'!C19)
A12: =IF('質問設定'!C20="","",'質問設定'!C20)
A13: =IF('質問設定'!C21="","",'質問設定'!C21)

Sheet 18
A1: 出席番号 18 の回答シート
A2: B列に 1〜4 の数字を入れてください（4=とてもそう思う … 1=そう思わない）。設問文は「質問設定」シートと連動しています。
A3: 設問 | B3: 回答(1-4)
A4: =IF('質問設定'!C12="","",'質問設定'!C12)
A5: =IF('質問設定'!C13="","",'質問設定'!C13)
A6: =IF('質問設定'!C14="","",'質問設定'!C14)
A7: =IF('質問設定'!C15="","",'質問設定'!C15)
A8: =IF('質問設定'!C16="","",'質問設定'!C16)
A9: =IF('質問設定'!C17="","",'質問設定'!C17)
A10: =IF('質問設定'!C18="","",'質問設定'!C18)
A11: =IF('質問設定'!C19="","",'質問設定'!C19)
A12: =IF('質問設定'!C20="","",'質問設定'!C20)
A13: =IF('質問設定'!C21="","",'質問設定'!C21)

Sheet 19
A1: 出席番号 19 の回答シート
A2: B列に 1〜4 の数字を入れてください（4=とてもそう思う … 1=そう思わない）。設問文は「質問設定」シートと連動しています。
A3: 設問 | B3: 回答(1-4)
A4: =IF('質問設定'!C12="","",'質問設定'!C12)
A5: =IF('質問設定'!C13="","",'質問設定'!C13)
A6: =IF('質問設定'!C14="","",'質問設定'!C14)
A7: =IF('質問設定'!C15="","",'質問設定'!C15)
A8: =IF('質問設定'!C16="","",'質問設定'!C16)
A9: =IF('質問設定'!C17="","",'質問設定'!C17)
A10: =IF('質問設定'!C18="","",'質問設定'!C18)
A11: =IF('質問設定'!C19="","",'質問設定'!C19)
A12: =IF('質問設定'!C20="","",'質問設定'!C20)
A13: =IF('質問設定'!C21="","",'質問設定'!C21)

Sheet 20
A1: 出席番号 20 の回答シート
A2: B列に 1〜4 の数字を入れてください（4=とてもそう思う … 1=そう思わない）。設問文は「質問設定」シートと連動しています。
A3: 設問 | B3: 回答(1-4)
A4: =IF('質問設定'!C12="","",'質問設定'!C12)
A5: =IF('質問設定'!C13="","",'質問設定'!C13)
A6: =IF('質問設定'!C14="","",'質問設定'!C14)
A7: =IF('質問設定'!C15="","",'質問設定'!C15)
A8: =IF('質問設定'!C16="","",'質問設定'!C16)
A9: =IF('質問設定'!C17="","",'質問設定'!C17)
A10: =IF('質問設定'!C18="","",'質問設定'!C18)
A11: =IF('質問設定'!C19="","",'質問設定'!C19)
A12: =IF('質問設定'!C20="","",'質問設定'!C20)
A13: =IF('質問設定'!C21="","",'質問設定'!C21)

Sheet 21
A1: 出席番号 21 の回答シート
A2: B列に 1〜4 の数字を入れてください（4=とてもそう思う … 1=そう思わない）。設問文は「質問設定」シートと連動しています。
A3: 設問 | B3: 回答(1-4)
A4: =IF('質問設定'!C12="","",'質問設定'!C12)
A5: =IF('質問設定'!C13="","",'質問設定'!C13)
A6: =IF('質問設定'!C14="","",'質問設定'!C14)
A7: =IF('質問設定'!C15="","",'質問設定'!C15)
A8: =IF('質問設定'!C16="","",'質問設定'!C16)
A9: =IF('質問設定'!C17="","",'質問設定'!C17)
A10: =IF('質問設定'!C18="","",'質問設定'!C18)
A11: =IF('質問設定'!C19="","",'質問設定'!C19)
A12: =IF('質問設定'!C20="","",'質問設定'!C20)
A13: =IF('質問設定'!C21="","",'質問設定'!C21)

Sheet 22
A1: 出席番号 22 の回答シート
A2: B列に 1〜4 の数字を入れてください（4=とてもそう思う … 1=そう思わない）。設問文は「質問設定」シートと連動しています。
A3: 設問 | B3: 回答(1-4)
A4: =IF('質問設定'!C12="","",'質問設定'!C12)
A5: =IF('質問設定'!C13="","",'質問設定'!C13)
A6: =IF('質問設定'!C14="","",'質問設定'!C14)
A7: =IF('質問設定'!C15="","",'質問設定'!C15)
A8: =IF('質問設定'!C16="","",'質問設定'!C16)
A9: =IF('質問設定'!C17="","",'質問設定'!C17)
A10: =IF('質問設定'!C18="","",'質問設定'!C18)
A11: =IF('質問設定'!C19="","",'質問設定'!C19)
A12: =IF('質問設定'!C20="","",'質問設定'!C20)
A13: =IF('質問設定'!C21="","",'質問設定'!C21)

Sheet 23
A1: 出席番号 23 の回答シート
A2: B列に 1〜4 の数字を入れてください（4=とてもそう思う … 1=そう思わない）。設問文は「質問設定」シートと連動しています。
A3: 設問 | B3: 回答(1-4)
A4: =IF('質問設定'!C12="","",'質問設定'!C12)
A5: =IF('質問設定'!C13="","",'質問設定'!C13)
A6: =IF('質問設定'!C14="","",'質問設定'!C14)
A7: =IF('質問設定'!C15="","",'質問設定'!C15)
A8: =IF('質問設定'!C16="","",'質問設定'!C16)
A9: =IF('質問設定'!C17="","",'質問設定'!C17)
A10: =IF('質問設定'!C18="","",'質問設定'!C18)
A11: =IF('質問設定'!C19="","",'質問設定'!C19)
A12: =IF('質問設定'!C20="","",'質問設定'!C20)
A13: =IF('質問設定'!C21="","",'質問設定'!C21)

Sheet 24
A1: 出席番号 24 の回答シート
A2: B列に 1〜4 の数字を入れてください（4=とてもそう思う … 1=そう思わない）。設問文は「質問設定」シートと連動しています。
A3: 設問 | B3: 回答(1-4)
A4: =IF('質問設定'!C12="","",'質問設定'!C12)
A5: =IF('質問設定'!C13="","",'質問設定'!C13)
A6: =IF('質問設定'!C14="","",'質問設定'!C14)
A7: =IF('質問設定'!C15="","",'質問設定'!C15)
A8: =IF('質問設定'!C16="","",'質問設定'!C16)
A9: =IF('質問設定'!C17="","",'質問設定'!C17)
A10: =IF('質問設定'!C18="","",'質問設定'!C18)
A11: =IF('質問設定'!C19="","",'質問設定'!C19)
A12: =IF('質問設定'!C20="","",'質問設定'!C20)
A13: =IF('質問設定'!C21="","",'質問設定'!C21)

Sheet 25
A1: 出席番号 25 の回答シート
A2: B列に 1〜4 の数字を入れてください（4=とてもそう思う … 1=そう思わない）。設問文は「質問設定」シートと連動しています。
A3: 設問 | B3: 回答(1-4)
A4: =IF('質問設定'!C12="","",'質問設定'!C12)
A5: =IF('質問設定'!C13="","",'質問設定'!C13)
A6: =IF('質問設定'!C14="","",'質問設定'!C14)
A7: =IF('質問設定'!C15="","",'質問設定'!C15)
A8: =IF('質問設定'!C16="","",'質問設定'!C16)
A9: =IF('質問設定'!C17="","",'質問設定'!C17)
A10: =IF('質問設定'!C18="","",'質問設定'!C18)
A11: =IF('質問設定'!C19="","",'質問設定'!C19)
A12: =IF('質問設定'!C20="","",'質問設定'!C20)
A13: =IF('質問設定'!C21="","",'質問設定'!C21)

Sheet 26
A1: 出席番号 26 の回答シート
A2: B列に 1〜4 の数字を入れてください（4=とてもそう思う … 1=そう思わない）。設問文は「質問設定」シートと連動しています。
A3: 設問 | B3: 回答(1-4)
A4: =IF('質問設定'!C12="","",'質問設定'!C12)
A5: =IF('質問設定'!C13="","",'質問設定'!C13)
A6: =IF('質問設定'!C14="","",'質問設定'!C14)
A7: =IF('質問設定'!C15="","",'質問設定'!C15)
A8: =IF('質問設定'!C16="","",'質問設定'!C16)
A9: =IF('質問設定'!C17="","",'質問設定'!C17)
A10: =IF('質問設定'!C18="","",'質問設定'!C18)
A11: =IF('質問設定'!C19="","",'質問設定'!C19)
A12: =IF('質問設定'!C20="","",'質問設定'!C20)
A13: =IF('質問設定'!C21="","",'質問設定'!C21)

Sheet 27
A1: 出席番号 27 の回答シート
A2: B列に 1〜4 の数字を入れてください（4=とてもそう思う … 1=そう思わない）。設問文は「質問設定」シートと連動しています。
A3: 設問 | B3: 回答(1-4)
A4: =IF('質問設定'!C12="","",'質問設定'!C12)
A5: =IF('質問設定'!C13="","",'質問設定'!C13)
A6: =IF('質問設定'!C14="","",'質問設定'!C14)
A7: =IF('質問設定'!C15="","",'質問設定'!C15)
A8: =IF('質問設定'!C16="","",'質問設定'!C16)
A9: =IF('質問設定'!C17="","",'質問設定'!C17)
A10: =IF('質問設定'!C18="","",'質問設定'!C18)
A11: =IF('質問設定'!C19="","",'質問設定'!C19)
A12: =IF('質問設定'!C20="","",'質問設定'!C20)
A13: =IF('質問設定'!C21="","",'質問設定'!C21)

Sheet 28
A1: 出席番号 28 の回答シート
A2: B列に 1〜4 の数字を入れてください（4=とてもそう思う … 1=そう思わない）。設問文は「質問設定」シートと連動しています。
A3: 設問 | B3: 回答(1-4)
A4: =IF('質問設定'!C12="","",'質問設定'!C12)
A5: =IF('質問設定'!C13="","",'質問設定'!C13)
A6: =IF('質問設定'!C14="","",'質問設定'!C14)
A7: =IF('質問設定'!C15="","",'質問設定'!C15)
A8: =IF('質問設定'!C16="","",'質問設定'!C16)
A9: =IF('質問設定'!C17="","",'質問設定'!C17)
A10: =IF('質問設定'!C18="","",'質問設定'!C18)
A11: =IF('質問設定'!C19="","",'質問設定'!C19)
A12: =IF('質問設定'!C20="","",'質問設定'!C20)
A13: =IF('質問設定'!C21="","",'質問設定'!C21)

Sheet 29
A1: 出席番号 29 の回答シート
A2: B列に 1〜4 の数字を入れてください（4=とてもそう思う … 1=そう思わない）。設問文は「質問設定」シートと連動しています。
A3: 設問 | B3: 回答(1-4)
A4: =IF('質問設定'!C12="","",'質問設定'!C12)
A5: =IF('質問設定'!C13="","",'質問設定'!C13)
A6: =IF('質問設定'!C14="","",'質問設定'!C14)
A7: =IF('質問設定'!C15="","",'質問設定'!C15)
A8: =IF('質問設定'!C16="","",'質問設定'!C16)
A9: =IF('質問設定'!C17="","",'質問設定'!C17)
A10: =IF('質問設定'!C18="","",'質問設定'!C18)
A11: =IF('質問設定'!C19="","",'質問設定'!C19)
A12: =IF('質問設定'!C20="","",'質問設定'!C20)
A13: =IF('質問設定'!C21="","",'質問設定'!C21)

Sheet 30
A1: 出席番号 30 の回答シート
A2: B列に 1〜4 の数字を入れてください（4=とてもそう思う … 1=そう思わない）。設問文は「質問設定」シートと連動しています。
A3: 設問 | B3: 回答(1-4)
A4: =IF('質問設定'!C12="","",'質問設定'!C12)
A5: =IF('質問設定'!C13="","",'質問設定'!C13)
A6: =IF('質問設定'!C14="","",'質問設定'!C14)
A7: =IF('質問設定'!C15="","",'質問設定'!C15)
A8: =IF('質問設定'!C16="","",'質問設定'!C16)
A9: =IF('質問設定'!C17="","",'質問設定'!C17)
A10: =IF('質問設定'!C18="","",'質問設定'!C18)
A11: =IF('質問設定'!C19="","",'質問設定'!C19)
A12: =IF('質問設定'!C20="","",'質問設定'!C20)
A13: =IF('質問設定'!C21="","",'質問設定'!C21)

Sheet 31
A1: 出席番号 31 の回答シート
A2: B列に 1〜4 の数字を入れてください（4=とてもそう思う … 1=そう思わない）。設問文は「質問設定」シートと連動しています。
A3: 設問 | B3: 回答(1-4)
A4: =IF('質問設定'!C12="","",'質問設定'!C12)
A5: =IF('質問設定'!C13="","",'質問設定'!C13)
A6: =IF('質問設定'!C14="","",'質問設定'!C14)
A7: =IF('質問設定'!C15="","",'質問設定'!C15)
A8: =IF('質問設定'!C16="","",'質問設定'!C16)
A9: =IF('質問設定'!C17="","",'質問設定'!C17)
A10: =IF('質問設定'!C18="","",'質問設定'!C18)
A11: =IF('質問設定'!C19="","",'質問設定'!C19)
A12: =IF('質問設定'!C20="","",'質問設定'!C20)
A13: =IF('質問設定'!C21="","",'質問設定'!C21)

Sheet 32
A1: 出席番号 32 の回答シート
A2: B列に 1〜4 の数字を入れてください（4=とてもそう思う … 1=そう思わない）。設問文は「質問設定」シートと連動しています。
A3: 設問 | B3: 回答(1-4)
A4: =IF('質問設定'!C12="","",'質問設定'!C12)
A5: =IF('質問設定'!C13="","",'質問設定'!C13)
A6: =IF('質問設定'!C14="","",'質問設定'!C14)
A7: =IF('質問設定'!C15="","",'質問設定'!C15)
A8: =IF('質問設定'!C16="","",'質問設定'!C16)
A9: =IF('質問設定'!C17="","",'質問設定'!C17)
A10: =IF('質問設定'!C18="","",'質問設定'!C18)
A11: =IF('質問設定'!C19="","",'質問設定'!C19)
A12: =IF('質問設定'!C20="","",'質問設定'!C20)
A13: =IF('質問設定'!C21="","",'質問設定'!C21)

Sheet 33
A1: 出席番号 33 の回答シート
A2: B列に 1〜4 の数字を入れてください（4=とてもそう思う … 1=そう思わない）。設問文は「質問設定」シートと連動しています。
A3: 設問 | B3: 回答(1-4)
A4: =IF('質問設定'!C12="","",'質問設定'!C12)
A5: =IF('質問設定'!C13="","",'質問設定'!C13)
A6: =IF('質問設定'!C14="","",'質問設定'!C14)
A7: =IF('質問設定'!C15="","",'質問設定'!C15)
A8: =IF('質問設定'!C16="","",'質問設定'!C16)
A9: =IF('質問設定'!C17="","",'質問設定'!C17)
A10: =IF('質問設定'!C18="","",'質問設定'!C18)
A11: =IF('質問設定'!C19="","",'質問設定'!C19)
A12: =IF('質問設定'!C20="","",'質問設定'!C20)
A13: =IF('質問設定'!C21="","",'質問設定'!C21)

Sheet 34
A1: 出席番号 34 の回答シート
A2: B列に 1〜4 の数字を入れてください（4=とてもそう思う … 1=そう思わない）。設問文は「質問設定」シートと連動しています。
A3: 設問 | B3: 回答(1-4)
A4: =IF('質問設定'!C12="","",'質問設定'!C12)
A5: =IF('質問設定'!C13="","",'質問設定'!C13)
A6: =IF('質問設定'!C14="","",'質問設定'!C14)
A7: =IF('質問設定'!C15="","",'質問設定'!C15)
A8: =IF('質問設定'!C16="","",'質問設定'!C16)
A9: =IF('質問設定'!C17="","",'質問設定'!C17)
A10: =IF('質問設定'!C18="","",'質問設定'!C18)
A11: =IF('質問設定'!C19="","",'質問設定'!C19)
A12: =IF('質問設定'!C20="","",'質問設定'!C20)
A13: =IF('質問設定'!C21="","",'質問設定'!C21)

Sheet 35
A1: 出席番号 35 の回答シート
A2: B列に 1〜4 の数字を入れてください（4=とてもそう思う … 1=そう思わない）。設問文は「質問設定」シートと連動しています。
A3: 設問 | B3: 回答(1-4)
A4: =IF('質問設定'!C12="","",'質問設定'!C12)
A5: =IF('質問設定'!C13="","",'質問設定'!C13)
A6: =IF('質問設定'!C14="","",'質問設定'!C14)
A7: =IF('質問設定'!C15="","",'質問設定'!C15)
A8: =IF('質問設定'!C16="","",'質問設定'!C16)
A9: =IF('質問設定'!C17="","",'質問設定'!C17)
A10: =IF('質問設定'!C18="","",'質問設定'!C18)
A11: =IF('質問設定'!C19="","",'質問設定'!C19)
A12: =IF('質問設定'!C20="","",'質問設定'!C20)
A13: =IF('質問設定'!C21="","",'質問設定'!C21)

Sheet 36
A1: 出席番号 36 の回答シート
A2: B列に 1〜4 の数字を入れてください（4=とてもそう思う … 1=そう思わない）。設問文は「質問設定」シートと連動しています。
A3: 設問 | B3: 回答(1-4)
A4: =IF('質問設定'!C12="","",'質問設定'!C12)
