Workbook

Sheet Sheet1
A1: ID | B1: 開始時刻 | C1: 完了時刻 | D1: メール | E1: 名前 | F1: ①目標：みんなで決めた目標やめあてに力を合わせてとりくんでいる学級です。 | G1: ②改善：自分たちの学習や生活をよくするための話し合いや活動をしている学級です。 | H1: ③役割：係や当番の活動に責任を持ってとりくむ学級です。 | I1: ④聞く姿勢：発言している人の話を最後までしっかりと聞いている学級です。 | J1: ⑤つながり：友だちの話に賛成・反対・つけたしと、つなげられるように発言している学級です。 | K1: ⑥積極性：話し合いの時、考えや意見を進んで出し合う学級です。 | L1: ⑦支え合い：勉強・運動・そうじ・給食などで、教え合いや助け合いをしている学級です。 | M1: ⑧仲直り：すなおに「ごめんね」と言って、仲直りができる学級です。 | N1: ⑨感謝：「ありがとう」を伝え合っている学級です。 | O1: ⑩認め合い：友だちのよいところやがんばっているところを伝え合っている学級です。 | P1: ⑪尊重：友だちの心を傷つけることを言ったり、からかったりしない学級です。 | Q1: ⑫仲間：だれとでも遊んだり、グループになったりすることができる学級です。 | R1: ⑬学習：授業中にむだなおしゃべりをしない学級です。 | S1: ⑭生活：ろうかを走らない、あいさつをするなど、学校のきまりを守っている学級です。 | T1: ⑮校外：校外ではひとのめいわくにならないように考えて行動できる学級です。
A2: 01 | F2: あまりそう思わない | G2: あまりそう思わない | H2: そう思う | I2: そう思う | J2: そう思う | K2: あまりそう思わない | L2: そう思う | M2: あまりそう思わない | N2: あまりそう思わない | O2: そう思う | P2: そう思う | Q2: そう思う | R2: そう思う | S2: そう思う | T2: あまりそう思わない
A3: 02 | F3: あまりそう思わない | G3: そう思う | H3: とてもそう思う | I3: そう思う | J3: そう思う | K3: そう思う | L3: あまりそう思わない | M3: あまりそう思わない | N3: そう思う | O3: そう思う | P3: あまりそう思わない | Q3: そう思う | R3: そう思う | S3: そう思う | T3: あまりそう思わない
A4: 03 | F4: そう思う | G4: あまりそう思わない | H4: そう思わない | I4: あまりそう思わない | J4: あまりそう思わない | K4: そう思う | L4: そう思う | M4: あまりそう思わない | N4: そう思う | O4: あまりそう思わない | P4: そう思う | Q4: あまりそう思わない | R4: そう思う | S4: そう思う | T4: そう思う
A5: 04 | F5: そう思う | G5: そう思う | H5: そう思う | I5: とてもそう思う | J5: そう思う | K5: そう思う | L5: そう思う | M5: そう思う | N5: とてもそう思う | O5: そう思う | P5: そう思う | Q5: そう思う | R5: あまりそう思わない | S5: そう思う | T5: そう思う
A6: 05 | F6: とてもそう思う | G6: そう思う | H6: そう思う | I6: そう思う | J6: とてもそう思う | K6: そう思う | L6: とてもそう思う | M6: そう思う | N6: そう思う | O6: とてもそう思う | P6: そう思う | Q6: とてもそう思う | R6: そう思う | S6: そう思う | T6: そう思う
A7: 06 | F7: =IF('06'!B4="","",IFERROR(CHOOSE('06'!B4,"そう思わない","あまりそう思わない","そう思う","とてもそう思う"),"")) | G7: =IF('06'!B5="","",IFERROR(CHOOSE('06'!B5,"そう思わない","あまりそう思わない","そう思う","とてもそう思う"),"")) | H7: =IF('06'!B6="","",IFERROR(CHOOSE('06'!B6,"そう思わない","あまりそう思わない","そう思う","とてもそう思う"),"")) | I7: =IF('06'!B7="","",IFERROR(CHOOSE('06'!B7,"そう思わない","あまりそう思わない","そう思う","とてもそう思う"),"")) | J7: =IF('06'!B8="","",IFERROR(CHOOSE('06'!B8,"そう思わない","あまりそう思わない","そう思う","とてもそう思う"),"")) | K7: =IF('06'!B9="","",IFERROR(CHOOSE('06'!B9,"そう思わない","あまりそう思わない","そう思う","とてもそう思う"),"")) | L7: =IF('06'!B10="","",IFERROR(CHOOSE('06'!B10,"そう思わない","あまりそう思わない","そう思う","とてもそう思う"),"")) | M7: =IF('06'!B11="","",IFERROR(CHOOSE('06'!B11,"そう思わない","あまりそう思わない","そう思う","とてもそう思う"),"")) | N7: =IF('06'!B12="","",IFERROR(CHOOSE('06'!B12,"そう思わない","あまりそう思わない","そう思う","とてもそう思う"),"")) | O7: =IF('06'!B13="","",IFERROR(CHOOSE('06'!B13,"そう思わない","あまりそう思わない","そう思う","とてもそう思う"),"")) | P7: =IF('06'!B14="","",IFERROR(CHOOSE('06'!B14,"そう思わない","あまりそう思わない","そう思う","とてもそう思う"),"")) | Q7: =IF('06'!B15="","",IFERROR(CHOOSE('06'!B15,"そう思わない","あまりそう思わない","そう思う","とてもそう思う"),"")) | R7: =IF('06'!B16="","",IFERROR(CHOOSE('06'!B16,"そう思わない","あまりそう思わない","そう思う","とてもそう思う"),"")) | S7: =IF('06'!B17="","",IFERROR(CHOOSE('06'!B17,"そう思わない","あまりそう思わない","そう思う","とてもそう思う"),"")) | T7: =IF('06'!B18="","",IFERROR(CHOOSE('06'!B18,"そう思わない","あまりそう思わない","そう思う","とてもそう思う"),""))
A8: 07 | F8: =IF('07'!B4="","",IFERROR(CHOOSE('07'!B4,"そう思わない","あまりそう思わない","そう思う","とてもそう思う"),"")) | G8: =IF('07'!B5="","",IFERROR(CHOOSE('07'!B5,"そう思わない","あまりそう思わない","そう思う","とてもそう思う"),"")) | H8: =IF('07'!B6="","",IFERROR(CHOOSE('07'!B6,"そう思わない","あまりそう思わない","そう思う","とてもそう思う"),"")) | I8: =IF('07'!B7="","",IFERROR(CHOOSE('07'!B7,"そう思わない","あまりそう思わない","そう思う","とてもそう思う"),"")) | J8: =IF('07'!B8="","",IFERROR(CHOOSE('07'!B8,"そう思わない","あまりそう思わない","そう思う","とてもそう思う"),"")) | K8: =IF('07'!B9="","",IFERROR(CHOOSE('07'!B9,"そう思わない","あまりそう思わない","そう思う","とてもそう思う"),"")) | L8: =IF('07'!B10="","",IFERROR(CHOOSE('07'!B10,"そう思わない","あまりそう思わない","そう思う","とてもそう思う"),"")) | M8: =IF('07'!B11="","",IFERROR(CHOOSE('07'!B11,"そう思わない","あまりそう思わない","そう思う","とてもそう思う"),"")) | N8: =IF('07'!B12="","",IFERROR(CHOOSE('07'!B12,"そう思わない","あまりそう思わない","そう思う","とてもそう思う"),"")) | O8: =IF('07'!B13="","",IFERROR(CHOOSE('07'!B13,"そう思わない","あまりそう思わない","そう思う","とてもそう思う"),"")) | P8: =IF('07'!B14="","",IFERROR(CHOOSE('07'!B14,"そう思わない","あまりそう思わない","そう思う","とてもそう思う"),"")) | Q8: =IF('07'!B15="","",IFERROR(CHOOSE('07'!B15,"そう思わない","あまりそう思わない","そう思う","とてもそう思う"),"")) | R8: =IF('07'!B16="","",IFERROR(CHOOSE('07'!B16,"そう思わない","あまりそう思わない","そう思う","とてもそう思う"),"")) | S8: =IF('07'!B17="","",IFERROR(CHOOSE('07'!B17,"そう思わない","あまりそう思わない","そう思う","とてもそう思う"),"")) | T8: =IF('07'!B18="","",IFERROR(CHOOSE('07'!B18,"そう思わない","あまりそう思わない","そう思う","とてもそう思う"),""))
A9: 08 | F9: =IF('08'!B4="","",IFERROR(CHOOSE('08'!B4,"そう思わない","あまりそう思わない","そう思う","とてもそう思う"),"")) | G9: =IF('08'!B5="","",IFERROR(CHOOSE('08'!B5,"そう思わない","あまりそう思わない","そう思う","とてもそう思う"),"")) | H9: =IF('08'!B6="","",IFERROR(CHOOSE('08'!B6,"そう思わない","あまりそう思わない","そう思う","とてもそう思う"),"")) | I9: =IF('08'!B7="","",IFERROR(CHOOSE('08'!B7,"そう思わない","あまりそう思わない","そう思う","とてもそう思う"),"")) | J9: =IF('08'!B8="","",IFERROR(CHOOSE('08'!B8,"そう思わない","あまりそう思わない","そう思う","とてもそう思う"),"")) | K9: =IF('08'!B9="","",IFERROR(CHOOSE('08'!B9,"そう思わない","あまりそう思わない","そう思う","とてもそう思う"),"")) | L9: =IF('08'!B10="","",IFERROR(CHOOSE('08'!B10,"そう思わない","あまりそう思わない","そう思う","とてもそう思う"),"")) | M9: =IF('08'!B11="","",IFERROR(CHOOSE('08'!B11,"そう思わない","あまりそう思わない","そう思う","とてもそう思う"),"")) | N9: =IF('08'!B12="","",IFERROR(CHOOSE('08'!B12,"そう思わない","あまりそう思わない","そう思う","とてもそう思う"),"")) | O9: =IF('08'!B13="","",IFERROR(CHOOSE('08'!B13,"そう思わない","あまりそう思わない","そう思う","とてもそう思う"),"")) | P9: =IF('08'!B14="","",IFERROR(CHOOSE('08'!B14,"そう思わない","あまりそう思わない","そう思う","とてもそう思う"),"")) | Q9: =IF('08'!B15="","",IFERROR(CHOOSE('08'!B15,"そう思わない","あまりそう思わない","そう思う","とてもそう思う"),"")) | R9: =IF('08'!B16="","",IFERROR(CHOOSE('08'!B16,"そう思わない","あまりそう思わない","そう思う","とてもそう思う"),"")) | S9: =IF('08'!B17="","",IFERROR(CHOOSE('08'!B17,"そう思わない","あまりそう思わない","そう思う","とてもそう思う"),"")) | T9: =IF('08'!B18="","",IFERROR(CHOOSE('08'!B18,"そう思わない","あまりそう思わない","そう思う","とてもそう思う"),""))
A10: 09 | F10: =IF('09'!B4="","",IFERROR(CHOOSE('09'!B4,"そう思わない","あまりそう思わない","そう思う","とてもそう思う"),"")) | G10: =IF('09'!B5="","",IFERROR(CHOOSE('09'!B5,"そう思わない","あまりそう思わない","そう思う","とてもそう思う"),"")) | H10: =IF('09'!B6="","",IFERROR(CHOOSE('09'!B6,"そう思わない","あまりそう思わない","そう思う","とてもそう思う"),"")) | I10: =IF('09'!B7="","",IFERROR(CHOOSE('09'!B7,"そう思わない","あまりそう思わない","そう思う","とてもそう思う"),"")) | J10: =IF('09'!B8="","",IFERROR(CHOOSE('09'!B8,"そう思わない","あまりそう思わない","そう思う","とてもそう思う"),"")) | K10: =IF('09'!B9="","",IFERROR(CHOOSE('09'!B9,"そう思わない","あまりそう思わない","そう思う","とてもそう思う"),"")) | L10: =IF('09'!B10="","",IFERROR(CHOOSE('09'!B10,"そう思わない","あまりそう思わない","そう思う","とてもそう思う"),"")) | M10: =IF('09'!B11="","",IFERROR(CHOOSE('09'!B11,"そう思わない","あまりそう思わない","そう思う","とてもそう思う"),"")) | N10: =IF('09'!B12="","",IFERROR(CHOOSE('09'!B12,"そう思わない","あまりそう思わない","そう思う","とてもそう思う"),"")) | O10: =IF('09'!B13="","",IFERROR(CHOOSE('09'!B13,"そう思わない","あまりそう思わない","そう思う","とてもそう思う"),"")) | P10: =IF('09'!B14="","",IFERROR(CHOOSE('09'!B14,"そう思わない","あまりそう思わない","そう思う","とてもそう思う"),"")) | Q10: =IF('09'!B15="","",IFERROR(CHOOSE('09'!B15,"そう思わない","あまりそう思わない","そう思う","とてもそう思う"),"")) | R10: =IF('09'!B16="","",IFERROR(CHOOSE('09'!B16,"そう思わない","あまりそう思わない","そう思う","とてもそう思う"),"")) | S10: =IF('09'!B17="","",IFERROR(CHOOSE('09'!B17,"そう思わない","あまりそう思わない","そう思う","とてもそう思う"),"")) | T10: =IF('09'!B18="","",IFERROR(CHOOSE('09'!B18,"そう思わない","あまりそう思わない","そう思う","とてもそう思う"),""))
A11: 10 | F11: =IF('10'!B4="","",IFERROR(CHOOSE('10'!B4,"そう思わない","あまりそう思わない","そう思う","とてもそう思う"),"")) | G11: =IF('10'!B5="","",IFERROR(CHOOSE('10'!B5,"そう思わない","あまりそう思わない","そう思う","とてもそう思う"),"")) | H11: =IF('10'!B6="","",IFERROR(CHOOSE('10'!B6,"そう思わない","あまりそう思わない","そう思う","とてもそう思う"),"")) | I11: =IF('10'!B7="","",IFERROR(CHOOSE('10'!B7,"そう思わない","あまりそう思わない","そう思う","とてもそう思う"),"")) | J11: =IF('10'!B8="","",IFERROR(CHOOSE('10'!B8,"そう思わない","あまりそう思わない","そう思う","とてもそう思う"),"")) | K11: =IF('10'!B9="","",IFERROR(CHOOSE('10'!B9,"そう思わない","あまりそう思わない","そう思う","とてもそう思う"),"")) | L11: =IF('10'!B10="","",IFERROR(CHOOSE('10'!B10,"そう思わない","あまりそう思わない","そう思う","とてもそう思う"),"")) | M11: =IF('10'!B11="","",IFERROR(CHOOSE('10'!B11,"そう思わない","あまりそう思わない","そう思う","とてもそう思う"),"")) | N11: =IF('10'!B12="","",IFERROR(CHOOSE('10'!B12,"そう思わない","あまりそう思わない","そう思う","とてもそう思う"),"")) | O11: =IF('10'!B13="","",IFERROR(CHOOSE('10'!B13,"そう思わない","あまりそう思わない","そう思う","とてもそう思う"),"")) | P11: =IF('10'!B14="","",IFERROR(CHOOSE('10'!B14,"そう思わない","あまりそう思わない","そう思う","とてもそう思う"),"")) | Q11: =IF('10'!B15="","",IFERROR(CHOOSE('10'!B15,"そう思わない","あまりそう思わない","そう思う","とてもそう思う"),"")) | R11: =IF('10'!B16="","",IFERROR(CHOOSE('10'!B16,"そう思わない","あまりそう思わない","そう思う","とてもそう思う"),"")) | S11: =IF('10'!B17="","",IFERROR(CHOOSE('10'!B17,"そう思わない","あまりそう思わない","そう思う","とてもそう思う"),"")) | T11: =IF('10'!B18="","",IFERROR(CHOOSE('10'!B18,"そう思わない","あまりそう思わない","そう思う","とてもそう思う"),""))
A12: 11 | F12: =IF('11'!B4="","",IFERROR(CHOOSE('11'!B4,"そう思わない","あまりそう思わない","そう思う","とてもそう思う"),"")) | G12: =IF('11'!B5="","",IFERROR(CHOOSE('11'!B5,"そう思わない","あまりそう思わない","そう思う","とてもそう思う"),"")) | H12: =IF('11'!B6="","",IFERROR(CHOOSE('11'!B6,"そう思わない","あまりそう思わない","そう思う","とてもそう思う"),"")) | I12: =IF('11'!B7="","",IFERROR(CHOOSE('11'!B7,"そう思わない","あまりそう思わない","そう思う","とてもそう思う"),"")) | J12: =IF('11'!B8="","",IFERROR(CHOOSE('11'!B8,"そう思わない","あまりそう思わない","そう思う","とてもそう思う"),"")) | K12: =IF('11'!B9="","",IFERROR(CHOOSE('11'!B9,"そう思わない","あまりそう思わない","そう思う","とてもそう思う"),"")) | L12: =IF('11'!B10="","",IFERROR(CHOOSE('11'!B10,"そう思わない","あまりそう思わない","そう思う","とてもそう思う"),"")) | M12: =IF('11'!B11="","",IFERROR(CHOOSE('11'!B11,"そう思わない","あまりそう思わない","そう思う","とてもそう思う"),"")) | N12: =IF('11'!B12="","",IFERROR(CHOOSE('11'!B12,"そう思わない","あまりそう思わない","そう思う","とてもそう思う"),"")) | O12: =IF('11'!B13="","",IFERROR(CHOOSE('11'!B13,"そう思わない","あまりそう思わない","そう思う","とてもそう思う"),"")) | P12: =IF('11'!B14="","",IFERROR(CHOOSE('11'!B14,"そう思わない","あまりそう思わない","そう思う","とてもそう思う"),"")) | Q12: =IF('11'!B15="","",IFERROR(CHOOSE('11'!B15,"そう思わない","あまりそう思わない","そう思う","とてもそう思う"),"")) | R12: =IF('11'!B16="","",IFERROR(CHOOSE('11'!B16,"そう思わない","あまりそう思わない","そう思う","とてもそう思う"),"")) | S12: =IF('11'!B17="","",IFERROR(CHOOSE('11'!B17,"そう思わない","あまりそう思わない","そう思う","とてもそう思う"),"")) | T12: =IF('11'!B18="","",IFERROR(CHOOSE('11'!B18,"そう思わない","あまりそう思わない","そう思う","とてもそう思う"),""))
A13: 12 | F13: =IF('12'!B4="","",IFERROR(CHOOSE('12'!B4,"そう思わない","あまりそう思わない","そう思う","とてもそう思う"),"")) | G13: =IF('12'!B5="","",IFERROR(CHOOSE('12'!B5,"そう思わない","あまりそう思わない","そう思う","とてもそう思う"),"")) | H13: =IF('12'!B6="","",IFERROR(CHOOSE('12'!B6,"そう思わない","あまりそう思わない","そう思う","とてもそう思う"),"")) | I13: =IF('12'!B7="","",IFERROR(CHOOSE('12'!B7,"そう思わない","あまりそう思わない","そう思う","とてもそう思う"),"")) | J13: =IF('12'!B8="","",IFERROR(CHOOSE('12'!B8,"そう思わない","あまりそう思わない","そう思う","とてもそう思う"),"")) | K13: =IF('12'!B9="","",IFERROR(CHOOSE('12'!B9,"そう思わない","あまりそう思わない","そう思う","とてもそう思う"),"")) | L13: =IF('12'!B10="","",IFERROR(CHOOSE('12'!B10,"そう思わない","あまりそう思わない","そう思う","とてもそう思う"),"")) | M13: =IF('12'!B11="","",IFERROR(CHOOSE('12'!B11,"そう思わない","あまりそう思わない","そう思う","とてもそう思う"),"")) | N13: =IF('12'!B12="","",IFERROR(CHOOSE('12'!B12,"そう思わない","あまりそう思わない","そう思う","とてもそう思う"),"")) | O13: =IF('12'!B13="","",IFERROR(CHOOSE('12'!B13,"そう思わない","あまりそう思わない","そう思う","とてもそう思う"),"")) | P13: =IF('12'!B14="","",IFERROR(CHOOSE('12'!B14,"そう思わない","あまりそう思わない","そう思う","とてもそう思う"),"")) | Q13: =IF('12'!B15="","",IFERROR(CHOOSE('12'!B15,"そう思わない","あまりそう思わない","そう思う","とてもそう思う"),"")) | R13: =IF('12'!B16="","",IFERROR(CHOOSE('12'!B16,"そう思わない","あまりそう思わない","そう思う","とてもそう思う"),"")) | S13: =IF('12'!B17="","",IFERROR(CHOOSE('12'!B17,"そう思わない","あまりそう思わない","そう思う","とてもそう思う"),"")) | T13: =IF('12'!B18="","",IFERROR(CHOOSE('12'!B18,"そう思わない","あまりそう思わない","そう思う","とてもそう思う"),""))
A14: 13 | F14: =IF('13'!B4="","",IFERROR(CHOOSE('13'!B4,"そう思わない","あまりそう思わない","そう思う","とてもそう思う"),"")) | G14: =IF('13'!B5="","",IFERROR(CHOOSE('13'!B5,"そう思わない","あまりそう思わない","そう思う","とてもそう思う"),"")) | H14: =IF('13'!B6="","",IFERROR(CHOOSE('13'!B6,"そう思わない","あまりそう思わない","そう思う","とてもそう思う"),"")) | I14: =IF('13'!B7="","",IFERROR(CHOOSE('13'!B7,"そう思わない","あまりそう思わない","そう思う","とてもそう思う"),"")) | J14: =IF('13'!B8="","",IFERROR(CHOOSE('13'!B8,"そう思わない","あまりそう思わない","そう思う","とてもそう思う"),"")) | K14: =IF('13'!B9="","",IFERROR(CHOOSE('13'!B9,"そう思わない","あまりそう思わない","そう思う","とてもそう思う"),"")) | L14: =IF('13'!B10="","",IFERROR(CHOOSE('13'!B10,"そう思わない","あまりそう思わない","そう思う","とてもそう思う"),"")) | M14: =IF('13'!B11="","",IFERROR(CHOOSE('13'!B11,"そう思わない","あまりそう思わない","そう思う","とてもそう思う"),"")) | N14: =IF('13'!B12="","",IFERROR(CHOOSE('13'!B12,"そう思わない","あまりそう思わない","そう思う","とてもそう思う"),"")) | O14: =IF('13'!B13="","",IFERROR(CHOOSE('13'!B13,"そう思わない","あまりそう思わない","そう思う","とてもそう思う"),"")) | P14: =IF('13'!B14="","",IFERROR(CHOOSE('13'!B14,"そう思わない","あまりそう思わない","そう思う","とてもそう思う"),"")) | Q14: =IF('13'!B15="","",IFERROR(CHOOSE('13'!B15,"そう思わない","あまりそう思わない","そう思う","とてもそう思う"),"")) | R14: =IF('13'!B16="","",IFERROR(CHOOSE('13'!B16,"そう思わない","あまりそう思わない","そう思う","とてもそう思う"),"")) | S14: =IF('13'!B17="","",IFERROR(CHOOSE('13'!B17,"そう思わない","あまりそう思わない","そう思う","とてもそう思う"),"")) | T14: =IF('13'!B18="","",IFERROR(CHOOSE('13'!B18,"そう思わない","あまりそう思わない","そう思う","とてもそう思う"),""))
A15: 14 | F15: =IF('14'!B4="","",IFERROR(CHOOSE('14'!B4,"そう思わない","あまりそう思わない","そう思う","とてもそう思う"),"")) | G15: =IF('14'!B5="","",IFERROR(CHOOSE('14'!B5,"そう思わない","あまりそう思わない","そう思う","とてもそう思う"),"")) | H15: =IF('14'!B6="","",IFERROR(CHOOSE('14'!B6,"そう思わない","あまりそう思わない","そう思う","とてもそう思う"),"")) | I15: =IF('14'!B7="","",IFERROR(CHOOSE('14'!B7,"そう思わない","あまりそう思わない","そう思う","とてもそう思う"),"")) | J15: =IF('14'!B8="","",IFERROR(CHOOSE('14'!B8,"そう思わない","あまりそう思わない","そう思う","とてもそう思う"),"")) | K15: =IF('14'!B9="","",IFERROR(CHOOSE('14'!B9,"そう思わない","あまりそう思わない","そう思う","とてもそう思う"),"")) | L15: =IF('14'!B10="","",IFERROR(CHOOSE('14'!B10,"そう思わない","あまりそう思わない","そう思う","とてもそう思う"),"")) | M15: =IF('14'!B11="","",IFERROR(CHOOSE('14'!B11,"そう思わない","あまりそう思わない","そう思う","とてもそう思う"),"")) | N15: =IF('14'!B12="","",IFERROR(CHOOSE('14'!B12,"そう思わない","あまりそう思わない","そう思う","とてもそう思う"),"")) | O15: =IF('14'!B13="","",IFERROR(CHOOSE('14'!B13,"そう思わない","あまりそう思わない","そう思う","とてもそう思う"),"")) | P15: =IF('14'!B14="","",IFERROR(CHOOSE('14'!B14,"そう思わない","あまりそう思わない","そう思う","とてもそう思う"),"")) | Q15: =IF('14'!B15="","",IFERROR(CHOOSE('14'!B15,"そう思わない","あまりそう思わない","そう思う","とてもそう思う"),"")) | R15: =IF('14'!B16="","",IFERROR(CHOOSE('14'!B16,"そう思わない","あまりそう思わない","そう思う","とてもそう思う"),"")) | S15: =IF('14'!B17="","",IFERROR(CHOOSE('14'!B17,"そう思わない","あまりそう思わない","そう思う","とてもそう思う"),"")) | T15: =IF('14'!B18="","",IFERROR(CHOOSE('14'!B18,"そう思わない","あまりそう思わない","そう思う","とてもそう思う"),""))
A16: 15 | F16: =IF('15'!B4="","",IFERROR(CHOOSE('15'!B4,"そう思わない","あまりそう思わない","そう思う","とてもそう思う"),"")) | G16: =IF('15'!B5="","",IFERROR(CHOOSE('15'!B5,"そう思わない","あまりそう思わない","そう思う","とてもそう思う"),"")) | H16: =IF('15'!B6="","",IFERROR(CHOOSE('15'!B6,"そう思わない","あまりそう思わない","そう思う","とてもそう思う"),"")) | I16: =IF('15'!B7="","",IFERROR(CHOOSE('15'!B7,"そう思わない","あまりそう思わない","そう思う","とてもそう思う"),"")) | J16: =IF('15'!B8="","",IFERROR(CHOOSE('15'!B8,"そう思わない","あまりそう思わない","そう思う","とてもそう思う"),"")) | K16: =IF('15'!B9="","",IFERROR(CHOOSE('15'!B9,"そう思わない","あまりそう思わない","そう思う","とてもそう思う"),"")) | L16: =IF('15'!B10="","",IFERROR(CHOOSE('15'!B10,"そう思わない","あまりそう思わない","そう思う","とてもそう思う"),"")) | M16: =IF('15'!B11="","",IFERROR(CHOOSE('15'!B11,"そう思わない","あまりそう思わない","そう思う","とてもそう思う"),"")) | N16: =IF('15'!B12="","",IFERROR(CHOOSE('15'!B12,"そう思わない","あまりそう思わない","そう思う","とてもそう思う"),"")) | O16: =IF('15'!B13="","",IFERROR(CHOOSE('15'!B13,"そう思わない","あまりそう思わない","そう思う","とてもそう思う"),"")) | P16: =IF('15'!B14="","",IFERROR(CHOOSE('15'!B14,"そう思わない","あまりそう思わない","そう思う","とてもそう思う"),"")) | Q16: =IF('15'!B15="","",IFERROR(CHOOSE('15'!B15,"そう思わない","あまりそう思わない","そう思う","とてもそう思う"),"")) | R16: =IF('15'!B16="","",IFERROR(CHOOSE('15'!B16,"そう思わない","あまりそう思わない","そう思う","とてもそう思う"),"")) | S16: =IF('15'!B17="","",IFERROR(CHOOSE('15'!B17,"そう思わない","あまりそう思わない","そう思う","とてもそう思う"),"")) | T16: =IF('15'!B18="","",IFERROR(CHOOSE('15'!B18,"そう思わない","あまりそう思わない","そう思う","とてもそう思う"),""))
A17: 16 | F17: =IF('16'!B4="","",IFERROR(CHOOSE('16'!B4,"そう思わない","あまりそう思わない","そう思う","とてもそう思う"),"")) | G17: =IF('16'!B5="","",IFERROR(CHOOSE('16'!B5,"そう思わない","あまりそう思わない","そう思う","とてもそう思う"),"")) | H17: =IF('16'!B6="","",IFERROR(CHOOSE('16'!B6,"そう思わない","あまりそう思わない","そう思う","とてもそう思う"),"")) | I17: =IF('16'!B7="","",IFERROR(CHOOSE('16'!B7,"そう思わない","あまりそう思わない","そう思う","とてもそう思う"),"")) | J17: =IF('16'!B8="","",IFERROR(CHOOSE('16'!B8,"そう思わない","あまりそう思わない","そう思う","とてもそう思う"),"")) | K17: =IF('16'!B9="","",IFERROR(CHOOSE('16'!B9,"そう思わない","あまりそう思わない","そう思う","とてもそう思う"),"")) | L17: =IF('16'!B10="","",IFERROR(CHOOSE('16'!B10,"そう思わない","あまりそう思わない","そう思う","とてもそう思う"),"")) | M17: =IF('16'!B11="","",IFERROR(CHOOSE('16'!B11,"そう思わない","あまりそう思わない","そう思う","とてもそう思う"),"")) | N17: =IF('16'!B12="","",IFERROR(CHOOSE('16'!B12,"そう思わない","あまりそう思わない","そう思う","とてもそう思う"),"")) | O17: =IF('16'!B13="","",IFERROR(CHOOSE('16'!B13,"そう思わない","あまりそう思わない","そう思う","とてもそう思う"),"")) | P17: =IF('16'!B14="","",IFERROR(CHOOSE('16'!B14,"そう思わない","あまりそう思わない","そう思う","とてもそう思う"),"")) | Q17: =IF('16'!B15="","",IFERROR(CHOOSE('16'!B15,"そう思わない","あまりそう思わない","そう思う","とてもそう思う"),"")) | R17: =IF('16'!B16="","",IFERROR(CHOOSE('16'!B16,"そう思わない","あまりそう思わない","そう思う","とてもそう思う"),"")) | S17: =IF('16'!B17="","",IFERROR(CHOOSE('16'!B17,"そう思わない","あまりそう思わない","そう思う","とてもそう思う"),"")) | T17: =IF('16'!B18="","",IFERROR(CHOOSE('16'!B18,"そう思わない","あまりそう思わない","そう思う","とてもそう思う"),""))
A18: 17 | F18: =IF('17'!B4="","",IFERROR(CHOOSE('17'!B4,"そう思わない","あまりそう思わない","そう思う","とてもそう思う"),"")) | G18: =IF('17'!B5="","",IFERROR(CHOOSE('17'!B5,"そう思わない","あまりそう思わない","そう思う","とてもそう思う"),"")) | H18: =IF('17'!B6="","",IFERROR(CHOOSE('17'!B6,"そう思わない","あまりそう思わない","そう思う","とてもそう思う"),"")) | I18: =IF('17'!B7="","",IFERROR(CHOOSE('17'!B7,"そう思わない","あまりそう思わない","そう思う","とてもそう思う"),"")) | J18: =IF('17'!B8="","",IFERROR(CHOOSE('17'!B8,"そう思わない","あまりそう思わない","そう思う","とてもそう思う"),"")) | K18: =IF('17'!B9="","",IFERROR(CHOOSE('17'!B9,"そう思わない","あまりそう思わない","そう思う","とてもそう思う"),"")) | L18: =IF('17'!B10="","",IFERROR(CHOOSE('17'!B10,"そう思わない","あまりそう思わない","そう思う","とてもそう思う"),"")) | M18: =IF('17'!B11="","",IFERROR(CHOOSE('17'!B11,"そう思わない","あまりそう思わない","そう思う","とてもそう思う"),"")) | N18: =IF('17'!B12="","",IFERROR(CHOOSE('17'!B12,"そう思わない","あまりそう思わない","そう思う","とてもそう思う"),"")) | O18: =IF('17'!B13="","",IFERROR(CHOOSE('17'!B13,"そう思わない","あまりそう思わない","そう思う","とてもそう思う"),"")) | P18: =IF('17'!B14="","",IFERROR(CHOOSE('17'!B14,"そう思わない","あまりそう思わない","そう思う","とてもそう思う"),"")) | Q18: =IF('17'!B15="","",IFERROR(CHOOSE('17'!B15,"そう思わない","あまりそう思わない","そう思う","とてもそう思う"),"")) | R18: =IF('17'!B16="","",IFERROR(CHOOSE('17'!B16,"そう思わない","あまりそう思わない","そう思う","とてもそう思う"),"")) | S18: =IF('17'!B17="","",IFERROR(CHOOSE('17'!B17,"そう思わない","あまりそう思わない","そう思う","とてもそう思う"),"")) | T18: =IF('17'!B18="","",IFERROR(CHOOSE('17'!B18,"そう思わない","あまりそう思わない","そう思う","とてもそう思う"),""))
A19: 18 | F19: =IF('18'!B4="","",IFERROR(CHOOSE('18'!B4,"そう思わない","あまりそう思わない","そう思う","とてもそう思う"),"")) | G19: =IF('18'!B5="","",IFERROR(CHOOSE('18'!B5,"そう思わない","あまりそう思わない","そう思う","とてもそう思う"),"")) | H19: =IF('18'!B6="","",IFERROR(CHOOSE('18'!B6,"そう思わない","あまりそう思わない","そう思う","とてもそう思う"),"")) | I19: =IF('18'!B7="","",IFERROR(CHOOSE('18'!B7,"そう思わない","あまりそう思わない","そう思う","とてもそう思う"),"")) | J19: =IF('18'!B8="","",IFERROR(CHOOSE('18'!B8,"そう思わない","あまりそう思わない","そう思う","とてもそう思う"),"")) | K19: =IF('18'!B9="","",IFERROR(CHOOSE('18'!B9,"そう思わない","あまりそう思わない","そう思う","とてもそう思う"),"")) | L19: =IF('18'!B10="","",IFERROR(CHOOSE('18'!B10,"そう思わない","あまりそう思わない","そう思う","とてもそう思う"),"")) | M19: =IF('18'!B11="","",IFERROR(CHOOSE('18'!B11,"そう思わない","あまりそう思わない","そう思う","とてもそう思う"),"")) | N19: =IF('18'!B12="","",IFERROR(CHOOSE('18'!B12,"そう思わない","あまりそう思わない","そう思う","とてもそう思う"),"")) | O19: =IF('18'!B13="","",IFERROR(CHOOSE('18'!B13,"そう思わない","あまりそう思わない","そう思う","とてもそう思う"),"")) | P19: =IF('18'!B14="","",IFERROR(CHOOSE('18'!B14,"そう思わない","あまりそう思わない","そう思う","とてもそう思う"),"")) | Q19: =IF('18'!B15="","",IFERROR(CHOOSE('18'!B15,"そう思わない","あまりそう思わない","そう思う","とてもそう思う"),"")) | R19: =IF('18'!B16="","",IFERROR(CHOOSE('18'!B16,"そう思わない","あまりそう思わない","そう思う","とてもそう思う"),"")) | S19: =IF('18'!B17="","",IFERROR(CHOOSE('18'!B17,"そう思わない","あまりそう思わない","そう思う","とてもそう思う"),"")) | T19: =IF('18'!B18="","",IFERROR(CHOOSE('18'!B18,"そう思わない","あまりそう思わない","そう思う","とてもそう思う"),""))
A20: 19 | F20: =IF('19'!B4="","",IFERROR(CHOOSE('19'!B4,"そう思わない","あまりそう思わない","そう思う","とてもそう思う"),"")) | G20: =IF('19'!B5="","",IFERROR(CHOOSE('19'!B5,"そう思わない","あまりそう思わない","そう思う","とてもそう思う"),"")) | H20: =IF('19'!B6="","",IFERROR(CHOOSE('19'!B6,"そう思わない","あまりそう思わない","そう思う","とてもそう思う"),"")) | I20: =IF('19'!B7="","",IFERROR(CHOOSE('19'!B7,"そう思わない","あまりそう思わない","そう思う","とてもそう思う"),"")) | J20: =IF('19'!B8="","",IFERROR(CHOOSE('19'!B8,"そう思わない","あまりそう思わない","そう思う","とてもそう思う"),"")) | K20: =IF('19'!B9="","",IFERROR(CHOOSE('19'!B9,"そう思わない","あまりそう思わない","そう思う","とてもそう思う"),"")) | L20: =IF('19'!B10="","",IFERROR(CHOOSE('19'!B10,"そう思わない","あまりそう思わない","そう思う","とてもそう思う"),"")) | M20: =IF('19'!B11="","",IFERROR(CHOOSE('19'!B11,"そう思わない","あまりそう思わない","そう思う","とてもそう思う"),"")) | N20: =IF('19'!B12="","",IFERROR(CHOOSE('19'!B12,"そう思わない","あまりそう思わない","そう思う","とてもそう思う"),"")) | O20: =IF('19'!B13="","",IFERROR(CHOOSE('19'!B13,"そう思わない","あまりそう思わない","そう思う","とてもそう思う"),"")) | P20: =IF('19'!B14="","",IFERROR(CHOOSE('19'!B14,"そう思わない","あまりそう思わない","そう思う","とてもそう思う"),"")) | Q20: =IF('19'!B15="","",IFERROR(CHOOSE('19'!B15,"そう思わない","あまりそう思わない","そう思う","とてもそう思う"),"")) | R20: =IF('19'!B16="","",IFERROR(CHOOSE('19'!B16,"そう思わない","あまりそう思わない","そう思う","とてもそう思う"),"")) | S20: =IF('19'!B17="","",IFERROR(CHOOSE('19'!B17,"そう思わない","あまりそう思わない","そう思う","とてもそう思う"),"")) | T20: =IF('19'!B18="","",IFERROR(CHOOSE('19'!B18,"そう思わない","あまりそう思わない","そう思う","とてもそう思う"),""))
A21: 20 | F21: =IF('20'!B4="","",IFERROR(CHOOSE('20'!B4,"そう思わない","あまりそう思わない","そう思う","とてもそう思う"),"")) | G21: =IF('20'!B5="","",IFERROR(CHOOSE('20'!B5,"そう思わない","あまりそう思わない","そう思う","とてもそう思う"),"")) | H21: =IF('20'!B6="","",IFERROR(CHOOSE('20'!B6,"そう思わない","あまりそう思わない","そう思う","とてもそう思う"),"")) | I21: =IF('20'!B7="","",IFERROR(CHOOSE('20'!B7,"そう思わない","あまりそう思わない","そう思う","とてもそう思う"),"")) | J21: =IF('20'!B8="","",IFERROR(CHOOSE('20'!B8,"そう思わない","あまりそう思わない","そう思う","とてもそう思う"),"")) | K21: =IF('20'!B9="","",IFERROR(CHOOSE('20'!B9,"そう思わない","あまりそう思わない","そう思う","とてもそう思う"),"")) | L21: =IF('20'!B10="","",IFERROR(CHOOSE('20'!B10,"そう思わない","あまりそう思わない","そう思う","とてもそう思う"),"")) | M21: =IF('20'!B11="","",IFERROR(CHOOSE('20'!B11,"そう思わない","あまりそう思わない","そう思う","とてもそう思う"),"")) | N21: =IF('20'!B12="","",IFERROR(CHOOSE('20'!B12,"そう思わない","あまりそう思わない","そう思う","とてもそう思う"),"")) | O21: =IF('20'!B13="","",IFERROR(CHOOSE('20'!B13,"そう思わない","あまりそう思わない","そう思う","とてもそう思う"),"")) | P21: =IF('20'!B14="","",IFERROR(CHOOSE('20'!B14,"そう思わない","あまりそう思わない","そう思う","とてもそう思う"),"")) | Q21: =IF('20'!B15="","",IFERROR(CHOOSE('20'!B15,"そう思わない","あまりそう思わない","そう思う","とてもそう思う"),"")) | R21: =IF('20'!B16="","",IFERROR(CHOOSE('20'!B16,"そう思わない","あまりそう思わない","そう思う","とてもそう思う"),"")) | S21: =IF('20'!B17="","",IFERROR(CHOOSE('20'!B17,"そう思わない","あまりそう思わない","そう思う","とてもそう思う"),"")) | T21: =IF('20'!B18="","",IFERROR(CHOOSE('20'!B18,"そう思わない","あまりそう思わない","そう思う","とてもそう思う"),""))
A22: 21 | F22: =IF('21'!B4="","",IFERROR(CHOOSE('21'!B4,"そう思わない","あまりそう思わない","そう思う","とてもそう思う"),"")) | G22: =IF('21'!B5="","",IFERROR(CHOOSE('21'!B5,"そう思わない","あまりそう思わない","そう思う","とてもそう思う"),"")) | H22: =IF('21'!B6="","",IFERROR(CHOOSE('21'!B6,"そう思わない","あまりそう思わない","そう思う","とてもそう思う"),"")) | I22: =IF('21'!B7="","",IFERROR(CHOOSE('21'!B7,"そう思わない","あまりそう思わない","そう思う","とてもそう思う"),"")) | J22: =IF('21'!B8="","",IFERROR(CHOOSE('21'!B8,"そう思わない","あまりそう思わない","そう思う","とてもそう思う"),"")) | K22: =IF('21'!B9="","",IFERROR(CHOOSE('21'!B9,"そう思わない","あまりそう思わない","そう思う","とてもそう思う"),"")) | L22: =IF('21'!B10="","",IFERROR(CHOOSE('21'!B10,"そう思わない","あまりそう思わない","そう思う","とてもそう思う"),"")) | M22: =IF('21'!B11="","",IFERROR(CHOOSE('21'!B11,"そう思わない","あまりそう思わない","そう思う","とてもそう思う"),"")) | N22: =IF('21'!B12="","",IFERROR(CHOOSE('21'!B12,"そう思わない","あまりそう思わない","そう思う","とてもそう思う"),"")) | O22: =IF('21'!B13="","",IFERROR(CHOOSE('21'!B13,"そう思わない","あまりそう思わない","そう思う","とてもそう思う"),"")) | P22: =IF('21'!B14="","",IFERROR(CHOOSE('21'!B14,"そう思わない","あまりそう思わない","そう思う","とてもそう思う"),"")) | Q22: =IF('21'!B15="","",IFERROR(CHOOSE('21'!B15,"そう思わない","あまりそう思わない","そう思う","とてもそう思う"),"")) | R22: =IF('21'!B16="","",IFERROR(CHOOSE('21'!B16,"そう思わない","あまりそう思わない","そう思う","とてもそう思う"),"")) | S22: =IF('21'!B17="","",IFERROR(CHOOSE('21'!B17,"そう思わない","あまりそう思わない","そう思う","とてもそう思う"),"")) | T22: =IF('21'!B18="","",IFERROR(CHOOSE('21'!B18,"そう思わない","あまりそう思わない","そう思う","とてもそう思う"),""))
A23: 22 | F23: =IF('22'!B4="","",IFERROR(CHOOSE('22'!B4,"そう思わない","あまりそう思わない","そう思う","とてもそう思う"),"")) | G23: =IF('22'!B5="","",IFERROR(CHOOSE('22'!B5,"そう思わない","あまりそう思わない","そう思う","とてもそう思う"),"")) | H23: =IF('22'!B6="","",IFERROR(CHOOSE('22'!B6,"そう思わない","あまりそう思わない","そう思う","とてもそう思う"),"")) | I23: =IF('22'!B7="","",IFERROR(CHOOSE('22'!B7,"そう思わない","あまりそう思わない","そう思う","とてもそう思う"),"")) | J23: =IF('22'!B8="","",IFERROR(CHOOSE('22'!B8,"そう思わない","あまりそう思わない","そう思う","とてもそう思う"),"")) | K23: =IF('22'!B9="","",IFERROR(CHOOSE('22'!B9,"そう思わない","あまりそう思わない","そう思う","とてもそう思う"),"")) | L23: =IF('22'!B10="","",IFERROR(CHOOSE('22'!B10,"そう思わない","あまりそう思わない","そう思う","とてもそう思う"),"")) | M23: =IF('22'!B11="","",IFERROR(CHOOSE('22'!B11,"そう思わない","あまりそう思わない","そう思う","とてもそう思う"),"")) | N23: =IF('22'!B12="","",IFERROR(CHOOSE('22'!B12,"そう思わない","あまりそう思わない","そう思う","とてもそう思う"),"")) | O23: =IF('22'!B13="","",IFERROR(CHOOSE('22'!B13,"そう思わない","あまりそう思わない","そう思う","とてもそう思う"),"")) | P23: =IF('22'!B14="","",IFERROR(CHOOSE('22'!B14,"そう思わない","あまりそう思わない","そう思う","とてもそう思う"),"")) | Q23: =IF('22'!B15="","",IFERROR(CHOOSE('22'!B15,"そう思わない","あまりそう思わない","そう思う","とてもそう思う"),"")) | R23: =IF('22'!B16="","",IFERROR(CHOOSE('22'!B16,"そう思わない","あまりそう思わない","そう思う","とてもそう思う"),"")) | S23: =IF('22'!B17="","",IFERROR(CHOOSE('22'!B17,"そう思わない","あまりそう思わない","そう思う","とてもそう思う"),"")) | T23: =IF('22'!B18="","",IFERROR(CHOOSE('22'!B18,"そう思わない","あまりそう思わない","そう思う","とてもそう思う"),""))
A24: 23 | F24: =IF('23'!B4="","",IFERROR(CHOOSE('23'!B4,"そう思わない","あまりそう思わない","そう思う","とてもそう思う"),"")) | G24: =IF('23'!B5="","",IFERROR(CHOOSE('23'!B5,"そう思わない","あまりそう思わない","そう思う","とてもそう思う"),"")) | H24: =IF('23'!B6="","",IFERROR(CHOOSE('23'!B6,"そう思わない","あまりそう思わない","そう思う","とてもそう思う"),"")) | I24: =IF('23'!B7="","",IFERROR(CHOOSE('23'!B7,"そう思わない","あまりそう思わない","そう思う","とてもそう思う"),"")) | J24: =IF('23'!B8="","",IFERROR(CHOOSE('23'!B8,"そう思わない","あまりそう思わない","そう思う","とてもそう思う"),"")) | K24: =IF('23'!B9="","",IFERROR(CHOOSE('23'!B9,"そう思わない","あまりそう思わない","そう思う","とてもそう思う"),"")) | L24: =IF('23'!B10="","",IFERROR(CHOOSE('23'!B10,"そう思わない","あまりそう思わない","そう思う","とてもそう思う"),"")) | M24: =IF('23'!B11="","",IFERROR(CHOOSE('23'!B11,"そう思わない","あまりそう思わない","そう思う","とてもそう思う"),"")) | N24: =IF('23'!B12="","",IFERROR(CHOOSE('23'!B12,"そう思わない","あまりそう思わない","そう思う","とてもそう思う"),"")) | O24: =IF('23'!B13="","",IFERROR(CHOOSE('23'!B13,"そう思わない","あまりそう思わない","そう思う","とてもそう思う"),"")) | P24: =IF('23'!B14="","",IFERROR(CHOOSE('23'!B14,"そう思わない","あまりそう思わない","そう思う","とてもそう思う"),"")) | Q24: =IF('23'!B15="","",IFERROR(CHOOSE('23'!B15,"そう思わない","あまりそう思わない","そう思う","とてもそう思う"),"")) | R24: =IF('23'!B16="","",IFERROR(CHOOSE('23'!B16,"そう思わない","あまりそう思わない","そう思う","とてもそう思う"),"")) | S24: =IF('23'!B17="","",IFERROR(CHOOSE('23'!B17,"そう思わない","あまりそう思わない","そう思う","とてもそう思う"),"")) | T24: =IF('23'!B18="","",IFERROR(CHOOSE('23'!B18,"そう思わない","あまりそう思わない","そう思う","とてもそう思う"),""))
A25: 24 | F25: =IF('24'!B4="","",IFERROR(CHOOSE('24'!B4,"そう思わない","あまりそう思わない","そう思う","とてもそう思う"),"")) | G25: =IF('24'!B5="","",IFERROR(CHOOSE('24'!B5,"そう思わない","あまりそう思わない","そう思う","とてもそう思う"),"")) | H25: =IF('24'!B6="","",IFERROR(CHOOSE('24'!B6,"そう思わない","あまりそう思わない","そう思う","とてもそう思う"),"")) | I25: =IF('24'!B7="","",IFERROR(CHOOSE('24'!B7,"そう思わない","あまりそう思わない","そう思う","とてもそう思う"),"")) | J25: =IF('24'!B8="","",IFERROR(CHOOSE('24'!B8,"そう思わない","あまりそう思わない","そう思う","とてもそう思う"),"")) | K25: =IF('24'!B9="","",IFERROR(CHOOSE('24'!B9,"そう思わない","あまりそう思わない","そう思う","とてもそう思う"),"")) | L25: =IF('24'!B10="","",IFERROR(CHOOSE('24'!B10,"そう思わない","あまりそう思わない","そう思う","とてもそう思う"),"")) | M25: =IF('24'!B11="","",IFERROR(CHOOSE('24'!B11,"そう思わない","あまりそう思わない","そう思う","とてもそう思う"),"")) | N25: =IF('24'!B12="","",IFERROR(CHOOSE('24'!B12,"そう思わない","あまりそう思わない","そう思う","とてもそう思う"),"")) | O25: =IF('24'!B13="","",IFERROR(CHOOSE('24'!B13,"そう思わない","あまりそう思わない","そう思う","とてもそう思う"),"")) | P25: =IF('24'!B14="","",IFERROR(CHOOSE('24'!B14,"そう思わない","あまりそう思わない","そう思う","とてもそう思う"),"")) | Q25: =IF('24'!B15="","",IFERROR(CHOOSE('24'!B15,"そう思わない","あまりそう思わない","そう思う","とてもそう思う"),"")) | R25: =IF('24'!B16="","",IFERROR(CHOOSE('24'!B16,"そう思わない","あまりそう思わない","そう思う","とてもそう思う"),"")) | S25: =IF('24'!B17="","",IFERROR(CHOOSE('24'!B17,"そう思わない","あまりそう思わない","そう思う","とてもそう思う"),"")) | T25: =IF('24'!B18="","",IFERROR(CHOOSE('24'!B18,"そう思わない","あまりそう思わない","そう思う","とてもそう思う"),""))
A26: 25 | F26: =IF('25'!B4="","",IFERROR(CHOOSE('25'!B4,"そう思わない","あまりそう思わない","そう思う","とてもそう思う"),"")) | G26: =IF('25'!B5="","",IFERROR(CHOOSE('25'!B5,"そう思わない","あまりそう思わない","そう思う","とてもそう思う"),"")) | H26: =IF('25'!B6="","",IFERROR(CHOOSE('25'!B6,"そう思わない","あまりそう思わない","そう思う","とてもそう思う"),"")) | I26: =IF('25'!B7="","",IFERROR(CHOOSE('25'!B7,"そう思わない","あまりそう思わない","そう思う","とてもそう思う"),"")) | J26: =IF('25'!B8="","",IFERROR(CHOOSE('25'!B8,"そう思わない","あまりそう思わない","そう思う","とてもそう思う"),"")) | K26: =IF('25'!B9="","",IFERROR(CHOOSE('25'!B9,"そう思わない","あまりそう思わない","そう思う","とてもそう思う"),"")) | L26: =IF('25'!B10="","",IFERROR(CHOOSE('25'!B10,"そう思わない","あまりそう思わない","そう思う","とてもそう思う"),"")) | M26: =IF('25'!B11="","",IFERROR(CHOOSE('25'!B11,"そう思わない","あまりそう思わない","そう思う","とてもそう思う"),"")) | N26: =IF('25'!B12="","",IFERROR(CHOOSE('25'!B12,"そう思わない","あまりそう思わない","そう思う","とてもそう思う"),"")) | O26: =IF('25'!B13="","",IFERROR(CHOOSE('25'!B13,"そう思わない","あまりそう思わない","そう思う","とてもそう思う"),"")) | P26: =IF('25'!B14="","",IFERROR(CHOOSE('25'!B14,"そう思わない","あまりそう思わない","そう思う","とてもそう思う"),"")) | Q26: =IF('25'!B15="","",IFERROR(CHOOSE('25'!B15,"そう思わない","あまりそう思わない","そう思う","とてもそう思う"),"")) | R26: =IF('25'!B16="","",IFERROR(CHOOSE('25'!B16,"そう思わない","あまりそう思わない","そう思う","とてもそう思う"),"")) | S26: =IF('25'!B17="","",IFERROR(CHOOSE('25'!B17,"そう思わない","あまりそう思わない","そう思う","とてもそう思う"),"")) | T26: =IF('25'!B18="","",IFERROR(CHOOSE('25'!B18,"そう思わない","あまりそう思わない","そう思う","とてもそう思う"),""))
A27: 26 | F27: =IF('26'!B4="","",IFERROR(CHOOSE('26'!B4,"そう思わない","あまりそう思わない","そう思う","とてもそう思う"),"")) | G27: =IF('26'!B5="","",IFERROR(CHOOSE('26'!B5,"そう思わない","あまりそう思わない","そう思う","とてもそう思う"),"")) | H27: =IF('26'!B6="","",IFERROR(CHOOSE('26'!B6,"そう思わない","あまりそう思わない","そう思う","とてもそう思う"),"")) | I27: =IF('26'!B7="","",IFERROR(CHOOSE('26'!B7,"そう思わない","あまりそう思わない","そう思う","とてもそう思う"),"")) | J27: =IF('26'!B8="","",IFERROR(CHOOSE('26'!B8,"そう思わない","あまりそう思わない","そう思う","とてもそう思う"),"")) | K27: =IF('26'!B9="","",IFERROR(CHOOSE('26'!B9,"そう思わない","あまりそう思わない","そう思う","とてもそう思う"),"")) | L27: =IF('26'!B10="","",IFERROR(CHOOSE('26'!B10,"そう思わない","あまりそう思わない","そう思う","とてもそう思う"),"")) | M27: =IF('26'!B11="","",IFERROR(CHOOSE('26'!B11,"そう思わない","あまりそう思わない","そう思う","とてもそう思う"),"")) | N27: =IF('26'!B12="","",IFERROR(CHOOSE('26'!B12,"そう思わない","あまりそう思わない","そう思う","とてもそう思う"),"")) | O27: =IF('26'!B13="","",IFERROR(CHOOSE('26'!B13,"そう思わない","あまりそう思わない","そう思う","とてもそう思う"),"")) | P27: =IF('26'!B14="","",IFERROR(CHOOSE('26'!B14,"そう思わない","あまりそう思わない","そう思う","とてもそう思う"),"")) | Q27: =IF('26'!B15="","",IFERROR(CHOOSE('26'!B15,"そう思わない","あまりそう思わない","そう思う","とてもそう思う"),"")) | R27: =IF('26'!B16="","",IFERROR(CHOOSE('26'!B16,"そう思わない","あまりそう思わない","そう思う","とてもそう思う"),"")) | S27: =IF('26'!B17="","",IFERROR(CHOOSE('26'!B17,"そう思わない","あまりそう思わない","そう思う","とてもそう思う"),"")) | T27: =IF('26'!B18="","",IFERROR(CHOOSE('26'!B18,"そう思わない","あまりそう思わない","そう思う","とてもそう思う"),""))
A28: 27 | F28: =IF('27'!B4="","",IFERROR(CHOOSE('27'!B4,"そう思わない","あまりそう思わない","そう思う","とてもそう思う"),"")) | G28: =IF('27'!B5="","",IFERROR(CHOOSE('27'!B5,"そう思わない","あまりそう思わない","そう思う","とてもそう思う"),"")) | H28: =IF('27'!B6="","",IFERROR(CHOOSE('27'!B6,"そう思わない","あまりそう思わない","そう思う","とてもそう思う"),"")) | I28: =IF('27'!B7="","",IFERROR(CHOOSE('27'!B7,"そう思わない","あまりそう思わない","そう思う","とてもそう思う"),"")) | J28: =IF('27'!B8="","",IFERROR(CHOOSE('27'!B8,"そう思わない","あまりそう思わない","そう思う","とてもそう思う"),"")) | K28: =IF('27'!B9="","",IFERROR(CHOOSE('27'!B9,"そう思わない","あまりそう思わない","そう思う","とてもそう思う"),"")) | L28: =IF('27'!B10="","",IFERROR(CHOOSE('27'!B10,"そう思わない","あまりそう思わない","そう思う","とてもそう思う"),"")) | M28: =IF('27'!B11="","",IFERROR(CHOOSE('27'!B11,"そう思わない","あまりそう思わない","そう思う","とてもそう思う"),"")) | N28: =IF('27'!B12="","",IFERROR(CHOOSE('27'!B12,"そう思わない","あまりそう思わない","そう思う","とてもそう思う"),"")) | O28: =IF('27'!B13="","",IFERROR(CHOOSE('27'!B13,"そう思わない","あまりそう思わない","そう思う","とてもそう思う"),"")) | P28: =IF('27'!B14="","",IFERROR(CHOOSE('27'!B14,"そう思わない","あまりそう思わない","そう思う","とてもそう思う"),"")) | Q28: =IF('27'!B15="","",IFERROR(CHOOSE('27'!B15,"そう思わない","あまりそう思わない","そう思う","とてもそう思う"),"")) | R28: =IF('27'!B16="","",IFERROR(CHOOSE('27'!B16,"そう思わない","あまりそう思わない","そう思う","とてもそう思う"),"")) | S28: =IF('27'!B17="","",IFERROR(CHOOSE('27'!B17,"そう思わない","あまりそう思わない","そう思う","とてもそう思う"),"")) | T28: =IF('27'!B18="","",IFERROR(CHOOSE('27'!B18,"そう思わない","あまりそう思わない","そう思う","とてもそう思う"),""))
A29: 28 | F29: =IF('28'!B4="","",IFERROR(CHOOSE('28'!B4,"そう思わない","あまりそう思わない","そう思う","とてもそう思う"),"")) | G29: =IF('28'!B5="","",IFERROR(CHOOSE('28'!B5,"そう思わない","あまりそう思わない","そう思う","とてもそう思う"),"")) | H29: =IF('28'!B6="","",IFERROR(CHOOSE('28'!B6,"そう思わない","あまりそう思わない","そう思う","とてもそう思う"),"")) | I29: =IF('28'!B7="","",IFERROR(CHOOSE('28'!B7,"そう思わない","あまりそう思わない","そう思う","とてもそう思う"),"")) | J29: =IF('28'!B8="","",IFERROR(CHOOSE('28'!B8,"そう思わない","あまりそう思わない","そう思う","とてもそう思う"),"")) | K29: =IF('28'!B9="","",IFERROR(CHOOSE('28'!B9,"そう思わない","あまりそう思わない","そう思う","とてもそう思う"),"")) | L29: =IF('28'!B10="","",IFERROR(CHOOSE('28'!B10,"そう思わない","あまりそう思わない","そう思う","とてもそう思う"),"")) | M29: =IF('28'!B11="","",IFERROR(CHOOSE('28'!B11,"そう思わない","あまりそう思わない","そう思う","とてもそう思う"),"")) | N29: =IF('28'!B12="","",IFERROR(CHOOSE('28'!B12,"そう思わない","あまりそう思わない","そう思う","とてもそう思う"),"")) | O29: =IF('28'!B13="","",IFERROR(CHOOSE('28'!B13,"そう思わない","あまりそう思わない","そう思う","とてもそう思う"),"")) | P29: =IF('28'!B14="","",IFERROR(CHOOSE('28'!B14,"そう思わない","あまりそう思わない","そう思う","とてもそう思う"),"")) | Q29: =IF('28'!B15="","",IFERROR(CHOOSE('28'!B15,"そう思わない","あまりそう思わない","そう思う","とてもそう思う"),"")) | R29: =IF('28'!B16="","",IFERROR(CHOOSE('28'!B16,"そう思わない","あまりそう思わない","そう思う","とてもそう思う"),"")) | S29: =IF('28'!B17="","",IFERROR(CHOOSE('28'!B17,"そう思わない","あまりそう思わない","そう思う","とてもそう思う"),"")) | T29: =IF('28'!B18="","",IFERROR(CHOOSE('28'!B18,"そう思わない","あまりそう思わない","そう思う","とてもそう思う"),""))
A30: 29 | F30: =IF('29'!B4="","",IFERROR(CHOOSE('29'!B4,"そう思わない","あまりそう思わない","そう思う","とてもそう思う"),"")) | G30: =IF('29'!B5="","",IFERROR(CHOOSE('29'!B5,"そう思わない","あまりそう思わない","そう思う","とてもそう思う"),"")) | H30: =IF('29'!B6="","",IFERROR(CHOOSE('29'!B6,"そう思わない","あまりそう思わない","そう思う","とてもそう思う"),"")) | I30: =IF('29'!B7="","",IFERROR(CHOOSE('29'!B7,"そう思わない","あまりそう思わない","そう思う","とてもそう思う"),"")) | J30: =IF('29'!B8="","",IFERROR(CHOOSE('29'!B8,"そう思わない","あまりそう思わない","そう思う","とてもそう思う"),"")) | K30: =IF('29'!B9="","",IFERROR(CHOOSE('29'!B9,"そう思わない","あまりそう思わない","そう思う","とてもそう思う"),"")) | L30: =IF('29'!B10="","",IFERROR(CHOOSE('29'!B10,"そう思わない","あまりそう思わない","そう思う","とてもそう思う"),"")) | M30: =IF('29'!B11="","",IFERROR(CHOOSE('29'!B11,"そう思わない","あまりそう思わない","そう思う","とてもそう思う"),"")) | N30: =IF('29'!B12="","",IFERROR(CHOOSE('29'!B12,"そう思わない","あまりそう思わない","そう思う","とてもそう思う"),"")) | O30: =IF('29'!B13="","",IFERROR(CHOOSE('29'!B13,"そう思わない","あまりそう思わない","そう思う","とてもそう思う"),"")) | P30: =IF('29'!B14="","",IFERROR(CHOOSE('29'!B14,"そう思わない","あまりそう思わない","そう思う","とてもそう思う"),"")) | Q30: =IF('29'!B15="","",IFERROR(CHOOSE('29'!B15,"そう思わない","あまりそう思わない","そう思う","とてもそう思う"),"")) | R30: =IF('29'!B16="","",IFERROR(CHOOSE('29'!B16,"そう思わない","あまりそう思わない","そう思う","とてもそう思う"),"")) | S30: =IF('29'!B17="","",IFERROR(CHOOSE('29'!B17,"そう思わない","あまりそう思わない","そう思う","とてもそう思う"),"")) | T30: =IF('29'!B18="","",IFERROR(CHOOSE('29'!B18,"そう思わない","あまりそう思わない","そう思う","とてもそう思う"),""))
A31: 30 | F31: =IF('30'!B4="","",IFERROR(CHOOSE('30'!B4,"そう思わない","あまりそう思わない","そう思う","とてもそう思う"),"")) | G31: =IF('30'!B5="","",IFERROR(CHOOSE('30'!B5,"そう思わない","あまりそう思わない","そう思う","とてもそう思う"),"")) | H31: =IF('30'!B6="","",IFERROR(CHOOSE('30'!B6,"そう思わない","あまりそう思わない","そう思う","とてもそう思う"),"")) | I31: =IF('30'!B7="","",IFERROR(CHOOSE('30'!B7,"そう思わない","あまりそう思わない","そう思う","とてもそう思う"),"")) | J31: =IF('30'!B8="","",IFERROR(CHOOSE('30'!B8,"そう思わない","あまりそう思わない","そう思う","とてもそう思う"),"")) | K31: =IF('30'!B9="","",IFERROR(CHOOSE('30'!B9,"そう思わない","あまりそう思わない","そう思う","とてもそう思う"),"")) | L31: =IF('30'!B10="","",IFERROR(CHOOSE('30'!B10,"そう思わない","あまりそう思わない","そう思う","とてもそう思う"),"")) | M31: =IF('30'!B11="","",IFERROR(CHOOSE('30'!B11,"そう思わない","あまりそう思わない","そう思う","とてもそう思う"),"")) | N31: =IF('30'!B12="","",IFERROR(CHOOSE('30'!B12,"そう思わない","あまりそう思わない","そう思う","とてもそう思う"),"")) | O31: =IF('30'!B13="","",IFERROR(CHOOSE('30'!B13,"そう思わない","あまりそう思わない","そう思う","とてもそう思う"),"")) | P31: =IF('30'!B14="","",IFERROR(CHOOSE('30'!B14,"そう思わない","あまりそう思わない","そう思う","とてもそう思う"),"")) | Q31: =IF('30'!B15="","",IFERROR(CHOOSE('30'!B15,"そう思わない","あまりそう思わない","そう思う","とてもそう思う"),"")) | R31: =IF('30'!B16="","",IFERROR(CHOOSE('30'!B16,"そう思わない","あまりそう思わない","そう思う","とてもそう思う"),"")) | S31: =IF('30'!B17="","",IFERROR(CHOOSE('30'!B17,"そう思わない","あまりそう思わない","そう思う","とてもそう思う"),"")) | T31: =IF('30'!B18="","",IFERROR(CHOOSE('30'!B18,"そう思わない","あまりそう思わない","そう思う","とてもそう思う"),""))
A32: 31 | F32: =IF('31'!B4="","",IFERROR(CHOOSE('31'!B4,"そう思わない","あまりそう思わない","そう思う","とてもそう思う"),"")) | G32: =IF('31'!B5="","",IFERROR(CHOOSE('31'!B5,"そう思わない","あまりそう思わない","そう思う","とてもそう思う"),"")) | H32: =IF('31'!B6="","",IFERROR(CHOOSE('31'!B6,"そう思わない","あまりそう思わない","そう思う","とてもそう思う"),"")) | I32: =IF('31'!B7="","",IFERROR(CHOOSE('31'!B7,"そう思わない","あまりそう思わない","そう思う","とてもそう思う"),"")) | J32: =IF('31'!B8="","",IFERROR(CHOOSE('31'!B8,"そう思わない","あまりそう思わない","そう思う","とてもそう思う"),"")) | K32: =IF('31'!B9="","",IFERROR(CHOOSE('31'!B9,"そう思わない","あまりそう思わない","そう思う","とてもそう思う"),"")) | L32: =IF('31'!B10="","",IFERROR(CHOOSE('31'!B10,"そう思わない","あまりそう思わない","そう思う","とてもそう思う"),"")) | M32: =IF('31'!B11="","",IFERROR(CHOOSE('31'!B11,"そう思わない","あまりそう思わない","そう思う","とてもそう思う"),"")) | N32: =IF('31'!B12="","",IFERROR(CHOOSE('31'!B12,"そう思わない","あまりそう思わない","そう思う","とてもそう思う"),"")) | O32: =IF('31'!B13="","",IFERROR(CHOOSE('31'!B13,"そう思わない","あまりそう思わない","そう思う","とてもそう思う"),"")) | P32: =IF('31'!B14="","",IFERROR(CHOOSE('31'!B14,"そう思わない","あまりそう思わない","そう思う","とてもそう思う"),"")) | Q32: =IF('31'!B15="","",IFERROR(CHOOSE('31'!B15,"そう思わない","あまりそう思わない","そう思う","とてもそう思う"),"")) | R32: =IF('31'!B16="","",IFERROR(CHOOSE('31'!B16,"そう思わない","あまりそう思わない","そう思う","とてもそう思う"),"")) | S32: =IF('31'!B17="","",IFERROR(CHOOSE('31'!B17,"そう思わない","あまりそう思わない","そう思う","とてもそう思う"),"")) | T32: =IF('31'!B18="","",IFERROR(CHOOSE('31'!B18,"そう思わない","あまりそう思わない","そう思う","とてもそう思う"),""))
A33: 32 | F33: =IF('32'!B4="","",IFERROR(CHOOSE('32'!B4,"そう思わない","あまりそう思わない","そう思う","とてもそう思う"),"")) | G33: =IF('32'!B5="","",IFERROR(CHOOSE('32'!B5,"そう思わない","あまりそう思わない","そう思う","とてもそう思う"),"")) | H33: =IF('32'!B6="","",IFERROR(CHOOSE('32'!B6,"そう思わない","あまりそう思わない","そう思う","とてもそう思う"),"")) | I33: =IF('32'!B7="","",IFERROR(CHOOSE('32'!B7,"そう思わない","あまりそう思わない","そう思う","とてもそう思う"),"")) | J33: =IF('32'!B8="","",IFERROR(CHOOSE('32'!B8,"そう思わない","あまりそう思わない","そう思う","とてもそう思う"),"")) | K33: =IF('32'!B9="","",IFERROR(CHOOSE('32'!B9,"そう思わない","あまりそう思わない","そう思う","とてもそう思う"),"")) | L33: =IF('32'!B10="","",IFERROR(CHOOSE('32'!B10,"そう思わない","あまりそう思わない","そう思う","とてもそう思う"),"")) | M33: =IF('32'!B11="","",IFERROR(CHOOSE('32'!B11,"そう思わない","あまりそう思わない","そう思う","とてもそう思う"),"")) | N33: =IF('32'!B12="","",IFERROR(CHOOSE('32'!B12,"そう思わない","あまりそう思わない","そう思う","とてもそう思う"),"")) | O33: =IF('32'!B13="","",IFERROR(CHOOSE('32'!B13,"そう思わない","あまりそう思わない","そう思う","とてもそう思う"),"")) | P33: =IF('32'!B14="","",IFERROR(CHOOSE('32'!B14,"そう思わない","あまりそう思わない","そう思う","とてもそう思う"),"")) | Q33: =IF('32'!B15="","",IFERROR(CHOOSE('32'!B15,"そう思わない","あまりそう思わない","そう思う","とてもそう思う"),"")) | R33: =IF('32'!B16="","",IFERROR(CHOOSE('32'!B16,"そう思わない","あまりそう思わない","そう思う","とてもそう思う"),"")) | S33: =IF('32'!B17="","",IFERROR(CHOOSE('32'!B17,"そう思わない","あまりそう思わない","そう思う","とてもそう思う"),"")) | T33: =IF('32'!B18="","",IFERROR(CHOOSE('32'!B18,"そう思わない","あまりそう思わない","そう思う","とてもそう思う"),""))
A34: 33 | F34: =IF('33'!B4="","",IFERROR(CHOOSE('33'!B4,"そう思わない","あまりそう思わない","そう思う","とてもそう思う"),"")) | G34: =IF('33'!B5="","",IFERROR(CHOOSE('33'!B5,"そう思わない","あまりそう思わない","そう思う","とてもそう思う"),"")) | H34: =IF('33'!B6="","",IFERROR(CHOOSE('33'!B6,"そう思わない","あまりそう思わない","そう思う","とてもそう思う"),"")) | I34: =IF('33'!B7="","",IFERROR(CHOOSE('33'!B7,"そう思わない","あまりそう思わない","そう思う","とてもそう思う"),"")) | J34: =IF('33'!B8="","",IFERROR(CHOOSE('33'!B8,"そう思わない","あまりそう思わない","そう思う","とてもそう思う"),"")) | K34: =IF('33'!B9="","",IFERROR(CHOOSE('33'!B9,"そう思わない","あまりそう思わない","そう思う","とてもそう思う"),"")) | L34: =IF('33'!B10="","",IFERROR(CHOOSE('33'!B10,"そう思わない","あまりそう思わない","そう思う","とてもそう思う"),"")) | M34: =IF('33'!B11="","",IFERROR(CHOOSE('33'!B11,"そう思わない","あまりそう思わない","そう思う","とてもそう思う"),"")) | N34: =IF('33'!B12="","",IFERROR(CHOOSE('33'!B12,"そう思わない","あまりそう思わない","そう思う","とてもそう思う"),"")) | O34: =IF('33'!B13="","",IFERROR(CHOOSE('33'!B13,"そう思わない","あまりそう思わない","そう思う","とてもそう思う"),"")) | P34: =IF('33'!B14="","",IFERROR(CHOOSE('33'!B14,"そう思わない","あまりそう思わない","そう思う","とてもそう思う"),"")) | Q34: =IF('33'!B15="","",IFERROR(CHOOSE('33'!B15,"そう思わない","あまりそう思わない","そう思う","とてもそう思う"),"")) | R34: =IF('33'!B16="","",IFERROR(CHOOSE('33'!B16,"そう思わない","あまりそう思わない","そう思う","とてもそう思う"),"")) | S34: =IF('33'!B17="","",IFERROR(CHOOSE('33'!B17,"そう思わない","あまりそう思わない","そう思う","とてもそう思う"),"")) | T34: =IF('33'!B18="","",IFERROR(CHOOSE('33'!B18,"そう思わない","あまりそう思わない","そう思う","とてもそう思う"),""))
A35: 34 | F35: =IF('34'!B4="","",IFERROR(CHOOSE('34'!B4,"そう思わない","あまりそう思わない","そう思う","とてもそう思う"),"")) | G35: =IF('34'!B5="","",IFERROR(CHOOSE('34'!B5,"そう思わない","あまりそう思わない","そう思う","とてもそう思う"),"")) | H35: =IF('34'!B6="","",IFERROR(CHOOSE('34'!B6,"そう思わない","あまりそう思わない","そう思う","とてもそう思う"),"")) | I35: =IF('34'!B7="","",IFERROR(CHOOSE('34'!B7,"そう思わない","あまりそう思わない","そう思う","とてもそう思う"),"")) | J35: =IF('34'!B8="","",IFERROR(CHOOSE('34'!B8,"そう思わない","あまりそう思わない","そう思う","とてもそう思う"),"")) | K35: =IF('34'!B9="","",IFERROR(CHOOSE('34'!B9,"そう思わない","あまりそう思わない","そう思う","とてもそう思う"),"")) | L35: =IF('34'!B10="","",IFERROR(CHOOSE('34'!B10,"そう思わない","あまりそう思わない","そう思う","とてもそう思う"),"")) | M35: =IF('34'!B11="","",IFERROR(CHOOSE('34'!B11,"そう思わない","あまりそう思わない","そう思う","とてもそう思う"),"")) | N35: =IF('34'!B12="","",IFERROR(CHOOSE('34'!B12,"そう思わない","あまりそう思わない","そう思う","とてもそう思う"),"")) | O35: =IF('34'!B13="","",IFERROR(CHOOSE('34'!B13,"そう思わない","あまりそう思わない","そう思う","とてもそう思う"),"")) | P35: =IF('34'!B14="","",IFERROR(CHOOSE('34'!B14,"そう思わない","あまりそう思わない","そう思う","とてもそう思う"),"")) | Q35: =IF('34'!B15="","",IFERROR(CHOOSE('34'!B15,"そう思わない","あまりそう思わない","そう思う","とてもそう思う"),"")) | R35: =IF('34'!B16="","",IFERROR(CHOOSE('34'!B16,"そう思わない","あまりそう思わない","そう思う","とてもそう思う"),"")) | S35: =IF('34'!B17="","",IFERROR(CHOOSE('34'!B17,"そう思わない","あまりそう思わない","そう思う","とてもそう思う"),"")) | T35: =IF('34'!B18="","",IFERROR(CHOOSE('34'!B18,"そう思わない","あまりそう思わない","そう思う","とてもそう思う"),""))
A36: 35 | F36: =IF('35'!B4="","",IFERROR(CHOOSE('35'!B4,"そう思わない","あまりそう思わない","そう思う","とてもそう思う"),"")) | G36: =IF('35'!B5="","",IFERROR(CHOOSE('35'!B5,"そう思わない","あまりそう思わない","そう思う","とてもそう思う"),"")) | H36: =IF('35'!B6="","",IFERROR(CHOOSE('35'!B6,"そう思わない","あまりそう思わない","そう思う","とてもそう思う"),"")) | I36: =IF('35'!B7="","",IFERROR(CHOOSE('35'!B7,"そう思わない","あまりそう思わない","そう思う","とてもそう思う"),"")) | J36: =IF('35'!B8="","",IFERROR(CHOOSE('35'!B8,"そう思わない","あまりそう思わない","そう思う","とてもそう思う"),"")) | K36: =IF('35'!B9="","",IFERROR(CHOOSE('35'!B9,"そう思わない","あまりそう思わない","そう思う","とてもそう思う"),"")) | L36: =IF('35'!B10="","",IFERROR(CHOOSE('35'!B10,"そう思わない","あまりそう思わない","そう思う","とてもそう思う"),"")) | M36: =IF('35'!B11="","",IFERROR(CHOOSE('35'!B11,"そう思わない","あまりそう思わない","そう思う","とてもそう思う"),"")) | N36: =IF('35'!B12="","",IFERROR(CHOOSE('35'!B12,"そう思わない","あまりそう思わない","そう思う","とてもそう思う"),"")) | O36: =IF('35'!B13="","",IFERROR(CHOOSE('35'!B13,"そう思わない","あまりそう思わない","そう思う","とてもそう思う"),"")) | P36: =IF('35'!B14="","",IFERROR(CHOOSE('35'!B14,"そう思わない","あまりそう思わない","そう思う","とてもそう思う"),"")) | Q36: =IF('35'!B15="","",IFERROR(CHOOSE('35'!B15,"そう思わない","あまりそう思わない","そう思う","とてもそう思う"),"")) | R36: =IF('35'!B16="","",IFERROR(CHOOSE('35'!B16,"そう思わない","あまりそう思わない","そう思う","とてもそう思う"),"")) | S36: =IF('35'!B17="","",IFERROR(CHOOSE('35'!B17,"そう思わない","あまりそう思わない","そう思う","とてもそう思う"),"")) | T36: =IF('35'!B18="","",IFERROR(CHOOSE('35'!B18,"そう思わない","あまりそう思わない","そう思う","とてもそう思う"),""))
A37: 36 | F37: =IF('36'!B4="","",IFERROR(CHOOSE('36'!B4,"そう思わない","あまりそう思わない","そう思う","とてもそう思う"),"")) | G37: =IF('36'!B5="","",IFERROR(CHOOSE('36'!B5,"そう思わない","あまりそう思わない","そう思う","とてもそう思う"),"")) | H37: =IF('36'!B6="","",IFERROR(CHOOSE('36'!B6,"そう思わない","あまりそう思わない","そう思う","とてもそう思う"),"")) | I37: =IF('36'!B7="","",IFERROR(CHOOSE('36'!B7,"そう思わない","あまりそう思わない","そう思う","とてもそう思う"),"")) | J37: =IF('36'!B8="","",IFERROR(CHOOSE('36'!B8,"そう思わない","あまりそう思わない","そう思う","とてもそう思う"),"")) | K37: =IF('36'!B9="","",IFERROR(CHOOSE('36'!B9,"そう思わない","あまりそう思わない","そう思う","とてもそう思う"),"")) | L37: =IF('36'!B10="","",IFERROR(CHOOSE('36'!B10,"そう思わない","あまりそう思わない","そう思う","とてもそう思う"),"")) | M37: =IF('36'!B11="","",IFERROR(CHOOSE('36'!B11,"そう思わない","あまりそう思わない","そう思う","とてもそう思う"),"")) | N37: =IF('36'!B12="","",IFERROR(CHOOSE('36'!B12,"そう思わない","あまりそう思わない","そう思う","とてもそう思う"),"")) | O37: =IF('36'!B13="","",IFERROR(CHOOSE('36'!B13,"そう思わない","あまりそう思わない","そう思う","とてもそう思う"),"")) | P37: =IF('36'!B14="","",IFERROR(CHOOSE('36'!B14,"そう思わない","あまりそう思わない","そう思う","とてもそう思う"),"")) | Q37: =IF('36'!B15="","",IFERROR(CHOOSE('36'!B15,"そう思わない","あまりそう思わない","そう思う","とてもそう思う"),"")) | R37: =IF('36'!B16="","",IFERROR(CHOOSE('36'!B16,"そう思わない","あまりそう思わない","そう思う","とてもそう思う"),"")) | S37: =IF('36'!B17="","",IFERROR(CHOOSE('36'!B17,"そう思わない","あまりそう思わない","そう思う","とてもそう思う"),"")) | T37: =IF('36'!B18="","",IFERROR(CHOOSE('36'!B18,"そう思わない","あまりそう思わない","そう思う","とてもそう思う"),""))
A38: 37 | F38: =IF('37'!B4="","",IFERROR(CHOOSE('37'!B4,"そう思わない","あまりそう思わない","そう思う","とてもそう思う"),"")) | G38: =IF('37'!B5="","",IFERROR(CHOOSE('37'!B5,"そう思わない","あまりそう思わない","そう思う","とてもそう思う"),"")) | H38: =IF('37'!B6="","",IFERROR(CHOOSE('37'!B6,"そう思わない","あまりそう思わない","そう思う","とてもそう思う"),"")) | I38: =IF('37'!B7="","",IFERROR(CHOOSE('37'!B7,"そう思わない","あまりそう思わない","そう思う","とてもそう思う"),"")) | J38: =IF('37'!B8="","",IFERROR(CHOOSE('37'!B8,"そう思わない","あまりそう思わない","そう思う","とてもそう思う"),"")) | K38: =IF('37'!B9="","",IFERROR(CHOOSE('37'!B9,"そう思わない","あまりそう思わない","そう思う","とてもそう思う"),"")) | L38: =IF('37'!B10="","",IFERROR(CHOOSE('37'!B10,"そう思わない","あまりそう思わない","そう思う","とてもそう思う"),"")) | M38: =IF('37'!B11="","",IFERROR(CHOOSE('37'!B11,"そう思わない","あまりそう思わない","そう思う","とてもそう思う"),"")) | N38: =IF('37'!B12="","",IFERROR(CHOOSE('37'!B12,"そう思わない","あまりそう思わない","そう思う","とてもそう思う"),"")) | O38: =IF('37'!B13="","",IFERROR(CHOOSE('37'!B13,"そう思わない","あまりそう思わない","そう思う","とてもそう思う"),"")) | P38: =IF('37'!B14="","",IFERROR(CHOOSE('37'!B14,"そう思わない","あまりそう思わない","そう思う","とてもそう思う"),"")) | Q38: =IF('37'!B15="","",IFERROR(CHOOSE('37'!B15,"そう思わない","あまりそう思わない","そう思う","とてもそう思う"),"")) | R38: =IF('37'!B16="","",IFERROR(CHOOSE('37'!B16,"そう思わない","あまりそう思わない","そう思う","とてもそう思う"),"")) | S38: =IF('37'!B17="","",IFERROR(CHOOSE('37'!B17,"そう思わない","あまりそう思わない","そう思う","とてもそう思う"),"")) | T38: =IF('37'!B18="","",IFERROR(CHOOSE('37'!B18,"そう思わない","あまりそう思わない","そう思う","とてもそう思う"),""))
A39: 38 | F39: =IF('38'!B4="","",IFERROR(CHOOSE('38'!B4,"そう思わない","あまりそう思わない","そう思う","とてもそう思う"),"")) | G39: =IF('38'!B5="","",IFERROR(CHOOSE('38'!B5,"そう思わない","あまりそう思わない","そう思う","とてもそう思う"),"")) | H39: =IF('38'!B6="","",IFERROR(CHOOSE('38'!B6,"そう思わない","あまりそう思わない","そう思う","とてもそう思う"),"")) | I39: =IF('38'!B7="","",IFERROR(CHOOSE('38'!B7,"そう思わない","あまりそう思わない","そう思う","とてもそう思う"),"")) | J39: =IF('38'!B8="","",IFERROR(CHOOSE('38'!B8,"そう思わない","あまりそう思わない","そう思う","とてもそう思う"),"")) | K39: =IF('38'!B9="","",IFERROR(CHOOSE('38'!B9,"そう思わない","あまりそう思わない","そう思う","とてもそう思う"),"")) | L39: =IF('38'!B10="","",IFERROR(CHOOSE('38'!B10,"そう思わない","あまりそう思わない","そう思う","とてもそう思う"),"")) | M39: =IF('38'!B11="","",IFERROR(CHOOSE('38'!B11,"そう思わない","あまりそう思わない","そう思う","とてもそう思う"),"")) | N39: =IF('38'!B12="","",IFERROR(CHOOSE('38'!B12,"そう思わない","あまりそう思わない","そう思う","とてもそう思う"),"")) | O39: =IF('38'!B13="","",IFERROR(CHOOSE('38'!B13,"そう思わない","あまりそう思わない","そう思う","とてもそう思う"),"")) | P39: =IF('38'!B14="","",IFERROR(CHOOSE('38'!B14,"そう思わない","あまりそう思わない","そう思う","とてもそう思う"),"")) | Q39: =IF('38'!B15="","",IFERROR(CHOOSE('38'!B15,"そう思わない","あまりそう思わない","そう思う","とてもそう思う"),"")) | R39: =IF('38'!B16="","",IFERROR(CHOOSE('38'!B16,"そう思わない","あまりそう思わない","そう思う","とてもそう思う"),"")) | S39: =IF('38'!B17="","",IFERROR(CHOOSE('38'!B17,"そう思わない","あまりそう思わない","そう思う","とてもそう思う"),"")) | T39: =IF('38'!B18="","",IFERROR(CHOOSE('38'!B18,"そう思わない","あまりそう思わない","そう思う","とてもそう思う"),""))
A40: 39 | F40: =IF('39'!B4="","",IFERROR(CHOOSE('39'!B4,"そう思わない","あまりそう思わない","そう思う","とてもそう思う"),"")) | G40: =IF('39'!B5="","",IFERROR(CHOOSE('39'!B5,"そう思わない","あまりそう思わない","そう思う","とてもそう思う"),"")) | H40: =IF('39'!B6="","",IFERROR(CHOOSE('39'!B6,"そう思わない","あまりそう思わない","そう思う","とてもそう思う"),"")) | I40: =IF('39'!B7="","",IFERROR(CHOOSE('39'!B7,"そう思わない","あまりそう思わない","そう思う","とてもそう思う"),"")) | J40: =IF('39'!B8="","",IFERROR(CHOOSE('39'!B8,"そう思わない","あまりそう思わない","そう思う","とてもそう思う"),"")) | K40: =IF('39'!B9="","",IFERROR(CHOOSE('39'!B9,"そう思わない","あまりそう思わない","そう思う","とてもそう思う"),"")) | L40: =IF('39'!B10="","",IFERROR(CHOOSE('39'!B10,"そう思わない","あまりそう思わない","そう思う","とてもそう思う"),"")) | M40: =IF('39'!B11="","",IFERROR(CHOOSE('39'!B11,"そう思わない","あまりそう思わない","そう思う","とてもそう思う"),"")) | N40: =IF('39'!B12="","",IFERROR(CHOOSE('39'!B12,"そう思わない","あまりそう思わない","そう思う","とてもそう思う"),"")) | O40: =IF('39'!B13="","",IFERROR(CHOOSE('39'!B13,"そう思わない","あまりそう思わない","そう思う","とてもそう思う"),"")) | P40: =IF('39'!B14="","",IFERROR(CHOOSE('39'!B14,"そう思わない","あまりそう思わない","そう思う","とてもそう思う"),"")) | Q40: =IF('39'!B15="","",IFERROR(CHOOSE('39'!B15,"そう思わない","あまりそう思わない","そう思う","とてもそう思う"),"")) | R40: =IF('39'!B16="","",IFERROR(CHOOSE('39'!B16,"そう思わない","あまりそう思わない","そう思う","とてもそう思う"),"")) | S40: =IF('39'!B17="","",IFERROR(CHOOSE('39'!B17,"そう思わない","あまりそう思わない","そう思う","とてもそう思う"),"")) | T40: =IF('39'!B18="","",IFERROR(CHOOSE('39'!B18,"そう思わない","あまりそう思わない","そう思う","とてもそう思う"),""))
...

Sheet 使い方
A1: 共同編集ブック（Formsと同じSheet1形式）
A3: ■ ポイント
A4: ・ツールが読むのは Sheet1 だけです。
A5: ・Sheet1 の列構成は Microsoft Forms のExcel出力と同じです。
A6: （ID / 開始時刻 / 完了時刻 / メール / 名前 / ①〜⑮の設問）
A7: ・そのため、Forms出力でもこのブックでも、ツール側の読み方は同じです。
A9: ■ 子ども（入力）
A10: 1. 自分の出席番号シート（01〜45）を開く
A11: 2. B列に 1〜4 を入れる（プルダウンあり）
A13: ■ 先生（集約・読込）
A14: 1. Excel / Excel Online でブックを開き、保存する（数式結果を確定）
A15: 2. Sheet1 に Formsと同じ形の表が並ぶ（回答はテキスト）
... A18: ※ 開始時刻・完了時刻・メール・名前は空欄で問題ありません。

Sheet 01
A1: 出席番号 01 の回答シート
A2: B列に 1〜4 の数字を入れてください（4=とてもそう思う … 1=そう思わない）
A3: 設問 | B3: 回答(1-4)
A4: ①目標：みんなで決めた目標やめあてに力を合わせてとりくんでいる学級です。 | B4: 2
A5: ②改善：自分たちの学習や生活をよくするための話し合いや活動をしている学級です。 | B5: 2
A6: ③役割：係や当番の活動に責任を持ってとりくむ学級です。 | B6: 3
A7: ④聞く姿勢：発言している人の話を最後までしっかりと聞いている学級です。 | B7: 3
A8: ⑤つながり：友だちの話に賛成・反対・つけたしと、つなげられるように発言している学級です。 | B8: 3
A9: ⑥積極性：話し合いの時、考えや意見を進んで出し合う学級です。 | B9: 2
A10: ⑦支え合い：勉強・運動・そうじ・給食などで、教え合いや助け合いをしている学級です。 | B10: 3
A11: ⑧仲直り：すなおに「ごめんね」と言って、仲直りができる学級です。 | B11: 2
A12: ⑨感謝：「ありがとう」を伝え合っている学級です。 | B12: 2
A13: ⑩認め合い：友だちのよいところやがんばっているところを伝え合っている学級です。 | B13: 3
A14: ⑪尊重：友だちの心を傷つけることを言ったり、からかったりしない学級です。 | B14: 3
A15: ⑫仲間：だれとでも遊んだり、グループになったりすることができる学級です。 | B15: 3
... A18: ⑮校外：校外ではひとのめいわくにならないように考えて行動できる学級です。 | B18: 2

Sheet 02
A1: 出席番号 02 の回答シート
A2: B列に 1〜4 の数字を入れてください（4=とてもそう思う … 1=そう思わない）
A3: 設問 | B3: 回答(1-4)
A4: ①目標：みんなで決めた目標やめあてに力を合わせてとりくんでいる学級です。 | B4: 2
A5: ②改善：自分たちの学習や生活をよくするための話し合いや活動をしている学級です。 | B5: 3
A6: ③役割：係や当番の活動に責任を持ってとりくむ学級です。 | B6: 4
A7: ④聞く姿勢：発言している人の話を最後までしっかりと聞いている学級です。 | B7: 3
A8: ⑤つながり：友だちの話に賛成・反対・つけたしと、つなげられるように発言している学級です。 | B8: 3
A9: ⑥積極性：話し合いの時、考えや意見を進んで出し合う学級です。 | B9: 3
A10: ⑦支え合い：勉強・運動・そうじ・給食などで、教え合いや助け合いをしている学級です。 | B10: 2
A11: ⑧仲直り：すなおに「ごめんね」と言って、仲直りができる学級です。 | B11: 2
A12: ⑨感謝：「ありがとう」を伝え合っている学級です。 | B12: 3
A13: ⑩認め合い：友だちのよいところやがんばっているところを伝え合っている学級です。 | B13: 3
A14: ⑪尊重：友だちの心を傷つけることを言ったり、からかったりしない学級です。 | B14: 2
A15: ⑫仲間：だれとでも遊んだり、グループになったりすることができる学級です。 | B15: 3
... A18: ⑮校外：校外ではひとのめいわくにならないように考えて行動できる学級です。 | B18: 2

Sheet 03
A1: 出席番号 03 の回答シート
A2: B列に 1〜4 の数字を入れてください（4=とてもそう思う … 1=そう思わない）
A3: 設問 | B3: 回答(1-4)
A4: ①目標：みんなで決めた目標やめあてに力を合わせてとりくんでいる学級です。 | B4: 3
A5: ②改善：自分たちの学習や生活をよくするための話し合いや活動をしている学級です。 | B5: 2
A6: ③役割：係や当番の活動に責任を持ってとりくむ学級です。 | B6: 1
A7: ④聞く姿勢：発言している人の話を最後までしっかりと聞いている学級です。 | B7: 2
A8: ⑤つながり：友だちの話に賛成・反対・つけたしと、つなげられるように発言している学級です。 | B8: 2
A9: ⑥積極性：話し合いの時、考えや意見を進んで出し合う学級です。 | B9: 3
A10: ⑦支え合い：勉強・運動・そうじ・給食などで、教え合いや助け合いをしている学級です。 | B10: 3
A11: ⑧仲直り：すなおに「ごめんね」と言って、仲直りができる学級です。 | B11: 2
A12: ⑨感謝：「ありがとう」を伝え合っている学級です。 | B12: 3
A13: ⑩認め合い：友だちのよいところやがんばっているところを伝え合っている学級です。 | B13: 2
A14: ⑪尊重：友だちの心を傷つけることを言ったり、からかったりしない学級です。 | B14: 3
A15: ⑫仲間：だれとでも遊んだり、グループになったりすることができる学級です。 | B15: 2
... A18: ⑮校外：校外ではひとのめいわくにならないように考えて行動できる学級です。 | B18: 3

Sheet 04
A1: 出席番号 04 の回答シート
A2: B列に 1〜4 の数字を入れてください（4=とてもそう思う … 1=そう思わない）
A3: 設問 | B3: 回答(1-4)
A4: ①目標：みんなで決めた目標やめあてに力を合わせてとりくんでいる学級です。 | B4: 3
A5: ②改善：自分たちの学習や生活をよくするための話し合いや活動をしている学級です。 | B5: 3
A6: ③役割：係や当番の活動に責任を持ってとりくむ学級です。 | B6: 3
A7: ④聞く姿勢：発言している人の話を最後までしっかりと聞いている学級です。 | B7: 4
A8: ⑤つながり：友だちの話に賛成・反対・つけたしと、つなげられるように発言している学級です。 | B8: 3
A9: ⑥積極性：話し合いの時、考えや意見を進んで出し合う学級です。 | B9: 3
A10: ⑦支え合い：勉強・運動・そうじ・給食などで、教え合いや助け合いをしている学級です。 | B10: 3
A11: ⑧仲直り：すなおに「ごめんね」と言って、仲直りができる学級です。 | B11: 3
A12: ⑨感謝：「ありがとう」を伝え合っている学級です。 | B12: 4
A13: ⑩認め合い：友だちのよいところやがんばっているところを伝え合っている学級です。 | B13: 3
A14: ⑪尊重：友だちの心を傷つけることを言ったり、からかったりしない学級です。 | B14: 3
A15: ⑫仲間：だれとでも遊んだり、グループになったりすることができる学級です。 | B15: 3
... A18: ⑮校外：校外ではひとのめいわくにならないように考えて行動できる学級です。 | B18: 3

Sheet 05
A1: 出席番号 05 の回答シート
A2: B列に 1〜4 の数字を入れてください（4=とてもそう思う … 1=そう思わない）
A3: 設問 | B3: 回答(1-4)
A4: ①目標：みんなで決めた目標やめあてに力を合わせてとりくんでいる学級です。 | B4: 4
A5: ②改善：自分たちの学習や生活をよくするための話し合いや活動をしている学級です。 | B5: 3
A6: ③役割：係や当番の活動に責任を持ってとりくむ学級です。 | B6: 3
A7: ④聞く姿勢：発言している人の話を最後までしっかりと聞いている学級です。 | B7: 3
A8: ⑤つながり：友だちの話に賛成・反対・つけたしと、つなげられるように発言している学級です。 | B8: 4
A9: ⑥積極性：話し合いの時、考えや意見を進んで出し合う学級です。 | B9: 3
A10: ⑦支え合い：勉強・運動・そうじ・給食などで、教え合いや助け合いをしている学級です。 | B10: 4
A11: ⑧仲直り：すなおに「ごめんね」と言って、仲直りができる学級です。 | B11: 3
A12: ⑨感謝：「ありがとう」を伝え合っている学級です。 | B12: 3
A13: ⑩認め合い：友だちのよいところやがんばっているところを伝え合っている学級です。 | B13: 4
A14: ⑪尊重：友だちの心を傷つけることを言ったり、からかったりしない学級です。 | B14: 3
A15: ⑫仲間：だれとでも遊んだり、グループになったりすることができる学級です。 | B15: 4
... A18: ⑮校外：校外ではひとのめいわくにならないように考えて行動できる学級です。 | B18: 3

Sheet 06
A1: 出席番号 06 の回答シート
A2: B列に 1〜4 の数字を入れてください（4=とてもそう思う … 1=そう思わない）
A3: 設問 | B3: 回答(1-4)
A4: ①目標：みんなで決めた目標やめあてに力を合わせてとりくんでいる学級です。
A5: ②改善：自分たちの学習や生活をよくするための話し合いや活動をしている学級です。
A6: ③役割：係や当番の活動に責任を持ってとりくむ学級です。
A7: ④聞く姿勢：発言している人の話を最後までしっかりと聞いている学級です。
A8: ⑤つながり：友だちの話に賛成・反対・つけたしと、つなげられるように発言している学級です。
A9: ⑥積極性：話し合いの時、考えや意見を進んで出し合う学級です。
A10: ⑦支え合い：勉強・運動・そうじ・給食などで、教え合いや助け合いをしている学級です。
A11: ⑧仲直り：すなおに「ごめんね」と言って、仲直りができる学級です。
A12: ⑨感謝：「ありがとう」を伝え合っている学級です。
A13: ⑩認め合い：友だちのよいところやがんばっているところを伝え合っている学級です。
A14: ⑪尊重：友だちの心を傷つけることを言ったり、からかったりしない学級です。
A15: ⑫仲間：だれとでも遊んだり、グループになったりすることができる学級です。
... A18: ⑮校外：校外ではひとのめいわくにならないように考えて行動できる学級です。

Sheet 07
A1: 出席番号 07 の回答シート
A2: B列に 1〜4 の数字を入れてください（4=とてもそう思う … 1=そう思わない）
A3: 設問 | B3: 回答(1-4)
A4: ①目標：みんなで決めた目標やめあてに力を合わせてとりくんでいる学級です。
A5: ②改善：自分たちの学習や生活をよくするための話し合いや活動をしている学級です。
A6: ③役割：係や当番の活動に責任を持ってとりくむ学級です。
A7: ④聞く姿勢：発言している人の話を最後までしっかりと聞いている学級です。
A8: ⑤つながり：友だちの話に賛成・反対・つけたしと、つなげられるように発言している学級です。
A9: ⑥積極性：話し合いの時、考えや意見を進んで出し合う学級です。
A10: ⑦支え合い：勉強・運動・そうじ・給食などで、教え合いや助け合いをしている学級です。
A11: ⑧仲直り：すなおに「ごめんね」と言って、仲直りができる学級です。
A12: ⑨感謝：「ありがとう」を伝え合っている学級です。
A13: ⑩認め合い：友だちのよいところやがんばっているところを伝え合っている学級です。
A14: ⑪尊重：友だちの心を傷つけることを言ったり、からかったりしない学級です。
A15: ⑫仲間：だれとでも遊んだり、グループになったりすることができる学級です。
... A18: ⑮校外：校外ではひとのめいわくにならないように考えて行動できる学級です。

Sheet 08
A1: 出席番号 08 の回答シート
A2: B列に 1〜4 の数字を入れてください（4=とてもそう思う … 1=そう思わない）
A3: 設問 | B3: 回答(1-4)
A4: ①目標：みんなで決めた目標やめあてに力を合わせてとりくんでいる学級です。
A5: ②改善：自分たちの学習や生活をよくするための話し合いや活動をしている学級です。
A6: ③役割：係や当番の活動に責任を持ってとりくむ学級です。
A7: ④聞く姿勢：発言している人の話を最後までしっかりと聞いている学級です。
A8: ⑤つながり：友だちの話に賛成・反対・つけたしと、つなげられるように発言している学級です。
A9: ⑥積極性：話し合いの時、考えや意見を進んで出し合う学級です。
A10: ⑦支え合い：勉強・運動・そうじ・給食などで、教え合いや助け合いをしている学級です。
A11: ⑧仲直り：すなおに「ごめんね」と言って、仲直りができる学級です。
A12: ⑨感謝：「ありがとう」を伝え合っている学級です。
A13: ⑩認め合い：友だちのよいところやがんばっているところを伝え合っている学級です。
A14: ⑪尊重：友だちの心を傷つけることを言ったり、からかったりしない学級です。
A15: ⑫仲間：だれとでも遊んだり、グループになったりすることができる学級です。
... A18: ⑮校外：校外ではひとのめいわくにならないように考えて行動できる学級です。

Sheet 09
A1: 出席番号 09 の回答シート
A2: B列に 1〜4 の数字を入れてください（4=とてもそう思う … 1=そう思わない）
A3: 設問 | B3: 回答(1-4)
A4: ①目標：みんなで決めた目標やめあてに力を合わせてとりくんでいる学級です。
A5: ②改善：自分たちの学習や生活をよくするための話し合いや活動をしている学級です。
A6: ③役割：係や当番の活動に責任を持ってとりくむ学級です。
A7: ④聞く姿勢：発言している人の話を最後までしっかりと聞いている学級です。
A8: ⑤つながり：友だちの話に賛成・反対・つけたしと、つなげられるように発言している学級です。
A9: ⑥積極性：話し合いの時、考えや意見を進んで出し合う学級です。
A10: ⑦支え合い：勉強・運動・そうじ・給食などで、教え合いや助け合いをしている学級です。
A11: ⑧仲直り：すなおに「ごめんね」と言って、仲直りができる学級です。
A12: ⑨感謝：「ありがとう」を伝え合っている学級です。
A13: ⑩認め合い：友だちのよいところやがんばっているところを伝え合っている学級です。
A14: ⑪尊重：友だちの心を傷つけることを言ったり、からかったりしない学級です。
A15: ⑫仲間：だれとでも遊んだり、グループになったりすることができる学級です。
... A18: ⑮校外：校外ではひとのめいわくにならないように考えて行動できる学級です。

Sheet 10
A1: 出席番号 10 の回答シート
A2: B列に 1〜4 の数字を入れてください（4=とてもそう思う … 1=そう思わない）
A3: 設問 | B3: 回答(1-4)
A4: ①目標：みんなで決めた目標やめあてに力を合わせてとりくんでいる学級です。
A5: ②改善：自分たちの学習や生活をよくするための話し合いや活動をしている学級です。
A6: ③役割：係や当番の活動に責任を持ってとりくむ学級です。
A7: ④聞く姿勢：発言している人の話を最後までしっかりと聞いている学級です。
A8: ⑤つながり：友だちの話に賛成・反対・つけたしと、つなげられるように発言している学級です。
A9: ⑥積極性：話し合いの時、考えや意見を進んで出し合う学級です。
A10: ⑦支え合い：勉強・運動・そうじ・給食などで、教え合いや助け合いをしている学級です。
A11: ⑧仲直り：すなおに「ごめんね」と言って、仲直りができる学級です。
A12: ⑨感謝：「ありがとう」を伝え合っている学級です。
A13: ⑩認め合い：友だちのよいところやがんばっているところを伝え合っている学級です。
A14: ⑪尊重：友だちの心を傷つけることを言ったり、からかったりしない学級です。
A15: ⑫仲間：だれとでも遊んだり、グループになったりすることができる学級です。
... A18: ⑮校外：校外ではひとのめいわくにならないように考えて行動できる学級です。

Sheet 11
A1: 出席番号 11 の回答シート
A2: B列に 1〜4 の数字を入れてください（4=とてもそう思う … 1=そう思わない）
A3: 設問 | B3: 回答(1-4)
A4: ①目標：みんなで決めた目標やめあてに力を合わせてとりくんでいる学級です。
A5: ②改善：自分たちの学習や生活をよくするための話し合いや活動をしている学級です。
A6: ③役割：係や当番の活動に責任を持ってとりくむ学級です。
A7: ④聞く姿勢：発言している人の話を最後までしっかりと聞いている学級です。
A8: ⑤つながり：友だちの話に賛成・反対・つけたしと、つなげられるように発言している学級です。
A9: ⑥積極性：話し合いの時、考えや意見を進んで出し合う学級です。
A10: ⑦支え合い：勉強・運動・そうじ・給食などで、教え合いや助け合いをしている学級です。
A11: ⑧仲直り：すなおに「ごめんね」と言って、仲直りができる学級です。
A12: ⑨感謝：「ありがとう」を伝え合っている学級です。
A13: ⑩認め合い：友だちのよいところやがんばっているところを伝え合っている学級です。
A14: ⑪尊重：友だちの心を傷つけることを言ったり、からかったりしない学級です。
A15: ⑫仲間：だれとでも遊んだり、グループになったりすることができる学級です。
... A18: ⑮校外：校外ではひとのめいわくにならないように考えて行動できる学級です。

Sheet 12
A1: 出席番号 12 の回答シート
A2: B列に 1〜4 の数字を入れてください（4=とてもそう思う … 1=そう思わない）
A3: 設問 | B3: 回答(1-4)
A4: ①目標：みんなで決めた目標やめあてに力を合わせてとりくんでいる学級です。
A5: ②改善：自分たちの学習や生活をよくするための話し合いや活動をしている学級です。
A6: ③役割：係や当番の活動に責任を持ってとりくむ学級です。
A7: ④聞く姿勢：発言している人の話を最後までしっかりと聞いている学級です。
A8: ⑤つながり：友だちの話に賛成・反対・つけたしと、つなげられるように発言している学級です。
A9: ⑥積極性：話し合いの時、考えや意見を進んで出し合う学級です。
A10: ⑦支え合い：勉強・運動・そうじ・給食などで、教え合いや助け合いをしている学級です。
A11: ⑧仲直り：すなおに「ごめんね」と言って、仲直りができる学級です。
A12: ⑨感謝：「ありがとう」を伝え合っている学級です。
A13: ⑩認め合い：友だちのよいところやがんばっているところを伝え合っている学級です。
A14: ⑪尊重：友だちの心を傷つけることを言ったり、からかったりしない学級です。
A15: ⑫仲間：だれとでも遊んだり、グループになったりすることができる学級です。
... A18: ⑮校外：校外ではひとのめいわくにならないように考えて行動できる学級です。

Sheet 13
A1: 出席番号 13 の回答シート
A2: B列に 1〜4 の数字を入れてください（4=とてもそう思う … 1=そう思わない）
A3: 設問 | B3: 回答(1-4)
A4: ①目標：みんなで決めた目標やめあてに力を合わせてとりくんでいる学級です。
A5: ②改善：自分たちの学習や生活をよくするための話し合いや活動をしている学級です。
A6: ③役割：係や当番の活動に責任を持ってとりくむ学級です。
A7: ④聞く姿勢：発言している人の話を最後までしっかりと聞いている学級です。
A8: ⑤つながり：友だちの話に賛成・反対・つけたしと、つなげられるように発言している学級です。
A9: ⑥積極性：話し合いの時、考えや意見を進んで出し合う学級です。
A10: ⑦支え合い：勉強・運動・そうじ・給食などで、教え合いや助け合いをしている学級です。
A11: ⑧仲直り：すなおに「ごめんね」と言って、仲直りができる学級です。
A12: ⑨感謝：「ありがとう」を伝え合っている学級です。
A13: ⑩認め合い：友だちのよいところやがんばっているところを伝え合っている学級です。
A14: ⑪尊重：友だちの心を傷つけることを言ったり、からかったりしない学級です。
A15: ⑫仲間：だれとでも遊んだり、グループになったりすることができる学級です。
... A18: ⑮校外：校外ではひとのめいわくにならないように考えて行動できる学級です。

Sheet 14
A1: 出席番号 14 の回答シート
A2: B列に 1〜4 の数字を入れてください（4=とてもそう思う … 1=そう思わない）
A3: 設問 | B3: 回答(1-4)
A4: ①目標：みんなで決めた目標やめあてに力を合わせてとりくんでいる学級です。
A5: ②改善：自分たちの学習や生活をよくするための話し合いや活動をしている学級です。
A6: ③役割：係や当番の活動に責任を持ってとりくむ学級です。
A7: ④聞く姿勢：発言している人の話を最後までしっかりと聞いている学級です。
A8: ⑤つながり：友だちの話に賛成・反対・つけたしと、つなげられるように発言している学級です。
A9: ⑥積極性：話し合いの時、考えや意見を進んで出し合う学級です。
A10: ⑦支え合い：勉強・運動・そうじ・給食などで、教え合いや助け合いをしている学級です。
A11: ⑧仲直り：すなおに「ごめんね」と言って、仲直りができる学級です。
A12: ⑨感謝：「ありがとう」を伝え合っている学級です。
A13: ⑩認め合い：友だちのよいところやがんばっているところを伝え合っている学級です。
A14: ⑪尊重：友だちの心を傷つけることを言ったり、からかったりしない学級です。
A15: ⑫仲間：だれとでも遊んだり、グループになったりすることができる学級です。
... A18: ⑮校外：校外ではひとのめいわくにならないように考えて行動できる学級です。

Sheet 15
A1: 出席番号 15 の回答シート
A2: B列に 1〜4 の数字を入れてください（4=とてもそう思う … 1=そう思わない）
A3: 設問 | B3: 回答(1-4)
A4: ①目標：みんなで決めた目標やめあてに力を合わせてとりくんでいる学級です。
A5: ②改善：自分たちの学習や生活をよくするための話し合いや活動をしている学級です。
A6: ③役割：係や当番の活動に責任を持ってとりくむ学級です。
A7: ④聞く姿勢：発言している人の話を最後までしっかりと聞いている学級です。
A8: ⑤つながり：友だちの話に賛成・反対・つけたしと、つなげられるように発言している学級です。
A9: ⑥積極性：話し合いの時、考えや意見を進んで出し合う学級です。
A10: ⑦支え合い：勉強・運動・そうじ・給食などで、教え合いや助け合いをしている学級です。
A11: ⑧仲直り：すなおに「ごめんね」と言って、仲直りができる学級です。
A12: ⑨感謝：「ありがとう」を伝え合っている学級です。
A13: ⑩認め合い：友だちのよいところやがんばっているところを伝え合っている学級です。
A14: ⑪尊重：友だちの心を傷つけることを言ったり、からかったりしない学級です。
A15: ⑫仲間：だれとでも遊んだり、グループになったりすることができる学級です。
... A18: ⑮校外：校外ではひとのめいわくにならないように考えて行動できる学級です。

Sheet 16
A1: 出席番号 16 の回答シート
A2: B列に 1〜4 の数字を入れてください（4=とてもそう思う … 1=そう思わない）
A3: 設問 | B3: 回答(1-4)
A4: ①目標：みんなで決めた目標やめあてに力を合わせてとりくんでいる学級です。
